Workbook
Name LEMI_REPORTING_MENSUEL: 'RAPPORT_MENSUEL'!$B$7:$E$64
Name LEMI_REPORTING_TRIMESTRIEL: 'BILAN_TRIMESTRIEL'!$B$7:$F$23
Name LEMI_REPORTING_HISTORIQUE: 'HISTORIQUE_RAPPORTS'!$A$5:$E$104

Sheet ACCUEIL
A2: 07 — REPORTING DMA | LEMI SARL | BRASUS v3.2
A3: Digital Mastery Agency | Consolidation & analyses stratégiques | Lecture seule
B5: KPI FLASH — REPORTING DMA
B6: Score global BRASUS (moyenne 5 départements) | C6: =IFERROR(AVERAGE(RAPPORT_MENSUEL!C8:C12),0)&"%" | D6: Depuis RAPPORT_MENSUEL
B7: CA encaissé cumul mois en cours (FCFA) | C7: =IFERROR(RAPPORT_MENSUEL!C16,0) | D7: Réf. Finance
B8: Trésorerie disponible (FCFA) | C8: =IFERROR(RAPPORT_MENSUEL!C17,0) | D8: Réf. Finance
B9: Filleuls parrainés ce mois | C9: =IFERROR(RAPPORT_MENSUEL!C28,0) | D9: Réf. 08_PARRAINAGE
B10: Commissions parrainage versées ce mois (FCFA) | C10: =IFERROR(RAPPORT_MENSUEL!C29,0) | D10: Réf. 08_PARRAINAGE
B11: Coût acquisition moyen / client (FCFA) | C11: =IFERROR(RAPPORT_MENSUEL!C32,0) | D11: Calcul DMA
B12: Rapports générés ce trimestre | C12: =IFERROR(COUNTA(HISTORIQUE_RAPPORTS!A5:A104)-COUNTBLANK(HISTORIQUE_RAPPORTS!B5:B104),0) | D12: Depuis HISTORIQUE
B14: NAVIGATION
B15: 📊 DASHBOARD_REPORTING | C15: KPIs consolides, tendances, comparaisons canaux | D15: Onglet 2
B16: 📄 RAPPORT_MENSUEL | C16: Rapport mensuel auto-calculé — tous les KPIs du mois | D16: Onglet 3
B17: 📈 BILAN_TRIMESTRIEL | C17: Analyse trimestrielle — ROI, tendances, recommandations | D17: Onglet 4
B18: 📑 RAPPORT_ANNUEL | C18: Bilan annuel — synthèse, objectifs, projections | D18: Onglet 5
B19: 📚 HISTORIQUE_RAPPORTS | C19: Archive horodatée de tous les rapports générés | D19: Onglet 6
B20: 📋 TACHES_PERIODIQUES | C20: Planning DMA : mensuel, trimestriel, annuel | D20: Onglet 7
B22: SOURCES DE DONNÉES
B23: COCKPIT_DG.xlsx | C23: Scores départementaux, alertes, plan d'actions
B24: CRM_LEMI_SARL.xlsx | C24: Prospects, clients actifs, pipeline, KPIs commerciaux
B25: COMMERCIAL / FINANCE / MARKETING / OPERATIONS / RH | C25: Taux d'exécution missions, historiques
B26: 08_PARRAINAGE.xlsx | C26: Filleuls, commissions, alertes fraude, parrains
A28: 07_REPORTING_DMA.xlsx | BRASUS v3.2 | Digital Mastery Agency | Abidjan | Lecture seule

Sheet DASHBOARD_REPORTING
A1: 📊 DASHBOARD REPORTING DMA | LEMI SARL | BRASUS v3.2
A2: 🔒 Consolidation automatique depuis tous les fichiers du système — Lecture seule
B4: PERFORMANCE GLOBALE LEMI SARL
B5: INDICATEUR | C5: SEMAINE EN COURS | D5: MOIS EN COURS | E5: TRIMESTRE | F5: TENDANCE | G5: OBJECTIF
B6: Score global BRASUS | C6: 0% | D6: 0% | E6: 0% | F6: 🟡 INIT | G6: ≥ 75%
B7: CA encaissé (FCFA) | C7: 0 | D7: 1 111 781 | E7: 1 111 781 | F7: 🟡 INIT | G7: 100 000 000 (M6)
B8: Contrats signés | C8: 0 | D8: 1 | E8: 1 | F8: 🟡 INIT | G8: ≥ 4/mois
B9: Taux de conversion | C9: 0% | D9: 50% | E9: 50% | F9: 🟢 | G9: ≥ 25%
B10: Prospects actifs | C10: 2 | D10: 2 | E10: 2 | F10: 🟡 INIT | G10: ≥ 20
B11: Présence moyenne | C11: 0/12 | D11: 0/12 | E11: 0/12 | F11: 🟡 INIT | G11: 12/12
B12: Incidents qualité | C12: 0 | D12: 0 | E12: 0 | F12: 🟢 | G12: 0
B13: Alertes actives | C13: 0 | D13: 0 | E13: 0 | F13: 🟢 | G13: 0
B15: SCORES PAR DÉPARTEMENT — TAUX D'EXÉCUTION MISSIONS
B16: DÉPARTEMENT | C16: TAUX JOUR | D16: TAUX SEMAINE | E16: TAUX MOIS | F16: NIVEAU | G16: RESPONSABLE
B17: Commercial | C17: 0% | D17: 0% | E17: 0% | F17: 🟡 INIT | G17: Resp. Commercial
B18: Finance | C18: 0% | D18: 0% | E18: 0% | F18: 🟡 INIT | G18: Resp. Finance
B19: Marketing | C19: 0% | D19: 0% | E19: 0% | F19: 🟡 INIT | G19: CM Digital
B20: Opérations | C20: 0% | D20: 0% | E20: 0% | F20: 🟡 INIT | G20: Chef Chantier
B21: Ressources Humaines | C21: 0% | D21: 0% | E21: 0% | F21: 🟡 INIT | G21: Resp. RH
B23: CANAUX D'ACQUISITION — COMPARAISON ROI
B24: CANAL | C24: CLIENTS CE MOIS | D24: COÛT ACQUISITION | E24: CA GÉNÉRÉ | F24: ROI | G24: PART DU CA (%)
B25: Prospection directe (WhatsApp) | C25: 0 | D25: 0 FCFA | E25: 0 FCFA | F25: — | G25: 0%
B26: Meta Ads (Facebook) | C26: 0 | D26: 0 FCFA (CPL) | E26: 0 FCFA | F26: — | G26: 0%
B27: Parrainage (2,5% acompte) | C27: 0 | D27: 0 FCFA | E27: 0 FCFA | F27: — | G27: 0%
B28: Bouche-à-oreille (non tracé) | C28: 1 | D28: 0 FCFA | E28: 3 705 935 FCFA | F28: ∞ | G28: 100%
A30: Données initialisées le 18/06/2026 — Les valeurs seront auto-calculées dès les premières clôtures BRASUS

Sheet RAPPORT_MENSUEL
A1: 📄 RAPPORT MENSUEL AUTO — LEMI SARL | BRASUS v3.2 | DMA
A2: 🔒 Généré automatiquement le dernier jour ouvré de chaque mois — Consolidation tous fichiers
B3: 📅 Mois : JUIN 2026 | Période : 01/06/2026 — 30/06/2026
B5: SECTION 1 — PERFORMANCE OPÉRATIONNELLE
B6: INDICATEUR | C6: VALEUR MOIS | D6: OBJECTIF | E6: ÉCART
B7: Nb jours ouvrés | C7: 0 | D7: 22 | E7: =IFERROR(C7-D7,0)
B8: Score global BRASUS (%) | C8: 0% | D8: ≥ 75% | E8: —
B9: — Commercial | C9: 0% | D9: ≥ 75% | E9: —
B10: — Finance | C10: 0% | D10: ≥ 75% | E10: —
B11: — Marketing | C11: 0% | D11: ≥ 75% | E11: —
B12: — Opérations | C12: 0% | D12: ≥ 75% | E12: —
B13: — RH | C13: 0% | D13: ≥ 75% | E13: —
B14: Missions FAIT / Total | C14: 0/0 | D14: 110/110 (22j×5) | E14: —
B16: SECTION 2 — INDICATEURS FINANCIERS
B17: INDICATEUR | C17: VALEUR MOIS | D17: OBJECTIF | E17: ÉCART
B18: CA encaissé mois (FCFA) | C18: 1 111 781 | D18: 8 333 333 | E18: =IFERROR(C18-D18,0)
B19: Trésorerie fin de mois (FCFA) | C19: À renseigner | D19: ≥ 5 000 000 | E19: —
B20: Nombre de contrats signés | C20: 1 | D20: ≥ 4 | E20: =IFERROR(C20-D20,0)
B21: Marge brute moyenne (%) | C21: À calculer | D21: ≥ 22% | E21: —
B22: Clients en retard paiement | C22: 0 | D22: 0 | E22: —
B23: Pénalités appliquées (FCFA) | C23: 0 | D23: — | E23: —
B24: Impayés > J+30 (FCFA) | C24: 0 | D24: 0 | E24: —
B26: SECTION 3 — PROGRAMME DE PARRAINAGE
B27: INDICATEUR | C27: VALEUR MOIS | D27: OBJECTIF | E27: ÉCART
B28: Nouveaux filleuls déclarés | C28: 0 | D28: — | E28: —
B29: Filleuls éligibles | C29: 0 | D29: — | E29: —
B30: Filleuls refusés (anti-fraude) | C30: 0 | D30: — | E30: —
B31: Commissions versées (FCFA) | C31: 0 | D31: — | E31: —
B32: Commissions en attente DG | C32: 0 | D32: 0 | E32: —
B33: Coût acquisition parrainage / client | C33: 0 FCFA | D33: < CPL Meta Ads | E33: —
B34: Parrains actifs | C34: 0 | D34: — | E34: —
B35: Top parrain du mois | C35: — | D35: — | E35: —
B36: Alertes fraude traitées | C36: 0 | D36: 0 en attente | E36: —
B38: SECTION 4 — MARKETING & ACQUISITION
B39: INDICATEUR | C39: VALEUR MOIS | D39: OBJECTIF | E39: ÉCART
B40: Leads générés (WhatsApp) | C40: 0 | D40: ≥ 100/mois | E40: —
B41: Leads qualifiés transmis | C41: 0 | D41: ≥ 40/mois | E41: —
B42: Posts publiés (Facebook) | C42: 0 | D42: ≥ 22/mois | E42: —
B43: CPL Meta Ads (FCFA) | C43: — | D43: < 2 500 | E43: —
B44: Budget Meta Ads dépensé (FCFA) | C44: 0 | D44: 25 000/mois | E44: —
...

Sheet BILAN_TRIMESTRIEL
A1: 📈 BILAN TRIMESTRIEL — LEMI SARL | BRASUS v3.2 | DMA
A2: 🔒 Analyse comparative trimestrielle — Tendances, ROI, recommandations stratégiques
B3: 📅 Trimestre : T2 2026 (Avril — Juin) | Exercice : 2026
B5: ÉVOLUTION MENSUELLE DU TRIMESTRE
B6: INDICATEUR | C6: MOIS 1 (AVR) | D6: MOIS 2 (MAI) | E6: MOIS 3 (JUN) | F6: TENDANCE
B7: Score global BRASUS (%) | C7: — | D7: — | E7: 0% | F7: 🟡
B8: CA encaissé (FCFA) | C8: — | D8: — | E8: 1 111 781 | F8: 🟡
B9: Contrats signés | C9: — | D9: — | E9: 1 | F9: 🟡
B10: Prospects nouveaux | C10: — | D10: — | E10: 2 | F10: 🟡
B11: Filleuls parrainés | C11: — | D11: — | E11: 0 | F11: 🟡
B12: Commissions versées (FCFA) | C12: — | D12: — | E12: 0 | F12: 🟡
B13: CPL Meta Ads (FCFA) | C13: — | D13: — | E13: — | F13: 🟡
B14: Taux présence moyen | C14: — | D14: — | E14: 0% | F14: 🟡
B15: Incidents qualité | C15: — | D15: — | E15: 0 | F15: 🟢
B17: ROI PAR CANAL D'ACQUISITION — ANALYSE TRIMESTRIELLE
B18: CANAL | C18: CLIENTS ACQUIS | D18: COÛT TOTAL (FCFA) | E18: CA GÉNÉRÉ (FCFA) | F18: ROI
B19: Prospection directe | C19: 0 | D19: 0 | E19: 0 | F19: =IFERROR(IF(D19=0,"—",E19/D19&"x"),"—")
B20: Meta Ads Facebook | C20: 0 | D20: 0 | E20: 0 | F20: =IFERROR(IF(D20=0,"—",E20/D20&"x"),"—")
B21: Parrainage (commission 2,5%) | C21: 0 | D21: 0 | E21: 0 | F21: =IFERROR(IF(D21=0,"—",E21/D21&"x"),"—")
B22: Bouche-à-oreille (non tracé) | C22: 1 | D22: 0 | E22: 3 705 935 | F22: =IFERROR(IF(D22=0,"∞",E22/D22&"x"),"∞")
B23: TOTAL TRIMESTRE | C23: =IFERROR(SUM(C19:C22),0) | D23: =IFERROR(SUM(D19:D22),0) | E23: =IFERROR(SUM(E19:E22),0) | F23: =IFERROR(IF(D23=0,"—",E23/D23&"x"),"—")
B25: RECOMMANDATIONS STRATÉGIQUES DMA — TRIMESTRE SUIVANT
B26: 1 | C26: [ Recommandation stratégique DMA — Générée à la fin du trimestre ]
B27: 2 | C27: [ Recommandation stratégique DMA — Générée à la fin du trimestre ]
B28: 3 | C28: [ Recommandation stratégique DMA — Générée à la fin du trimestre ]
B29: 4 | C29: [ Recommandation stratégique DMA — Générée à la fin du trimestre ]
B30: 5 | C30: [ Objectif de CA pour le trimestre suivant — À valider par le DG ]
A32: Bilan trimestriel BRASUS v3.2 | DMA | Prochain bilan : fin T3 2026 (Septembre)

Sheet RAPPORT_ANNUEL
A1: 📑 RAPPORT ANNUEL — LEMI SARL | EXERCICE 2026 | DMA
A2: 🔒 Synthèse annuelle — Objectifs vs réalisé — Projections 2027
B4: SYNTHÈSE ANNUELLE PAR TRIMESTRE
B5: INDICATEUR | C5: T1 | D5: T2 | E5: T3 | F5: T4 | G5: TOTAL ANNUEL
B6: CA encaissé (FCFA) | C6: — | D6: — | E6: — | F6: — | G6: =IFERROR(SUM(C6:F6),0)
B7: Contrats signés | C7: — | D7: — | E7: — | F7: — | G7: =IFERROR(SUM(C7:F7),0)
B8: Prospects générés | C8: — | D8: — | E8: — | F8: — | G8: =IFERROR(SUM(C8:F8),0)
B9: Score BRASUS moyen (%) | C9: — | D9: — | E9: — | F9: — | G9: —
B10: Filleuls parrainés | C10: — | D10: — | E10: — | F10: — | G10: =IFERROR(SUM(C10:F10),0)
B11: Commissions versées (FCFA) | C11: — | D11: — | E11: — | F11: — | G11: =IFERROR(SUM(C11:F11),0)
B12: CPL Meta Ads moyen (FCFA) | C12: — | D12: — | E12: — | F12: — | G12: —
B13: Coût acquisition parrainage moyen | C13: — | D13: — | E13: — | F13: — | G13: —
B14: Taux présence moyen (%) | C14: — | D14: — | E14: — | F14: — | G14: —
B15: Chantiers livrés | C15: — | D15: — | E15: — | F15: — | G15: —
B16: Incidents qualité | C16: — | D16: — | E16: — | F16: — | G16: =IFERROR(SUM(C16:F16),0)
B18: OBJECTIFS 2026 vs RÉALISÉ
B19: OBJECTIF | C19: CIBLE 2026 | D19: RÉALISÉ | E19: TAUX | F19: STATUT | G19: COMMENTAIRE
B20: CA annuel | C20: 100 000 000 FCFA | D20: 1 111 781 | E20: =IFERROR(ROUND(D20/C20*100,1)&"%","0%") | F20: 🟡 | G20: Démarrage juin
B21: Contrats signés | C21: 48 | D21: 1 | E21: =IFERROR(ROUND(D21/C21*100,1)&"%","0%") | F21: 🟡 | G21: Objectif 4/mois
B22: Score BRASUS | C22: ≥ 75% | D22: 0% | E22: — | F22: 🟡 | G22: En attente 1ère clôture
B23: Présence | C23: ≥ 95% | D23: 0% | E23: — | F23: 🟡 | G23: —
B24: Programme parrainage | C24: 20 filleuls/an | D24: 0 | E24: 0% | F24: 🟡 | G24: Lancé en juin
A26: Rapport annuel BRASUS v3.2 | DMA | Exercice 2026 | Livraison : Janvier 2027

Sheet HISTORIQUE_RAPPORTS
A1: 📚 HISTORIQUE DES RAPPORTS — LEMI SARL | BRASUS v3.2
A2: 🔒 Archive horodatée de tous les rapports générés par BRASUS — Ne pas supprimer
A4: DATE | B4: TYPE RAPPORT | C4: RÉSUMÉ / TITRE | D4: PÉRIODE | E4: STATUT
A5: 18/06/2026 | B5: RAPPORT JOURNALIER | C5: Jour 1 BRASUS — Initialisation système, 2 prospects, 1 client actif, 5 fichiers J+1 générés | D5: 18/06/2026 | E5: 🟢 Livré

Sheet TACHES_PERIODIQUES
A1: 📋 TÂCHES PÉRIODIQUES — REPORTING DMA | LEMI SARL | BRASUS v3.2
A2: 🔒 Planning opérationnel DMA — Reporting, analyses et recommandations stratégiques
A3: 🔒 ZONE A — Tâches et délais (verrouillé) | E3: ✏️ ZONE B — Suivi exécution (déverrouillé)
A4: FRÉQUENCE | B4: TÂCHE | C4: RESPONSABLE | D4: DÉLAI | E4: STATUT | F4: DATE EXÉCUTION | G4: COMMENTAIRES
A5: MENSUEL | B5: Générer le RAPPORT_MENSUEL — consolider tous les KPIs du mois | C5: DMA | D5: J+1 du mois
B6: Intégrer les KPI parrainage (filleuls, commissions, top parrains) dans RAPPORT_MENSUEL | C6: DMA | D6: J+1 du mois
B7: Mettre à jour le DASHBOARD_REPORTING avec les données du mois écoulé | C7: DMA | D7: J+2 du mois
B8: Archiver le rapport mensuel dans HISTORIQUE_RAPPORTS | C8: DMA | D8: J+2 du mois
B9: Envoyer le rapport mensuel synthèse au DG via WhatsApp | C9: DMA | D9: J+3 du mois
A10: TRIMESTRIEL | B10: Générer le BILAN_TRIMESTRIEL — analyse tendances + ROI par canal | C10: DMA | D10: Fin de trimestre
B11: Comparer le coût d'acquisition par parrainage (2,5% acompte) vs coût Meta Ads (CPL) | C11: DMA | D11: Fin de trimestre
B12: Préparer les recommandations stratégiques pour le trimestre suivant | C12: DMA | D12: Fin de trimestre
B13: Présenter le bilan trimestriel au DG — réunion de cadrage | C13: DMA + DG | D13: Fin de trimestre
A14: SEMESTRIEL | B14: Évaluation approfondie du programme de parrainage — ajustement du taux si nécessaire | C14: DMA + DG | D14: Juin / Décembre
B15: Audit complet du système BRASUS — cohérence des fichiers, formules, interconnexions | C15: DMA | D15: Juin / Décembre
A16: ANNUEL | B16: Générer le RAPPORT_ANNUEL — synthèse exercice, objectifs vs réalisé | C16: DMA | D16: Janvier 2027
B17: Intégrer la performance du programme de parrainage au rapport annuel | C17: DMA | D17: Janvier 2027
B18: Préparer les objectifs et le plan d'action de l'année suivante | C18: DMA + DG | D18: Janvier 2027
B19: Décision de reconduction / ajustement du taux de commission parrainage | C19: DG | D19: Avril 2027
A20: 07_REPORTING_DMA.xlsx | BRASUS v3.2 | Digital Mastery Agency | Abidjan
