Workbook
Name LEMI_PARRAINAGE_REGISTRE: 'REGISTRE_PARRAINS'!$A$7:$J$106
Name LEMI_PARRAINAGE_FILLEULS: 'FILLEULS'!$A$7:$J$106
Name LEMI_PARRAINAGE_COMMISSIONS: 'COMMISSIONS_PARRAINAGE'!$A$7:$M$106

Sheet ACCUEIL
A2: LEMI SARL — PROGRAMME DE PARRAINAGE CLIENT
A3: Tontine Habitat | Abidjan, Côte d'Ivoire | BRASUS v3.2 | Digital Mastery Agency
B5: KPI FLASH — PARRAINAGE
B6: Commissions versées ce mois (FCFA) | C6: =IFERROR(SUMPRODUCT((COMMISSIONS_PARRAINAGE!H7:H106="Payé")*(MONTH(COMMISSIONS_PARRAINAGE!K7:K106)=MONTH(TODAY()))*(YEAR(COMMISSIONS_PARRAINAGE!K7:K106)=YEAR(TODAY()))*COMMISSIONS_PARRAINAGE!G7:G106),0) | D6: Calculé depuis COMMISSIONS_PARRAINAGE
B7: Filleuls éligibles ce mois | C7: =IFERROR(COUNTIFS(FILLEULS!G7:G106,"*ÉLIGIBLE*",FILLEULS!E7:E106,">="&DATE(YEAR(TODAY()),MONTH(TODAY()),1)),0) | D7: Filleuls avec statut ÉLIGIBLE
B8: Parrain le plus actif | C8: =IFERROR(INDEX(REGISTRE_PARRAINS!B7:B106,MATCH(MAX(REGISTRE_PARRAINS!H7:H106),REGISTRE_PARRAINS!H7:H106,0)),"—") | D8: Par nombre de filleuls cumulés
B9: Commissions en attente de validation | C9: =IFERROR(COUNTIF(COMMISSIONS_PARRAINAGE!H7:H106,"À valider"),0) | D9: Requièrent validation DG
B10: Total parrains inscrits | C10: =IFERROR(COUNTA(REGISTRE_PARRAINS!B7:B106)-COUNTBLANK(REGISTRE_PARRAINS!B7:B106),0) | D10: Depuis REGISTRE_PARRAINS
B12: NAVIGATION
B13: 📊 DASHBOARD_PARRAINAGE | C13: Courbes, barres, top parrains, répartitions | D13: Onglet 2
B14: 📗 REGISTRE_PARRAINS | C14: Inscription et suivi des parrains | D14: Onglet 3
B15: 👥 FILLEULS | C15: Déclaration et éligibilité des filleuls | D15: Onglet 4
B16: 💰 COMMISSIONS_PARRAINAGE | C16: Calcul, validation DG, paiement | D16: Onglet 5
B17: 🚨 ALERTES_FRAUDE | C17: Verrous 1-5 — Signaux et blocages | D17: Onglet 6
B18: 📋 TACHES_PERIODIQUES | C18: Planning quotidien / hebdo / mensuel / trimestriel | D18: Onglet 7
B20: RÈGLES DU PROGRAMME
B21: Taux de commission | C21: 2,5% de l'acompte de signature (30% du contrat)
B22: Déclenchement | C22: Dès réception confirmée de l'acompte du filleul
B23: Mode de paiement | C23: Orange Money ou Wave — versement direct au parrain
B24: Plafond filleuls | C24: Aucun — volume illimité
B25: Qui peut parrainer | C25: Clients actifs, prospects ET partenaires
B26: Déclaration obligatoire | C26: Code parrain au 1er contact — après signature = refusé
B27: Validation | C27: Double contrôle : éligibilité auto + validation DG
A29: Dernière mise à jour : =TEXT(TODAY(),"DD/MM/YYYY") | BRASUS v3.2 | LEMI SARL | DMA Abidjan

Sheet DASHBOARD_PARRAINAGE
A1: LEMI SARL | DASHBOARD PARRAINAGE | BRASUS v3.2
A2: 🔒 Indicateurs consolidés automatiquement — Lecture seule | Mis à jour : 18/06/2026
B4: ÉVOLUTION MENSUELLE — FILLEULS PARRAINÉS | H4: COMMISSIONS VERSÉES PAR MOIS (FCFA)
B5: Jan | C5: Fév | D5: Mar | E5: Avr | F5: Mai | G5: Juin | H5: Jan | I5: Fév | J5: Mar | K5: Avr | L5: Mai | M5: Juin
B6: 0 | C6: 0 | D6: 0 | E6: 0 | F6: 0 | G6: 0 | H6: 0 | I6: 0 | J6: 0 | K6: 0 | L6: 0 | M6: 0
B8: TOP 5 — MEILLEURS PARRAINS | H8: RÉPARTITION PAR TYPE DE PARRAIN
B9: # | C9: NOM PARRAIN | D9: TYPE | E9: NB FILLEULS | F9: COMMISSIONS (FCFA) | G9: STATUT | H9: TYPE | I9: NOMBRE | J9: % DU TOTAL | K9: COMMISSIONS | L9: COMM. MOY. | M9: FILLEULS MOY.
B10: 1 | C10: — | D10: — | E10: 0 | F10: 0 FCFA | G10: — | H10: Client actif | I10: =IFERROR(COUNTIF(REGISTRE_PARRAINS!D7:D106,"Client"),0) | J10: 0% | K10: 0 FCFA | L10: 0 FCFA | M10: 0
B11: 2 | C11: — | D11: — | E11: 0 | F11: 0 FCFA | G11: — | H11: Prospect | I11: =IFERROR(COUNTIF(REGISTRE_PARRAINS!D7:D106,"Prospect"),0) | J11: 0% | K11: 0 FCFA | L11: 0 FCFA | M11: 0
B12: 3 | C12: — | D12: — | E12: 0 | F12: 0 FCFA | G12: — | H12: Partenaire | I12: =IFERROR(COUNTIF(REGISTRE_PARRAINS!D7:D106,"Partenaire"),0) | J12: 0% | K12: 0 FCFA | L12: 0 FCFA | M12: 0
B13: 4 | C13: — | D13: — | E13: 0 | F13: 0 FCFA | G13: —
B14: 5 | C14: — | D14: — | E14: 0 | F14: 0 FCFA | G14: —
B16: JAUGE — COMMISSIONS EN ATTENTE DE VALIDATION DG
B17: Commissions À VALIDER | H17: =IFERROR(COUNTIF(COMMISSIONS_PARRAINAGE!H7:H106,"À valider"),0)
B18: Montant total à valider (FCFA) | H18: =IFERROR(SUMPRODUCT((COMMISSIONS_PARRAINAGE!H7:H106="À valider")*COMMISSIONS_PARRAINAGE!G7:G106),0)
B19: Commissions VALIDÉES DG (non payées) | H19: =IFERROR(COUNTIF(COMMISSIONS_PARRAINAGE!H7:H106,"Validé DG"),0)
B20: Commissions PAYÉES ce mois | H20: =IFERROR(COUNTIF(COMMISSIONS_PARRAINAGE!H7:H106,"Payé"),0)
B21: Clawbacks actifs | H21: =IFERROR(COUNTIF(COMMISSIONS_PARRAINAGE!M7:M106,"*DÉDUIRE*"),0)

Sheet REGISTRE_PARRAINS
A1: 📗 REGISTRE DES PARRAINS — LEMI SARL | BRASUS v3.2
A2: Plage nommée : LEMI_PARRAINAGE_REGISTRE | Colonnes A-F : saisie | Colonnes G-J : calcul auto 🔒
A3: ✏️ ZONE SAISIE — Colonnes déverrouillées | F3: 🔒 ZONE CALCUL — Colonnes verrouillées (auto)
A4: 📋 ORDRE CANONIQUE A→J: | B4: A=CODE | C4: B=NOM PRÉNOM | D4: C=TÉLÉPHONE | E4: D=TYPE | F4: E=DATE INSCRIPTION | G4: F=N° MOBILE MONEY | H4: G=STATUT | I4: H=NB FILLEULS | J4: I=TOTAL COMMISSIONS | K4: J=STATUT COMPTE
A5: INFORMATIONS PARRAIN (saisie manuelle) | F5: DONNÉES CALCULÉES AUTOMATIQUEMENT
A6: CODE PARRAIN | B6: NOM PRÉNOM | C6: TÉLÉPHONE | D6: TYPE | E6: DATE INSCRIPTION | F6: N° ORANGE MONEY / WAVE | G6: STATUT PARRAIN | H6: NB FILLEULS CUMULÉS | I6: TOTAL COMMISSIONS (FCFA) | J6: STATUT COMPTE
A7: LEMI-PARR-001 | B7: Nom et prénom | C7: 07 XX XX XX XX | E7: JJ/MM/AAAA | G7: =IFERROR(IF(B7="","",IF(COUNTIF(FILLEULS!G7:G106,"*ÉLIGIBLE*")>0,"Actif","Inscrit")),"—") | H7: =IFERROR(COUNTIF(FILLEULS!D7:D106,A7),0) | I7: =IFERROR(SUMPRODUCT((COMMISSIONS_PARRAINAGE!C7:C106=A7)*(COMMISSIONS_PARRAINAGE!H7:H106="Payé")*COMMISSIONS_PARRAINAGE!G7:G106),0) | J7: =IFERROR(IF(B7="","","Actif"),"—")
A8: LEMI-PARR-002 | G8: =IFERROR(IF(B8="","",IF(COUNTIF(FILLEULS!G7:G106,"*ÉLIGIBLE*")>0,"Actif","Inscrit")),"—") | H8: =IFERROR(COUNTIF(FILLEULS!D7:D106,A8),0) | I8: =IFERROR(SUMPRODUCT((COMMISSIONS_PARRAINAGE!C7:C106=A8)*(COMMISSIONS_PARRAINAGE!H7:H106="Payé")*COMMISSIONS_PARRAINAGE!G7:G106),0) | J8: =IFERROR(IF(B8="","","Actif"),"—")
A9: LEMI-PARR-003 | G9: =IFERROR(IF(B9="","",IF(COUNTIF(FILLEULS!G7:G106,"*ÉLIGIBLE*")>0,"Actif","Inscrit")),"—") | H9: =IFERROR(COUNTIF(FILLEULS!D7:D106,A9),0) | I9: =IFERROR(SUMPRODUCT((COMMISSIONS_PARRAINAGE!C7:C106=A9)*(COMMISSIONS_PARRAINAGE!H7:H106="Payé")*COMMISSIONS_PARRAINAGE!G7:G106),0) | J9: =IFERROR(IF(B9="","","Actif"),"—")
A10: LEMI-PARR-004 | G10: =IFERROR(IF(B10="","",IF(COUNTIF(FILLEULS!G7:G106,"*ÉLIGIBLE*")>0,"Actif","Inscrit")),"—") | H10: =IFERROR(COUNTIF(FILLEULS!D7:D106,A10),0) | I10: =IFERROR(SUMPRODUCT((COMMISSIONS_PARRAINAGE!C7:C106=A10)*(COMMISSIONS_PARRAINAGE!H7:H106="Payé")*COMMISSIONS_PARRAINAGE!G7:G106),0) | J10: =IFERROR(IF(B10="","","Actif"),"—")
A11: LEMI-PARR-005 | G11: =IFERROR(IF(B11="","",IF(COUNTIF(FILLEULS!G7:G106,"*ÉLIGIBLE*")>0,"Actif","Inscrit")),"—") | H11: =IFERROR(COUNTIF(FILLEULS!D7:D106,A11),0) | I11: =IFERROR(SUMPRODUCT((COMMISSIONS_PARRAINAGE!C7:C106=A11)*(COMMISSIONS_PARRAINAGE!H7:H106="Payé")*COMMISSIONS_PARRAINAGE!G7:G106),0) | J11: =IFERROR(IF(B11="","","Actif"),"—")
A12: LEMI-PARR-006 | G12: =IFERROR(IF(B12="","",IF(COUNTIF(FILLEULS!G7:G106,"*ÉLIGIBLE*")>0,"Actif","Inscrit")),"—") | H12: =IFERROR(COUNTIF(FILLEULS!D7:D106,A12),0) | I12: =IFERROR(SUMPRODUCT((COMMISSIONS_PARRAINAGE!C7:C106=A12)*(COMMISSIONS_PARRAINAGE!H7:H106="Payé")*COMMISSIONS_PARRAINAGE!G7:G106),0) | J12: =IFERROR(IF(B12="","","Actif"),"—")
A13: LEMI-PARR-007 | G13: =IFERROR(IF(B13="","",IF(COUNTIF(FILLEULS!G7:G106,"*ÉLIGIBLE*")>0,"Actif","Inscrit")),"—") | H13: =IFERROR(COUNTIF(FILLEULS!D7:D106,A13),0) | I13: =IFERROR(SUMPRODUCT((COMMISSIONS_PARRAINAGE!C7:C106=A13)*(COMMISSIONS_PARRAINAGE!H7:H106="Payé")*COMMISSIONS_PARRAINAGE!G7:G106),0) | J13: =IFERROR(IF(B13="","","Actif"),"—")
A14: LEMI-PARR-008 | G14: =IFERROR(IF(B14="","",IF(COUNTIF(FILLEULS!G7:G106,"*ÉLIGIBLE*")>0,"Actif","Inscrit")),"—") | H14: =IFERROR(COUNTIF(FILLEULS!D7:D106,A14),0) | I14: =IFERROR(SUMPRODUCT((COMMISSIONS_PARRAINAGE!C7:C106=A14)*(COMMISSIONS_PARRAINAGE!H7:H106="Payé")*COMMISSIONS_PARRAINAGE!G7:G106),0) | J14: =IFERROR(IF(B14="","","Actif"),"—")
A15: LEMI-PARR-009 | G15: =IFERROR(IF(B15="","",IF(COUNTIF(FILLEULS!G7:G106,"*ÉLIGIBLE*")>0,"Actif","Inscrit")),"—") | H15: =IFERROR(COUNTIF(FILLEULS!D7:D106,A15),0) | I15: =IFERROR(SUMPRODUCT((COMMISSIONS_PARRAINAGE!C7:C106=A15)*(COMMISSIONS_PARRAINAGE!H7:H106="Payé")*COMMISSIONS_PARRAINAGE!G7:G106),0) | J15: =IFERROR(IF(B15="","","Actif"),"—")
A16: LEMI-PARR-010 | G16: =IFERROR(IF(B16="","",IF(COUNTIF(FILLEULS!G7:G106,"*ÉLIGIBLE*")>0,"Actif","Inscrit")),"—") | H16: =IFERROR(COUNTIF(FILLEULS!D7:D106,A16),0) | I16: =IFERROR(SUMPRODUCT((COMMISSIONS_PARRAINAGE!C7:C106=A16)*(COMMISSIONS_PARRAINAGE!H7:H106="Payé")*COMMISSIONS_PARRAINAGE!G7:G106),0) | J16: =IFERROR(IF(B16="","","Actif"),"—")
A17: LEMI-PARR-011 | G17: =IFERROR(IF(B17="","",IF(COUNTIF(FILLEULS!G7:G106,"*ÉLIGIBLE*")>0,"Actif","Inscrit")),"—") | H17: =IFERROR(COUNTIF(FILLEULS!D7:D106,A17),0) | I17: =IFERROR(SUMPRODUCT((COMMISSIONS_PARRAINAGE!C7:C106=A17)*(COMMISSIONS_PARRAINAGE!H7:H106="Payé")*COMMISSIONS_PARRAINAGE!G7:G106),0) | J17: =IFERROR(IF(B17="","","Actif"),"—")
A18: LEMI-PARR-012 | G18: =IFERROR(IF(B18="","",IF(COUNTIF(FILLEULS!G7:G106,"*ÉLIGIBLE*")>0,"Actif","Inscrit")),"—") | H18: =IFERROR(COUNTIF(FILLEULS!D7:D106,A18),0) | I18: =IFERROR(SUMPRODUCT((COMMISSIONS_PARRAINAGE!C7:C106=A18)*(COMMISSIONS_PARRAINAGE!H7:H106="Payé")*COMMISSIONS_PARRAINAGE!G7:G106),0) | J18: =IFERROR(IF(B18="","","Actif"),"—")
A19: LEMI-PARR-013 | G19: =IFERROR(IF(B19="","",IF(COUNTIF(FILLEULS!G7:G106,"*ÉLIGIBLE*")>0,"Actif","Inscrit")),"—") | H19: =IFERROR(COUNTIF(FILLEULS!D7:D106,A19),0) | I19: =IFERROR(SUMPRODUCT((COMMISSIONS_PARRAINAGE!C7:C106=A19)*(COMMISSIONS_PARRAINAGE!H7:H106="Payé")*COMMISSIONS_PARRAINAGE!G7:G106),0) | J19: =IFERROR(IF(B19="","","Actif"),"—")
A20: LEMI-PARR-014 | G20: =IFERROR(IF(B20="","",IF(COUNTIF(FILLEULS!G7:G106,"*ÉLIGIBLE*")>0,"Actif","Inscrit")),"—") | H20: =IFERROR(COUNTIF(FILLEULS!D7:D106,A20),0) | I20: =IFERROR(SUMPRODUCT((COMMISSIONS_PARRAINAGE!C7:C106=A20)*(COMMISSIONS_PARRAINAGE!H7:H106="Payé")*COMMISSIONS_PARRAINAGE!G7:G106),0) | J20: =IFERROR(IF(B20="","","Actif"),"—")
A21: LEMI-PARR-015 | G21: =IFERROR(IF(B21="","",IF(COUNTIF(FILLEULS!G7:G106,"*ÉLIGIBLE*")>0,"Actif","Inscrit")),"—") | H21: =IFERROR(COUNTIF(FILLEULS!D7:D106,A21),0) | I21: =IFERROR(SUMPRODUCT((COMMISSIONS_PARRAINAGE!C7:C106=A21)*(COMMISSIONS_PARRAINAGE!H7:H106="Payé")*COMMISSIONS_PARRAINAGE!G7:G106),0) | J21: =IFERROR(IF(B21="","","Actif"),"—")
A22: LEMI-PARR-016 | G22: =IFERROR(IF(B22="","",IF(COUNTIF(FILLEULS!G7:G106,"*ÉLIGIBLE*")>0,"Actif","Inscrit")),"—") | H22: =IFERROR(COUNTIF(FILLEULS!D7:D106,A22),0) | I22: =IFERROR(SUMPRODUCT((COMMISSIONS_PARRAINAGE!C7:C106=A22)*(COMMISSIONS_PARRAINAGE!H7:H106="Payé")*COMMISSIONS_PARRAINAGE!G7:G106),0) | J22: =IFERROR(IF(B22="","","Actif"),"—")
A23: LEMI-PARR-017 | G23: =IFERROR(IF(B23="","",IF(COUNTIF(FILLEULS!G7:G106,"*ÉLIGIBLE*")>0,"Actif","Inscrit")),"—") | H23: =IFERROR(COUNTIF(FILLEULS!D7:D106,A23),0) | I23: =IFERROR(SUMPRODUCT((COMMISSIONS_PARRAINAGE!C7:C106=A23)*(COMMISSIONS_PARRAINAGE!H7:H106="Payé")*COMMISSIONS_PARRAINAGE!G7:G106),0) | J23: =IFERROR(IF(B23="","","Actif"),"—")
A24: LEMI-PARR-018 | G24: =IFERROR(IF(B24="","",IF(COUNTIF(FILLEULS!G7:G106,"*ÉLIGIBLE*")>0,"Actif","Inscrit")),"—") | H24: =IFERROR(COUNTIF(FILLEULS!D7:D106,A24),0) | I24: =IFERROR(SUMPRODUCT((COMMISSIONS_PARRAINAGE!C7:C106=A24)*(COMMISSIONS_PARRAINAGE!H7:H106="Payé")*COMMISSIONS_PARRAINAGE!G7:G106),0) | J24: =IFERROR(IF(B24="","","Actif"),"—")
A25: LEMI-PARR-019 | G25: =IFERROR(IF(B25="","",IF(COUNTIF(FILLEULS!G7:G106,"*ÉLIGIBLE*")>0,"Actif","Inscrit")),"—") | H25: =IFERROR(COUNTIF(FILLEULS!D7:D106,A25),0) | I25: =IFERROR(SUMPRODUCT((COMMISSIONS_PARRAINAGE!C7:C106=A25)*(COMMISSIONS_PARRAINAGE!H7:H106="Payé")*COMMISSIONS_PARRAINAGE!G7:G106),0) | J25: =IFERROR(IF(B25="","","Actif"),"—")
A26: LEMI-PARR-020 | G26: =IFERROR(IF(B26="","",IF(COUNTIF(FILLEULS!G7:G106,"*ÉLIGIBLE*")>0,"Actif","Inscrit")),"—") | H26: =IFERROR(COUNTIF(FILLEULS!D7:D106,A26),0) | I26: =IFERROR(SUMPRODUCT((COMMISSIONS_PARRAINAGE!C7:C106=A26)*(COMMISSIONS_PARRAINAGE!H7:H106="Payé")*COMMISSIONS_PARRAINAGE!G7:G106),0) | J26: =IFERROR(IF(B26="","","Actif"),"—")
A27: LEMI-PARR-021 | G27: =IFERROR(IF(B27="","",IF(COUNTIF(FILLEULS!G7:G106,"*ÉLIGIBLE*")>0,"Actif","Inscrit")),"—") | H27: =IFERROR(COUNTIF(FILLEULS!D7:D106,A27),0) | I27: =IFERROR(SUMPRODUCT((COMMISSIONS_PARRAINAGE!C7:C106=A27)*(COMMISSIONS_PARRAINAGE!H7:H106="Payé")*COMMISSIONS_PARRAINAGE!G7:G106),0) | J27: =IFERROR(IF(B27="","","Actif"),"—")
A28: LEMI-PARR-022 | G28: =IFERROR(IF(B28="","",IF(COUNTIF(FILLEULS!G7:G106,"*ÉLIGIBLE*")>0,"Actif","Inscrit")),"—") | H28: =IFERROR(COUNTIF(FILLEULS!D7:D106,A28),0) | I28: =IFERROR(SUMPRODUCT((COMMISSIONS_PARRAINAGE!C7:C106=A28)*(COMMISSIONS_PARRAINAGE!H7:H106="Payé")*COMMISSIONS_PARRAINAGE!G7:G106),0) | J28: =IFERROR(IF(B28="","","Actif"),"—")
A29: LEMI-PARR-023 | G29: =IFERROR(IF(B29="","",IF(COUNTIF(FILLEULS!G7:G106,"*ÉLIGIBLE*")>0,"Actif","Inscrit")),"—") | H29: =IFERROR(COUNTIF(FILLEULS!D7:D106,A29),0) | I29: =IFERROR(SUMPRODUCT((COMMISSIONS_PARRAINAGE!C7:C106=A29)*(COMMISSIONS_PARRAINAGE!H7:H106="Payé")*COMMISSIONS_PARRAINAGE!G7:G106),0) | J29: =IFERROR(IF(B29="","","Actif"),"—")
A30: LEMI-PARR-024 | G30: =IFERROR(IF(B30="","",IF(COUNTIF(FILLEULS!G7:G106,"*ÉLIGIBLE*")>0,"Actif","Inscrit")),"—") | H30: =IFERROR(COUNTIF(FILLEULS!D7:D106,A30),0) | I30: =IFERROR(SUMPRODUCT((COMMISSIONS_PARRAINAGE!C7:C106=A30)*(COMMISSIONS_PARRAINAGE!H7:H106="Payé")*COMMISSIONS_PARRAINAGE!G7:G106),0) | J30: =IFERROR(IF(B30="","","Actif"),"—")
A31: LEMI-PARR-025 | G31: =IFERROR(IF(B31="","",IF(COUNTIF(FILLEULS!G7:G106,"*ÉLIGIBLE*")>0,"Actif","Inscrit")),"—") | H31: =IFERROR(COUNTIF(FILLEULS!D7:D106,A31),0) | I31: =IFERROR(SUMPRODUCT((COMMISSIONS_PARRAINAGE!C7:C106=A31)*(COMMISSIONS_PARRAINAGE!H7:H106="Payé")*COMMISSIONS_PARRAINAGE!G7:G106),0) | J31: =IFERROR(IF(B31="","","Actif"),"—")
A32: LEMI-PARR-026 | G32: =IFERROR(IF(B32="","",IF(COUNTIF(FILLEULS!G7:G106,"*ÉLIGIBLE*")>0,"Actif","Inscrit")),"—") | H32: =IFERROR(COUNTIF(FILLEULS!D7:D106,A32),0) | I32: =IFERROR(SUMPRODUCT((COMMISSIONS_PARRAINAGE!C7:C106=A32)*(COMMISSIONS_PARRAINAGE!H7:H106="Payé")*COMMISSIONS_PARRAINAGE!G7:G106),0) | J32: =IFERROR(IF(B32="","","Actif"),"—")
A33: LEMI-PARR-027 | G33: =IFERROR(IF(B33="","",IF(COUNTIF(FILLEULS!G7:G106,"*ÉLIGIBLE*")>0,"Actif","Inscrit")),"—") | H33: =IFERROR(COUNTIF(FILLEULS!D7:D106,A33),0) | I33: =IFERROR(SUMPRODUCT((COMMISSIONS_PARRAINAGE!C7:C106=A33)*(COMMISSIONS_PARRAINAGE!H7:H106="Payé")*COMMISSIONS_PARRAINAGE!G7:G106),0) | J33: =IFERROR(IF(B33="","","Actif"),"—")
A34: LEMI-PARR-028 | G34: =IFERROR(IF(B34="","",IF(COUNTIF(FILLEULS!G7:G106,"*ÉLIGIBLE*")>0,"Actif","Inscrit")),"—") | H34: =IFERROR(COUNTIF(FILLEULS!D7:D106,A34),0) | I34: =IFERROR(SUMPRODUCT((COMMISSIONS_PARRAINAGE!C7:C106=A34)*(COMMISSIONS_PARRAINAGE!H7:H106="Payé")*COMMISSIONS_PARRAINAGE!G7:G106),0) | J34: =IFERROR(IF(B34="","","Actif"),"—")
A35: LEMI-PARR-029 | G35: =IFERROR(IF(B35="","",IF(COUNTIF(FILLEULS!G7:G106,"*ÉLIGIBLE*")>0,"Actif","Inscrit")),"—") | H35: =IFERROR(COUNTIF(FILLEULS!D7:D106,A35),0) | I35: =IFERROR(SUMPRODUCT((COMMISSIONS_PARRAINAGE!C7:C106=A35)*(COMMISSIONS_PARRAINAGE!H7:H106="Payé")*COMMISSIONS_PARRAINAGE!G7:G106),0) | J35: =IFERROR(IF(B35="","","Actif"),"—")
A36: LEMI-PARR-030 | G36: =IFERROR(IF(B36="","",IF(COUNTIF(FILLEULS!G7:G106,"*ÉLIGIBLE*")>0,"Actif","Inscrit")),"—") | H36: =IFERROR(COUNTIF(FILLEULS!D7:D106,A36),0) | I36: =IFERROR(SUMPRODUCT((COMMISSIONS_PARRAINAGE!C7:C106=A36)*(COMMISSIONS_PARRAINAGE!H7:H106="Payé")*COMMISSIONS_PARRAINAGE!G7:G106),0) | J36: =IFERROR(IF(B36="","","Actif"),"—")
A37: LEMI-PARR-031 | G37: =IFERROR(IF(B37="","",IF(COUNTIF(FILLEULS!G7:G106,"*ÉLIGIBLE*")>0,"Actif","Inscrit")),"—") | H37: =IFERROR(COUNTIF(FILLEULS!D7:D106,A37),0) | I37: =IFERROR(SUMPRODUCT((COMMISSIONS_PARRAINAGE!C7:C106=A37)*(COMMISSIONS_PARRAINAGE!H7:H106="Payé")*COMMISSIONS_PARRAINAGE!G7:G106),0) | J37: =IFERROR(IF(B37="","","Actif"),"—")
A38: LEMI-PARR-032 | G38: =IFERROR(IF(B38="","",IF(COUNTIF(FILLEULS!G7:G106,"*ÉLIGIBLE*")>0,"Actif","Inscrit")),"—") | H38: =IFERROR(COUNTIF(FILLEULS!D7:D106,A38),0) | I38: =IFERROR(SUMPRODUCT((COMMISSIONS_PARRAINAGE!C7:C106=A38)*(COMMISSIONS_PARRAINAGE!H7:H106="Payé")*COMMISSIONS_PARRAINAGE!G7:G106),0) | J38: =IFERROR(IF(B38="","","Actif"),"—")
A39: LEMI-PARR-033 | G39: =IFERROR(IF(B39="","",IF(COUNTIF(FILLEULS!G7:G106,"*ÉLIGIBLE*")>0,"Actif","Inscrit")),"—") | H39: =IFERROR(COUNTIF(FILLEULS!D7:D106,A39),0) | I39: =IFERROR(SUMPRODUCT((COMMISSIONS_PARRAINAGE!C7:C106=A39)*(COMMISSIONS_PARRAINAGE!H7:H106="Payé")*COMMISSIONS_PARRAINAGE!G7:G106),0) | J39: =IFERROR(IF(B39="","","Actif"),"—")
A40: LEMI-PARR-034 | G40: =IFERROR(IF(B40="","",IF(COUNTIF(FILLEULS!G7:G106,"*ÉLIGIBLE*")>0,"Actif","Inscrit")),"—") | H40: =IFERROR(COUNTIF(FILLEULS!D7:D106,A40),0) | I40: =IFERROR(SUMPRODUCT((COMMISSIONS_PARRAINAGE!C7:C106=A40)*(COMMISSIONS_PARRAINAGE!H7:H106="Payé")*COMMISSIONS_PARRAINAGE!G7:G106),0) | J40: =IFERROR(IF(B40="","","Actif"),"—")
...

Sheet FILLEULS
A1: 👥 FILLEULS DÉCLARÉS — CONTRÔLE D'ÉLIGIBILITÉ | LEMI SARL | BRASUS v3.2
A2: Plage nommée : LEMI_PARRAINAGE_FILLEULS | Colonnes A-F : saisie | Colonnes G-J : contrôle auto 🔒
A3: 🚨 VERROUS ANTI-FRAUDE ACTIFS : V1 (unicité téléphone) | V2 (déclaration au 1er contact) | V5 (signaux faibles)
A5: ✏️ ZONE SAISIE | G5: 🔒 CONTRÔLE AUTOMATIQUE (Verrous 1-2-5)
A6: ID FILLEUL | B6: NOM PRÉNOM FILLEUL | C6: TÉLÉPHONE FILLEUL | D6: CODE PARRAIN DÉCLARÉ | E6: DATE DÉCLARATION | F6: DATE 1ER CONTACT (CRM) | G6: ÉLIGIBILITÉ (AUTO) | H6: STATUT CONTRAT (CRM) | I6: MONTANT ACOMPTE (CRM) | J6: SIGNAL ALERTE (V5)
A7: FIL-001 | B7: Nom et prénom | C7: 07 XX XX XX XX | D7: LEMI-PARR-XXX | E7: JJ/MM/AAAA | F7: JJ/MM/AAAA (depuis CRM) | G7: =IFERROR(IF(B7=""," ",IF(COUNTIF(C$7:C$6,C7)+COUNTIF(REGISTRE_PARRAINS!C7:C106,C7)>0,"🚫 REFUSÉ — NUMÉRO DÉJÀ ENREGISTRÉ",IF(AND(E7<>"",F7<>"",E7<>F7),"🚫 REFUSÉ — CODE DÉCLARÉ HORS DÉLAI","✅ ÉLIGIBLE")))," ") | H7: =IFERROR(IF(B7="","","À vérifier CRM")," ") | I7: =IFERROR(IF(B7="","","Réf. CRM")," ") | J7: =IFERROR(IF(B7=""," ",IF(COUNTIF(REGISTRE_PARRAINS!C7:C106,C7)>0,"⚠️ MÊME ADRESSE/TEL QUE PARRAIN"," "))," ")
A8: FIL-002 | G8: =IFERROR(IF(B8=""," ",IF(COUNTIF(C$7:C$7,C8)+COUNTIF(REGISTRE_PARRAINS!C7:C106,C8)>0,"🚫 REFUSÉ — NUMÉRO DÉJÀ ENREGISTRÉ",IF(AND(E8<>"",F8<>"",E8<>F8),"🚫 REFUSÉ — CODE DÉCLARÉ HORS DÉLAI","✅ ÉLIGIBLE")))," ") | H8: =IFERROR(IF(B8="","","À vérifier CRM")," ") | I8: =IFERROR(IF(B8="","","Réf. CRM")," ") | J8: =IFERROR(IF(B8=""," ",IF(COUNTIF(REGISTRE_PARRAINS!C7:C106,C8)>0,"⚠️ MÊME ADRESSE/TEL QUE PARRAIN"," "))," ")
A9: FIL-003 | G9: =IFERROR(IF(B9=""," ",IF(COUNTIF(C$7:C$8,C9)+COUNTIF(REGISTRE_PARRAINS!C7:C106,C9)>0,"🚫 REFUSÉ — NUMÉRO DÉJÀ ENREGISTRÉ",IF(AND(E9<>"",F9<>"",E9<>F9),"🚫 REFUSÉ — CODE DÉCLARÉ HORS DÉLAI","✅ ÉLIGIBLE")))," ") | H9: =IFERROR(IF(B9="","","À vérifier CRM")," ") | I9: =IFERROR(IF(B9="","","Réf. CRM")," ") | J9: =IFERROR(IF(B9=""," ",IF(COUNTIF(REGISTRE_PARRAINS!C7:C106,C9)>0,"⚠️ MÊME ADRESSE/TEL QUE PARRAIN"," "))," ")
A10: FIL-004 | G10: =IFERROR(IF(B10=""," ",IF(COUNTIF(C$7:C$9,C10)+COUNTIF(REGISTRE_PARRAINS!C7:C106,C10)>0,"🚫 REFUSÉ — NUMÉRO DÉJÀ ENREGISTRÉ",IF(AND(E10<>"",F10<>"",E10<>F10),"🚫 REFUSÉ — CODE DÉCLARÉ HORS DÉLAI","✅ ÉLIGIBLE")))," ") | H10: =IFERROR(IF(B10="","","À vérifier CRM")," ") | I10: =IFERROR(IF(B10="","","Réf. CRM")," ") | J10: =IFERROR(IF(B10=""," ",IF(COUNTIF(REGISTRE_PARRAINS!C7:C106,C10)>0,"⚠️ MÊME ADRESSE/TEL QUE PARRAIN"," "))," ")
A11: FIL-005 | G11: =IFERROR(IF(B11=""," ",IF(COUNTIF(C$7:C$10,C11)+COUNTIF(REGISTRE_PARRAINS!C7:C106,C11)>0,"🚫 REFUSÉ — NUMÉRO DÉJÀ ENREGISTRÉ",IF(AND(E11<>"",F11<>"",E11<>F11),"🚫 REFUSÉ — CODE DÉCLARÉ HORS DÉLAI","✅ ÉLIGIBLE")))," ") | H11: =IFERROR(IF(B11="","","À vérifier CRM")," ") | I11: =IFERROR(IF(B11="","","Réf. CRM")," ") | J11: =IFERROR(IF(B11=""," ",IF(COUNTIF(REGISTRE_PARRAINS!C7:C106,C11)>0,"⚠️ MÊME ADRESSE/TEL QUE PARRAIN"," "))," ")
A12: FIL-006 | G12: =IFERROR(IF(B12=""," ",IF(COUNTIF(C$7:C$11,C12)+COUNTIF(REGISTRE_PARRAINS!C7:C106,C12)>0,"🚫 REFUSÉ — NUMÉRO DÉJÀ ENREGISTRÉ",IF(AND(E12<>"",F12<>"",E12<>F12),"🚫 REFUSÉ — CODE DÉCLARÉ HORS DÉLAI","✅ ÉLIGIBLE")))," ") | H12: =IFERROR(IF(B12="","","À vérifier CRM")," ") | I12: =IFERROR(IF(B12="","","Réf. CRM")," ") | J12: =IFERROR(IF(B12=""," ",IF(COUNTIF(REGISTRE_PARRAINS!C7:C106,C12)>0,"⚠️ MÊME ADRESSE/TEL QUE PARRAIN"," "))," ")
A13: FIL-007 | G13: =IFERROR(IF(B13=""," ",IF(COUNTIF(C$7:C$12,C13)+COUNTIF(REGISTRE_PARRAINS!C7:C106,C13)>0,"🚫 REFUSÉ — NUMÉRO DÉJÀ ENREGISTRÉ",IF(AND(E13<>"",F13<>"",E13<>F13),"🚫 REFUSÉ — CODE DÉCLARÉ HORS DÉLAI","✅ ÉLIGIBLE")))," ") | H13: =IFERROR(IF(B13="","","À vérifier CRM")," ") | I13: =IFERROR(IF(B13="","","Réf. CRM")," ") | J13: =IFERROR(IF(B13=""," ",IF(COUNTIF(REGISTRE_PARRAINS!C7:C106,C13)>0,"⚠️ MÊME ADRESSE/TEL QUE PARRAIN"," "))," ")
A14: FIL-008 | G14: =IFERROR(IF(B14=""," ",IF(COUNTIF(C$7:C$13,C14)+COUNTIF(REGISTRE_PARRAINS!C7:C106,C14)>0,"🚫 REFUSÉ — NUMÉRO DÉJÀ ENREGISTRÉ",IF(AND(E14<>"",F14<>"",E14<>F14),"🚫 REFUSÉ — CODE DÉCLARÉ HORS DÉLAI","✅ ÉLIGIBLE")))," ") | H14: =IFERROR(IF(B14="","","À vérifier CRM")," ") | I14: =IFERROR(IF(B14="","","Réf. CRM")," ") | J14: =IFERROR(IF(B14=""," ",IF(COUNTIF(REGISTRE_PARRAINS!C7:C106,C14)>0,"⚠️ MÊME ADRESSE/TEL QUE PARRAIN"," "))," ")
A15: FIL-009 | G15: =IFERROR(IF(B15=""," ",IF(COUNTIF(C$7:C$14,C15)+COUNTIF(REGISTRE_PARRAINS!C7:C106,C15)>0,"🚫 REFUSÉ — NUMÉRO DÉJÀ ENREGISTRÉ",IF(AND(E15<>"",F15<>"",E15<>F15),"🚫 REFUSÉ — CODE DÉCLARÉ HORS DÉLAI","✅ ÉLIGIBLE")))," ") | H15: =IFERROR(IF(B15="","","À vérifier CRM")," ") | I15: =IFERROR(IF(B15="","","Réf. CRM")," ") | J15: =IFERROR(IF(B15=""," ",IF(COUNTIF(REGISTRE_PARRAINS!C7:C106,C15)>0,"⚠️ MÊME ADRESSE/TEL QUE PARRAIN"," "))," ")
A16: FIL-010 | G16: =IFERROR(IF(B16=""," ",IF(COUNTIF(C$7:C$15,C16)+COUNTIF(REGISTRE_PARRAINS!C7:C106,C16)>0,"🚫 REFUSÉ — NUMÉRO DÉJÀ ENREGISTRÉ",IF(AND(E16<>"",F16<>"",E16<>F16),"🚫 REFUSÉ — CODE DÉCLARÉ HORS DÉLAI","✅ ÉLIGIBLE")))," ") | H16: =IFERROR(IF(B16="","","À vérifier CRM")," ") | I16: =IFERROR(IF(B16="","","Réf. CRM")," ") | J16: =IFERROR(IF(B16=""," ",IF(COUNTIF(REGISTRE_PARRAINS!C7:C106,C16)>0,"⚠️ MÊME ADRESSE/TEL QUE PARRAIN"," "))," ")
A17: FIL-011 | G17: =IFERROR(IF(B17=""," ",IF(COUNTIF(C$7:C$16,C17)+COUNTIF(REGISTRE_PARRAINS!C7:C106,C17)>0,"🚫 REFUSÉ — NUMÉRO DÉJÀ ENREGISTRÉ",IF(AND(E17<>"",F17<>"",E17<>F17),"🚫 REFUSÉ — CODE DÉCLARÉ HORS DÉLAI","✅ ÉLIGIBLE")))," ") | H17: =IFERROR(IF(B17="","","À vérifier CRM")," ") | I17: =IFERROR(IF(B17="","","Réf. CRM")," ") | J17: =IFERROR(IF(B17=""," ",IF(COUNTIF(REGISTRE_PARRAINS!C7:C106,C17)>0,"⚠️ MÊME ADRESSE/TEL QUE PARRAIN"," "))," ")
A18: FIL-012 | G18: =IFERROR(IF(B18=""," ",IF(COUNTIF(C$7:C$17,C18)+COUNTIF(REGISTRE_PARRAINS!C7:C106,C18)>0,"🚫 REFUSÉ — NUMÉRO DÉJÀ ENREGISTRÉ",IF(AND(E18<>"",F18<>"",E18<>F18),"🚫 REFUSÉ — CODE DÉCLARÉ HORS DÉLAI","✅ ÉLIGIBLE")))," ") | H18: =IFERROR(IF(B18="","","À vérifier CRM")," ") | I18: =IFERROR(IF(B18="","","Réf. CRM")," ") | J18: =IFERROR(IF(B18=""," ",IF(COUNTIF(REGISTRE_PARRAINS!C7:C106,C18)>0,"⚠️ MÊME ADRESSE/TEL QUE PARRAIN"," "))," ")
A19: FIL-013 | G19: =IFERROR(IF(B19=""," ",IF(COUNTIF(C$7:C$18,C19)+COUNTIF(REGISTRE_PARRAINS!C7:C106,C19)>0,"🚫 REFUSÉ — NUMÉRO DÉJÀ ENREGISTRÉ",IF(AND(E19<>"",F19<>"",E19<>F19),"🚫 REFUSÉ — CODE DÉCLARÉ HORS DÉLAI","✅ ÉLIGIBLE")))," ") | H19: =IFERROR(IF(B19="","","À vérifier CRM")," ") | I19: =IFERROR(IF(B19="","","Réf. CRM")," ") | J19: =IFERROR(IF(B19=""," ",IF(COUNTIF(REGISTRE_PARRAINS!C7:C106,C19)>0,"⚠️ MÊME ADRESSE/TEL QUE PARRAIN"," "))," ")
A20: FIL-014 | G20: =IFERROR(IF(B20=""," ",IF(COUNTIF(C$7:C$19,C20)+COUNTIF(REGISTRE_PARRAINS!C7:C106,C20)>0,"🚫 REFUSÉ — NUMÉRO DÉJÀ ENREGISTRÉ",IF(AND(E20<>"",F20<>"",E20<>F20),"🚫 REFUSÉ — CODE DÉCLARÉ HORS DÉLAI","✅ ÉLIGIBLE")))," ") | H20: =IFERROR(IF(B20="","","À vérifier CRM")," ") | I20: =IFERROR(IF(B20="","","Réf. CRM")," ") | J20: =IFERROR(IF(B20=""," ",IF(COUNTIF(REGISTRE_PARRAINS!C7:C106,C20)>0,"⚠️ MÊME ADRESSE/TEL QUE PARRAIN"," "))," ")
A21: FIL-015 | G21: =IFERROR(IF(B21=""," ",IF(COUNTIF(C$7:C$20,C21)+COUNTIF(REGISTRE_PARRAINS!C7:C106,C21)>0,"🚫 REFUSÉ — NUMÉRO DÉJÀ ENREGISTRÉ",IF(AND(E21<>"",F21<>"",E21<>F21),"🚫 REFUSÉ — CODE DÉCLARÉ HORS DÉLAI","✅ ÉLIGIBLE")))," ") | H21: =IFERROR(IF(B21="","","À vérifier CRM")," ") | I21: =IFERROR(IF(B21="","","Réf. CRM")," ") | J21: =IFERROR(IF(B21=""," ",IF(COUNTIF(REGISTRE_PARRAINS!C7:C106,C21)>0,"⚠️ MÊME ADRESSE/TEL QUE PARRAIN"," "))," ")
A22: FIL-016 | G22: =IFERROR(IF(B22=""," ",IF(COUNTIF(C$7:C$21,C22)+COUNTIF(REGISTRE_PARRAINS!C7:C106,C22)>0,"🚫 REFUSÉ — NUMÉRO DÉJÀ ENREGISTRÉ",IF(AND(E22<>"",F22<>"",E22<>F22),"🚫 REFUSÉ — CODE DÉCLARÉ HORS DÉLAI","✅ ÉLIGIBLE")))," ") | H22: =IFERROR(IF(B22="","","À vérifier CRM")," ") | I22: =IFERROR(IF(B22="","","Réf. CRM")," ") | J22: =IFERROR(IF(B22=""," ",IF(COUNTIF(REGISTRE_PARRAINS!C7:C106,C22)>0,"⚠️ MÊME ADRESSE/TEL QUE PARRAIN"," "))," ")
A23: FIL-017 | G23: =IFERROR(IF(B23=""," ",IF(COUNTIF(C$7:C$22,C23)+COUNTIF(REGISTRE_PARRAINS!C7:C106,C23)>0,"🚫 REFUSÉ — NUMÉRO DÉJÀ ENREGISTRÉ",IF(AND(E23<>"",F23<>"",E23<>F23),"🚫 REFUSÉ — CODE DÉCLARÉ HORS DÉLAI","✅ ÉLIGIBLE")))," ") | H23: =IFERROR(IF(B23="","","À vérifier CRM")," ") | I23: =IFERROR(IF(B23="","","Réf. CRM")," ") | J23: =IFERROR(IF(B23=""," ",IF(COUNTIF(REGISTRE_PARRAINS!C7:C106,C23)>0,"⚠️ MÊME ADRESSE/TEL QUE PARRAIN"," "))," ")
A24: FIL-018 | G24: =IFERROR(IF(B24=""," ",IF(COUNTIF(C$7:C$23,C24)+COUNTIF(REGISTRE_PARRAINS!C7:C106,C24)>0,"🚫 REFUSÉ — NUMÉRO DÉJÀ ENREGISTRÉ",IF(AND(E24<>"",F24<>"",E24<>F24),"🚫 REFUSÉ — CODE DÉCLARÉ HORS DÉLAI","✅ ÉLIGIBLE")))," ") | H24: =IFERROR(IF(B24="","","À vérifier CRM")," ") | I24: =IFERROR(IF(B24="","","Réf. CRM")," ") | J24: =IFERROR(IF(B24=""," ",IF(COUNTIF(REGISTRE_PARRAINS!C7:C106,C24)>0,"⚠️ MÊME ADRESSE/TEL QUE PARRAIN"," "))," ")
A25: FIL-019 | G25: =IFERROR(IF(B25=""," ",IF(COUNTIF(C$7:C$24,C25)+COUNTIF(REGISTRE_PARRAINS!C7:C106,C25)>0,"🚫 REFUSÉ — NUMÉRO DÉJÀ ENREGISTRÉ",IF(AND(E25<>"",F25<>"",E25<>F25),"🚫 REFUSÉ — CODE DÉCLARÉ HORS DÉLAI","✅ ÉLIGIBLE")))," ") | H25: =IFERROR(IF(B25="","","À vérifier CRM")," ") | I25: =IFERROR(IF(B25="","","Réf. CRM")," ") | J25: =IFERROR(IF(B25=""," ",IF(COUNTIF(REGISTRE_PARRAINS!C7:C106,C25)>0,"⚠️ MÊME ADRESSE/TEL QUE PARRAIN"," "))," ")
A26: FIL-020 | G26: =IFERROR(IF(B26=""," ",IF(COUNTIF(C$7:C$25,C26)+COUNTIF(REGISTRE_PARRAINS!C7:C106,C26)>0,"🚫 REFUSÉ — NUMÉRO DÉJÀ ENREGISTRÉ",IF(AND(E26<>"",F26<>"",E26<>F26),"🚫 REFUSÉ — CODE DÉCLARÉ HORS DÉLAI","✅ ÉLIGIBLE")))," ") | H26: =IFERROR(IF(B26="","","À vérifier CRM")," ") | I26: =IFERROR(IF(B26="","","Réf. CRM")," ") | J26: =IFERROR(IF(B26=""," ",IF(COUNTIF(REGISTRE_PARRAINS!C7:C106,C26)>0,"⚠️ MÊME ADRESSE/TEL QUE PARRAIN"," "))," ")
A27: FIL-021 | G27: =IFERROR(IF(B27=""," ",IF(COUNTIF(C$7:C$26,C27)+COUNTIF(REGISTRE_PARRAINS!C7:C106,C27)>0,"🚫 REFUSÉ — NUMÉRO DÉJÀ ENREGISTRÉ",IF(AND(E27<>"",F27<>"",E27<>F27),"🚫 REFUSÉ — CODE DÉCLARÉ HORS DÉLAI","✅ ÉLIGIBLE")))," ") | H27: =IFERROR(IF(B27="","","À vérifier CRM")," ") | I27: =IFERROR(IF(B27="","","Réf. CRM")," ") | J27: =IFERROR(IF(B27=""," ",IF(COUNTIF(REGISTRE_PARRAINS!C7:C106,C27)>0,"⚠️ MÊME ADRESSE/TEL QUE PARRAIN"," "))," ")
A28: FIL-022 | G28: =IFERROR(IF(B28=""," ",IF(COUNTIF(C$7:C$27,C28)+COUNTIF(REGISTRE_PARRAINS!C7:C106,C28)>0,"🚫 REFUSÉ — NUMÉRO DÉJÀ ENREGISTRÉ",IF(AND(E28<>"",F28<>"",E28<>F28),"🚫 REFUSÉ — CODE DÉCLARÉ HORS DÉLAI","✅ ÉLIGIBLE")))," ") | H28: =IFERROR(IF(B28="","","À vérifier CRM")," ") | I28: =IFERROR(IF(B28="","","Réf. CRM")," ") | J28: =IFERROR(IF(B28=""," ",IF(COUNTIF(REGISTRE_PARRAINS!C7:C106,C28)>0,"⚠️ MÊME ADRESSE/TEL QUE PARRAIN"," "))," ")
A29: FIL-023 | G29: =IFERROR(IF(B29=""," ",IF(COUNTIF(C$7:C$28,C29)+COUNTIF(REGISTRE_PARRAINS!C7:C106,C29)>0,"🚫 REFUSÉ — NUMÉRO DÉJÀ ENREGISTRÉ",IF(AND(E29<>"",F29<>"",E29<>F29),"🚫 REFUSÉ — CODE DÉCLARÉ HORS DÉLAI","✅ ÉLIGIBLE")))," ") | H29: =IFERROR(IF(B29="","","À vérifier CRM")," ") | I29: =IFERROR(IF(B29="","","Réf. CRM")," ") | J29: =IFERROR(IF(B29=""," ",IF(COUNTIF(REGISTRE_PARRAINS!C7:C106,C29)>0,"⚠️ MÊME ADRESSE/TEL QUE PARRAIN"," "))," ")
A30: FIL-024 | G30: =IFERROR(IF(B30=""," ",IF(COUNTIF(C$7:C$29,C30)+COUNTIF(REGISTRE_PARRAINS!C7:C106,C30)>0,"🚫 REFUSÉ — NUMÉRO DÉJÀ ENREGISTRÉ",IF(AND(E30<>"",F30<>"",E30<>F30),"🚫 REFUSÉ — CODE DÉCLARÉ HORS DÉLAI","✅ ÉLIGIBLE")))," ") | H30: =IFERROR(IF(B30="","","À vérifier CRM")," ") | I30: =IFERROR(IF(B30="","","Réf. CRM")," ") | J30: =IFERROR(IF(B30=""," ",IF(COUNTIF(REGISTRE_PARRAINS!C7:C106,C30)>0,"⚠️ MÊME ADRESSE/TEL QUE PARRAIN"," "))," ")
A31: FIL-025 | G31: =IFERROR(IF(B31=""," ",IF(COUNTIF(C$7:C$30,C31)+COUNTIF(REGISTRE_PARRAINS!C7:C106,C31)>0,"🚫 REFUSÉ — NUMÉRO DÉJÀ ENREGISTRÉ",IF(AND(E31<>"",F31<>"",E31<>F31),"🚫 REFUSÉ — CODE DÉCLARÉ HORS DÉLAI","✅ ÉLIGIBLE")))," ") | H31: =IFERROR(IF(B31="","","À vérifier CRM")," ") | I31: =IFERROR(IF(B31="","","Réf. CRM")," ") | J31: =IFERROR(IF(B31=""," ",IF(COUNTIF(REGISTRE_PARRAINS!C7:C106,C31)>0,"⚠️ MÊME ADRESSE/TEL QUE PARRAIN"," "))," ")
A32: FIL-026 | G32: =IFERROR(IF(B32=""," ",IF(COUNTIF(C$7:C$31,C32)+COUNTIF(REGISTRE_PARRAINS!C7:C106,C32)>0,"🚫 REFUSÉ — NUMÉRO DÉJÀ ENREGISTRÉ",IF(AND(E32<>"",F32<>"",E32<>F32),"🚫 REFUSÉ — CODE DÉCLARÉ HORS DÉLAI","✅ ÉLIGIBLE")))," ") | H32: =IFERROR(IF(B32="","","À vérifier CRM")," ") | I32: =IFERROR(IF(B32="","","Réf. CRM")," ") | J32: =IFERROR(IF(B32=""," ",IF(COUNTIF(REGISTRE_PARRAINS!C7:C106,C32)>0,"⚠️ MÊME ADRESSE/TEL QUE PARRAIN"," "))," ")
A33: FIL-027 | G33: =IFERROR(IF(B33=""," ",IF(COUNTIF(C$7:C$32,C33)+COUNTIF(REGISTRE_PARRAINS!C7:C106,C33)>0,"🚫 REFUSÉ — NUMÉRO DÉJÀ ENREGISTRÉ",IF(AND(E33<>"",F33<>"",E33<>F33),"🚫 REFUSÉ — CODE DÉCLARÉ HORS DÉLAI","✅ ÉLIGIBLE")))," ") | H33: =IFERROR(IF(B33="","","À vérifier CRM")," ") | I33: =IFERROR(IF(B33="","","Réf. CRM")," ") | J33: =IFERROR(IF(B33=""," ",IF(COUNTIF(REGISTRE_PARRAINS!C7:C106,C33)>0,"⚠️ MÊME ADRESSE/TEL QUE PARRAIN"," "))," ")
A34: FIL-028 | G34: =IFERROR(IF(B34=""," ",IF(COUNTIF(C$7:C$33,C34)+COUNTIF(REGISTRE_PARRAINS!C7:C106,C34)>0,"🚫 REFUSÉ — NUMÉRO DÉJÀ ENREGISTRÉ",IF(AND(E34<>"",F34<>"",E34<>F34),"🚫 REFUSÉ — CODE DÉCLARÉ HORS DÉLAI","✅ ÉLIGIBLE")))," ") | H34: =IFERROR(IF(B34="","","À vérifier CRM")," ") | I34: =IFERROR(IF(B34="","","Réf. CRM")," ") | J34: =IFERROR(IF(B34=""," ",IF(COUNTIF(REGISTRE_PARRAINS!C7:C106,C34)>0,"⚠️ MÊME ADRESSE/TEL QUE PARRAIN"," "))," ")
A35: FIL-029 | G35: =IFERROR(IF(B35=""," ",IF(COUNTIF(C$7:C$34,C35)+COUNTIF(REGISTRE_PARRAINS!C7:C106,C35)>0,"🚫 REFUSÉ — NUMÉRO DÉJÀ ENREGISTRÉ",IF(AND(E35<>"",F35<>"",E35<>F35),"🚫 REFUSÉ — CODE DÉCLARÉ HORS DÉLAI","✅ ÉLIGIBLE")))," ") | H35: =IFERROR(IF(B35="","","À vérifier CRM")," ") | I35: =IFERROR(IF(B35="","","Réf. CRM")," ") | J35: =IFERROR(IF(B35=""," ",IF(COUNTIF(REGISTRE_PARRAINS!C7:C106,C35)>0,"⚠️ MÊME ADRESSE/TEL QUE PARRAIN"," "))," ")
A36: FIL-030 | G36: =IFERROR(IF(B36=""," ",IF(COUNTIF(C$7:C$35,C36)+COUNTIF(REGISTRE_PARRAINS!C7:C106,C36)>0,"🚫 REFUSÉ — NUMÉRO DÉJÀ ENREGISTRÉ",IF(AND(E36<>"",F36<>"",E36<>F36),"🚫 REFUSÉ — CODE DÉCLARÉ HORS DÉLAI","✅ ÉLIGIBLE")))," ") | H36: =IFERROR(IF(B36="","","À vérifier CRM")," ") | I36: =IFERROR(IF(B36="","","Réf. CRM")," ") | J36: =IFERROR(IF(B36=""," ",IF(COUNTIF(REGISTRE_PARRAINS!C7:C106,C36)>0,"⚠️ MÊME ADRESSE/TEL QUE PARRAIN"," "))," ")
A37: FIL-031 | G37: =IFERROR(IF(B37=""," ",IF(COUNTIF(C$7:C$36,C37)+COUNTIF(REGISTRE_PARRAINS!C7:C106,C37)>0,"🚫 REFUSÉ — NUMÉRO DÉJÀ ENREGISTRÉ",IF(AND(E37<>"",F37<>"",E37<>F37),"🚫 REFUSÉ — CODE DÉCLARÉ HORS DÉLAI","✅ ÉLIGIBLE")))," ") | H37: =IFERROR(IF(B37="","","À vérifier CRM")," ") | I37: =IFERROR(IF(B37="","","Réf. CRM")," ") | J37: =IFERROR(IF(B37=""," ",IF(COUNTIF(REGISTRE_PARRAINS!C7:C106,C37)>0,"⚠️ MÊME ADRESSE/TEL QUE PARRAIN"," "))," ")
A38: FIL-032 | G38: =IFERROR(IF(B38=""," ",IF(COUNTIF(C$7:C$37,C38)+COUNTIF(REGISTRE_PARRAINS!C7:C106,C38)>0,"🚫 REFUSÉ — NUMÉRO DÉJÀ ENREGISTRÉ",IF(AND(E38<>"",F38<>"",E38<>F38),"🚫 REFUSÉ — CODE DÉCLARÉ HORS DÉLAI","✅ ÉLIGIBLE")))," ") | H38: =IFERROR(IF(B38="","","À vérifier CRM")," ") | I38: =IFERROR(IF(B38="","","Réf. CRM")," ") | J38: =IFERROR(IF(B38=""," ",IF(COUNTIF(REGISTRE_PARRAINS!C7:C106,C38)>0,"⚠️ MÊME ADRESSE/TEL QUE PARRAIN"," "))," ")
A39: FIL-033 | G39: =IFERROR(IF(B39=""," ",IF(COUNTIF(C$7:C$38,C39)+COUNTIF(REGISTRE_PARRAINS!C7:C106,C39)>0,"🚫 REFUSÉ — NUMÉRO DÉJÀ ENREGISTRÉ",IF(AND(E39<>"",F39<>"",E39<>F39),"🚫 REFUSÉ — CODE DÉCLARÉ HORS DÉLAI","✅ ÉLIGIBLE")))," ") | H39: =IFERROR(IF(B39="","","À vérifier CRM")," ") | I39: =IFERROR(IF(B39="","","Réf. CRM")," ") | J39: =IFERROR(IF(B39=""," ",IF(COUNTIF(REGISTRE_PARRAINS!C7:C106,C39)>0,"⚠️ MÊME ADRESSE/TEL QUE PARRAIN"," "))," ")
A40: FIL-034 | G40: =IFERROR(IF(B40=""," ",IF(COUNTIF(C$7:C$39,C40)+COUNTIF(REGISTRE_PARRAINS!C7:C106,C40)>0,"🚫 REFUSÉ — NUMÉRO DÉJÀ ENREGISTRÉ",IF(AND(E40<>"",F40<>"",E40<>F40),"🚫 REFUSÉ — CODE DÉCLARÉ HORS DÉLAI","✅ ÉLIGIBLE")))," ") | H40: =IFERROR(IF(B40="","","À vérifier CRM")," ") | I40: =IFERROR(IF(B40="","","Réf. CRM")," ") | J40: =IFERROR(IF(B40=""," ",IF(COUNTIF(REGISTRE_PARRAINS!C7:C106,C40)>0,"⚠️ MÊME ADRESSE/TEL QUE PARRAIN"," "))," ")
A41: FIL-035 | G41: =IFERROR(IF(B41=""," ",IF(COUNTIF(C$7:C$40,C41)+COUNTIF(REGISTRE_PARRAINS!C7:C106,C41)>0,"🚫 REFUSÉ — NUMÉRO DÉJÀ ENREGISTRÉ",IF(AND(E41<>"",F41<>"",E41<>F41),"🚫 REFUSÉ — CODE DÉCLARÉ HORS DÉLAI","✅ ÉLIGIBLE")))," ") | H41: =IFERROR(IF(B41="","","À vérifier CRM")," ") | I41: =IFERROR(IF(B41="","","Réf. CRM")," ") | J41: =IFERROR(IF(B41=""," ",IF(COUNTIF(REGISTRE_PARRAINS!C7:C106,C41)>0,"⚠️ MÊME ADRESSE/TEL QUE PARRAIN"," "))," ")
...

Sheet COMMISSIONS_PARRAINAGE
A1: 💰 COMMISSIONS DE PARRAINAGE — LEMI SARL | BRASUS v3.2
A2: Plage nommée : LEMI_PARRAINAGE_COMMISSIONS | Commission = Acompte filleul × 2,5% | Validation DG obligatoire avant paiement
A3: 🔒 CALCUL AUTOMATIQUE — Ne pas modifier | H3: ✏️ WORKFLOW DE VALIDATION — DG uniquement | M3: 🔒 CLAWBACK
A5: DONNÉES COMMISSION (auto) | H5: VALIDATION & PAIEMENT (DG) | M5: CLAWBACK
A6: ID COMMISSION | B6: CODE PARRAIN | C6: NOM PARRAIN | D6: FILLEUL | E6: ACOMPTE FILLEUL (FCFA) | F6: DATE RÉCEPTION ACOMPTE | G6: COMMISSION DUE (FCFA) | H6: STATUT | I6: VALIDÉ DG | J6: DATE VALIDATION | K6: RÉF. TRANSACTION OM/WAVE | L6: NOTES | M6: ALERTE CLAWBACK
A7: COM-001 | B7: =IFERROR(IF(FILLEULS!D7="","",FILLEULS!D7)," ") | C7: =IFERROR(IF(B7=" ","",VLOOKUP(B7,REGISTRE_PARRAINS!A7:B106,2,FALSE))," ") | D7: =IFERROR(IF(FILLEULS!B7="","",FILLEULS!B7)," ") | E7: =IFERROR(IF(FILLEULS!I7="","",FILLEULS!I7)," ") | F7: =IFERROR(IF(FILLEULS!E7="","",FILLEULS!E7)," ") | G7: =IFERROR(IF(AND(FILLEULS!G7="✅ ÉLIGIBLE",E7<>""),ROUND(E7*0.025,0),0),0) | H7: À valider | M7: =IFERROR(IF(AND(FILLEULS!H7="Remboursé",FILLEULS!G7<>""),"🔻 À DÉDUIRE — Commission à reprendre"," ")," ")
A8: COM-002 | B8: =IFERROR(IF(FILLEULS!D8="","",FILLEULS!D8)," ") | C8: =IFERROR(IF(B8=" ","",VLOOKUP(B8,REGISTRE_PARRAINS!A7:B106,2,FALSE))," ") | D8: =IFERROR(IF(FILLEULS!B8="","",FILLEULS!B8)," ") | E8: =IFERROR(IF(FILLEULS!I8="","",FILLEULS!I8)," ") | F8: =IFERROR(IF(FILLEULS!E8="","",FILLEULS!E8)," ") | G8: =IFERROR(IF(AND(FILLEULS!G8="✅ ÉLIGIBLE",E8<>""),ROUND(E8*0.025,0),0),0) | M8: =IFERROR(IF(AND(FILLEULS!H8="Remboursé",FILLEULS!G8<>""),"🔻 À DÉDUIRE — Commission à reprendre"," ")," ")
A9: COM-003 | B9: =IFERROR(IF(FILLEULS!D9="","",FILLEULS!D9)," ") | C9: =IFERROR(IF(B9=" ","",VLOOKUP(B9,REGISTRE_PARRAINS!A7:B106,2,FALSE))," ") | D9: =IFERROR(IF(FILLEULS!B9="","",FILLEULS!B9)," ") | E9: =IFERROR(IF(FILLEULS!I9="","",FILLEULS!I9)," ") | F9: =IFERROR(IF(FILLEULS!E9="","",FILLEULS!E9)," ") | G9: =IFERROR(IF(AND(FILLEULS!G9="✅ ÉLIGIBLE",E9<>""),ROUND(E9*0.025,0),0),0) | M9: =IFERROR(IF(AND(FILLEULS!H9="Remboursé",FILLEULS!G9<>""),"🔻 À DÉDUIRE — Commission à reprendre"," ")," ")
A10: COM-004 | B10: =IFERROR(IF(FILLEULS!D10="","",FILLEULS!D10)," ") | C10: =IFERROR(IF(B10=" ","",VLOOKUP(B10,REGISTRE_PARRAINS!A7:B106,2,FALSE))," ") | D10: =IFERROR(IF(FILLEULS!B10="","",FILLEULS!B10)," ") | E10: =IFERROR(IF(FILLEULS!I10="","",FILLEULS!I10)," ") | F10: =IFERROR(IF(FILLEULS!E10="","",FILLEULS!E10)," ") | G10: =IFERROR(IF(AND(FILLEULS!G10="✅ ÉLIGIBLE",E10<>""),ROUND(E10*0.025,0),0),0) | M10: =IFERROR(IF(AND(FILLEULS!H10="Remboursé",FILLEULS!G10<>""),"🔻 À DÉDUIRE — Commission à reprendre"," ")," ")
A11: COM-005 | B11: =IFERROR(IF(FILLEULS!D11="","",FILLEULS!D11)," ") | C11: =IFERROR(IF(B11=" ","",VLOOKUP(B11,REGISTRE_PARRAINS!A7:B106,2,FALSE))," ") | D11: =IFERROR(IF(FILLEULS!B11="","",FILLEULS!B11)," ") | E11: =IFERROR(IF(FILLEULS!I11="","",FILLEULS!I11)," ") | F11: =IFERROR(IF(FILLEULS!E11="","",FILLEULS!E11)," ") | G11: =IFERROR(IF(AND(FILLEULS!G11="✅ ÉLIGIBLE",E11<>""),ROUND(E11*0.025,0),0),0) | M11: =IFERROR(IF(AND(FILLEULS!H11="Remboursé",FILLEULS!G11<>""),"🔻 À DÉDUIRE — Commission à reprendre"," ")," ")
A12: COM-006 | B12: =IFERROR(IF(FILLEULS!D12="","",FILLEULS!D12)," ") | C12: =IFERROR(IF(B12=" ","",VLOOKUP(B12,REGISTRE_PARRAINS!A7:B106,2,FALSE))," ") | D12: =IFERROR(IF(FILLEULS!B12="","",FILLEULS!B12)," ") | E12: =IFERROR(IF(FILLEULS!I12="","",FILLEULS!I12)," ") | F12: =IFERROR(IF(FILLEULS!E12="","",FILLEULS!E12)," ") | G12: =IFERROR(IF(AND(FILLEULS!G12="✅ ÉLIGIBLE",E12<>""),ROUND(E12*0.025,0),0),0) | M12: =IFERROR(IF(AND(FILLEULS!H12="Remboursé",FILLEULS!G12<>""),"🔻 À DÉDUIRE — Commission à reprendre"," ")," ")
A13: COM-007 | B13: =IFERROR(IF(FILLEULS!D13="","",FILLEULS!D13)," ") | C13: =IFERROR(IF(B13=" ","",VLOOKUP(B13,REGISTRE_PARRAINS!A7:B106,2,FALSE))," ") | D13: =IFERROR(IF(FILLEULS!B13="","",FILLEULS!B13)," ") | E13: =IFERROR(IF(FILLEULS!I13="","",FILLEULS!I13)," ") | F13: =IFERROR(IF(FILLEULS!E13="","",FILLEULS!E13)," ") | G13: =IFERROR(IF(AND(FILLEULS!G13="✅ ÉLIGIBLE",E13<>""),ROUND(E13*0.025,0),0),0) | M13: =IFERROR(IF(AND(FILLEULS!H13="Remboursé",FILLEULS!G13<>""),"🔻 À DÉDUIRE — Commission à reprendre"," ")," ")
A14: COM-008 | B14: =IFERROR(IF(FILLEULS!D14="","",FILLEULS!D14)," ") | C14: =IFERROR(IF(B14=" ","",VLOOKUP(B14,REGISTRE_PARRAINS!A7:B106,2,FALSE))," ") | D14: =IFERROR(IF(FILLEULS!B14="","",FILLEULS!B14)," ") | E14: =IFERROR(IF(FILLEULS!I14="","",FILLEULS!I14)," ") | F14: =IFERROR(IF(FILLEULS!E14="","",FILLEULS!E14)," ") | G14: =IFERROR(IF(AND(FILLEULS!G14="✅ ÉLIGIBLE",E14<>""),ROUND(E14*0.025,0),0),0) | M14: =IFERROR(IF(AND(FILLEULS!H14="Remboursé",FILLEULS!G14<>""),"🔻 À DÉDUIRE — Commission à reprendre"," ")," ")
A15: COM-009 | B15: =IFERROR(IF(FILLEULS!D15="","",FILLEULS!D15)," ") | C15: =IFERROR(IF(B15=" ","",VLOOKUP(B15,REGISTRE_PARRAINS!A7:B106,2,FALSE))," ") | D15: =IFERROR(IF(FILLEULS!B15="","",FILLEULS!B15)," ") | E15: =IFERROR(IF(FILLEULS!I15="","",FILLEULS!I15)," ") | F15: =IFERROR(IF(FILLEULS!E15="","",FILLEULS!E15)," ") | G15: =IFERROR(IF(AND(FILLEULS!G15="✅ ÉLIGIBLE",E15<>""),ROUND(E15*0.025,0),0),0) | M15: =IFERROR(IF(AND(FILLEULS!H15="Remboursé",FILLEULS!G15<>""),"🔻 À DÉDUIRE — Commission à reprendre"," ")," ")
A16: COM-010 | B16: =IFERROR(IF(FILLEULS!D16="","",FILLEULS!D16)," ") | C16: =IFERROR(IF(B16=" ","",VLOOKUP(B16,REGISTRE_PARRAINS!A7:B106,2,FALSE))," ") | D16: =IFERROR(IF(FILLEULS!B16="","",FILLEULS!B16)," ") | E16: =IFERROR(IF(FILLEULS!I16="","",FILLEULS!I16)," ") | F16: =IFERROR(IF(FILLEULS!E16="","",FILLEULS!E16)," ") | G16: =IFERROR(IF(AND(FILLEULS!G16="✅ ÉLIGIBLE",E16<>""),ROUND(E16*0.025,0),0),0) | M16: =IFERROR(IF(AND(FILLEULS!H16="Remboursé",FILLEULS!G16<>""),"🔻 À DÉDUIRE — Commission à reprendre"," ")," ")
A17: COM-011 | B17: =IFERROR(IF(FILLEULS!D17="","",FILLEULS!D17)," ") | C17: =IFERROR(IF(B17=" ","",VLOOKUP(B17,REGISTRE_PARRAINS!A7:B106,2,FALSE))," ") | D17: =IFERROR(IF(FILLEULS!B17="","",FILLEULS!B17)," ") | E17: =IFERROR(IF(FILLEULS!I17="","",FILLEULS!I17)," ") | F17: =IFERROR(IF(FILLEULS!E17="","",FILLEULS!E17)," ") | G17: =IFERROR(IF(AND(FILLEULS!G17="✅ ÉLIGIBLE",E17<>""),ROUND(E17*0.025,0),0),0) | M17: =IFERROR(IF(AND(FILLEULS!H17="Remboursé",FILLEULS!G17<>""),"🔻 À DÉDUIRE — Commission à reprendre"," ")," ")
A18: COM-012 | B18: =IFERROR(IF(FILLEULS!D18="","",FILLEULS!D18)," ") | C18: =IFERROR(IF(B18=" ","",VLOOKUP(B18,REGISTRE_PARRAINS!A7:B106,2,FALSE))," ") | D18: =IFERROR(IF(FILLEULS!B18="","",FILLEULS!B18)," ") | E18: =IFERROR(IF(FILLEULS!I18="","",FILLEULS!I18)," ") | F18: =IFERROR(IF(FILLEULS!E18="","",FILLEULS!E18)," ") | G18: =IFERROR(IF(AND(FILLEULS!G18="✅ ÉLIGIBLE",E18<>""),ROUND(E18*0.025,0),0),0) | M18: =IFERROR(IF(AND(FILLEULS!H18="Remboursé",FILLEULS!G18<>""),"🔻 À DÉDUIRE — Commission à reprendre"," ")," ")
A19: COM-013 | B19: =IFERROR(IF(FILLEULS!D19="","",FILLEULS!D19)," ") | C19: =IFERROR(IF(B19=" ","",VLOOKUP(B19,REGISTRE_PARRAINS!A7:B106,2,FALSE))," ") | D19: =IFERROR(IF(FILLEULS!B19="","",FILLEULS!B19)," ") | E19: =IFERROR(IF(FILLEULS!I19="","",FILLEULS!I19)," ") | F19: =IFERROR(IF(FILLEULS!E19="","",FILLEULS!E19)," ") | G19: =IFERROR(IF(AND(FILLEULS!G19="✅ ÉLIGIBLE",E19<>""),ROUND(E19*0.025,0),0),0) | M19: =IFERROR(IF(AND(FILLEULS!H19="Remboursé",FILLEULS!G19<>""),"🔻 À DÉDUIRE — Commission à reprendre"," ")," ")
A20: COM-014 | B20: =IFERROR(IF(FILLEULS!D20="","",FILLEULS!D20)," ") | C20: =IFERROR(IF(B20=" ","",VLOOKUP(B20,REGISTRE_PARRAINS!A7:B106,2,FALSE))," ") | D20: =IFERROR(IF(FILLEULS!B20="","",FILLEULS!B20)," ") | E20: =IFERROR(IF(FILLEULS!I20="","",FILLEULS!I20)," ") | F20: =IFERROR(IF(FILLEULS!E20="","",FILLEULS!E20)," ") | G20: =IFERROR(IF(AND(FILLEULS!G20="✅ ÉLIGIBLE",E20<>""),ROUND(E20*0.025,0),0),0) | M20: =IFERROR(IF(AND(FILLEULS!H20="Remboursé",FILLEULS!G20<>""),"🔻 À DÉDUIRE — Commission à reprendre"," ")," ")
A21: COM-015 | B21: =IFERROR(IF(FILLEULS!D21="","",FILLEULS!D21)," ") | C21: =IFERROR(IF(B21=" ","",VLOOKUP(B21,REGISTRE_PARRAINS!A7:B106,2,FALSE))," ") | D21: =IFERROR(IF(FILLEULS!B21="","",FILLEULS!B21)," ") | E21: =IFERROR(IF(FILLEULS!I21="","",FILLEULS!I21)," ") | F21: =IFERROR(IF(FILLEULS!E21="","",FILLEULS!E21)," ") | G21: =IFERROR(IF(AND(FILLEULS!G21="✅ ÉLIGIBLE",E21<>""),ROUND(E21*0.025,0),0),0) | M21: =IFERROR(IF(AND(FILLEULS!H21="Remboursé",FILLEULS!G21<>""),"🔻 À DÉDUIRE — Commission à reprendre"," ")," ")
A22: COM-016 | B22: =IFERROR(IF(FILLEULS!D22="","",FILLEULS!D22)," ") | C22: =IFERROR(IF(B22=" ","",VLOOKUP(B22,REGISTRE_PARRAINS!A7:B106,2,FALSE))," ") | D22: =IFERROR(IF(FILLEULS!B22="","",FILLEULS!B22)," ") | E22: =IFERROR(IF(FILLEULS!I22="","",FILLEULS!I22)," ") | F22: =IFERROR(IF(FILLEULS!E22="","",FILLEULS!E22)," ") | G22: =IFERROR(IF(AND(FILLEULS!G22="✅ ÉLIGIBLE",E22<>""),ROUND(E22*0.025,0),0),0) | M22: =IFERROR(IF(AND(FILLEULS!H22="Remboursé",FILLEULS!G22<>""),"🔻 À DÉDUIRE — Commission à reprendre"," ")," ")
A23: COM-017 | B23: =IFERROR(IF(FILLEULS!D23="","",FILLEULS!D23)," ") | C23: =IFERROR(IF(B23=" ","",VLOOKUP(B23,REGISTRE_PARRAINS!A7:B106,2,FALSE))," ") | D23: =IFERROR(IF(FILLEULS!B23="","",FILLEULS!B23)," ") | E23: =IFERROR(IF(FILLEULS!I23="","",FILLEULS!I23)," ") | F23: =IFERROR(IF(FILLEULS!E23="","",FILLEULS!E23)," ") | G23: =IFERROR(IF(AND(FILLEULS!G23="✅ ÉLIGIBLE",E23<>""),ROUND(E23*0.025,0),0),0) | M23: =IFERROR(IF(AND(FILLEULS!H23="Remboursé",FILLEULS!G23<>""),"🔻 À DÉDUIRE — Commission à reprendre"," ")," ")
A24: COM-018 | B24: =IFERROR(IF(FILLEULS!D24="","",FILLEULS!D24)," ") | C24: =IFERROR(IF(B24=" ","",VLOOKUP(B24,REGISTRE_PARRAINS!A7:B106,2,FALSE))," ") | D24: =IFERROR(IF(FILLEULS!B24="","",FILLEULS!B24)," ") | E24: =IFERROR(IF(FILLEULS!I24="","",FILLEULS!I24)," ") | F24: =IFERROR(IF(FILLEULS!E24="","",FILLEULS!E24)," ") | G24: =IFERROR(IF(AND(FILLEULS!G24="✅ ÉLIGIBLE",E24<>""),ROUND(E24*0.025,0),0),0) | M24: =IFERROR(IF(AND(FILLEULS!H24="Remboursé",FILLEULS!G24<>""),"🔻 À DÉDUIRE — Commission à reprendre"," ")," ")
A25: COM-019 | B25: =IFERROR(IF(FILLEULS!D25="","",FILLEULS!D25)," ") | C25: =IFERROR(IF(B25=" ","",VLOOKUP(B25,REGISTRE_PARRAINS!A7:B106,2,FALSE))," ") | D25: =IFERROR(IF(FILLEULS!B25="","",FILLEULS!B25)," ") | E25: =IFERROR(IF(FILLEULS!I25="","",FILLEULS!I25)," ") | F25: =IFERROR(IF(FILLEULS!E25="","",FILLEULS!E25)," ") | G25: =IFERROR(IF(AND(FILLEULS!G25="✅ ÉLIGIBLE",E25<>""),ROUND(E25*0.025,0),0),0) | M25: =IFERROR(IF(AND(FILLEULS!H25="Remboursé",FILLEULS!G25<>""),"🔻 À DÉDUIRE — Commission à reprendre"," ")," ")
A26: COM-020 | B26: =IFERROR(IF(FILLEULS!D26="","",FILLEULS!D26)," ") | C26: =IFERROR(IF(B26=" ","",VLOOKUP(B26,REGISTRE_PARRAINS!A7:B106,2,FALSE))," ") | D26: =IFERROR(IF(FILLEULS!B26="","",FILLEULS!B26)," ") | E26: =IFERROR(IF(FILLEULS!I26="","",FILLEULS!I26)," ") | F26: =IFERROR(IF(FILLEULS!E26="","",FILLEULS!E26)," ") | G26: =IFERROR(IF(AND(FILLEULS!G26="✅ ÉLIGIBLE",E26<>""),ROUND(E26*0.025,0),0),0) | M26: =IFERROR(IF(AND(FILLEULS!H26="Remboursé",FILLEULS!G26<>""),"🔻 À DÉDUIRE — Commission à reprendre"," ")," ")
A27: COM-021 | B27: =IFERROR(IF(FILLEULS!D27="","",FILLEULS!D27)," ") | C27: =IFERROR(IF(B27=" ","",VLOOKUP(B27,REGISTRE_PARRAINS!A7:B106,2,FALSE))," ") | D27: =IFERROR(IF(FILLEULS!B27="","",FILLEULS!B27)," ") | E27: =IFERROR(IF(FILLEULS!I27="","",FILLEULS!I27)," ") | F27: =IFERROR(IF(FILLEULS!E27="","",FILLEULS!E27)," ") | G27: =IFERROR(IF(AND(FILLEULS!G27="✅ ÉLIGIBLE",E27<>""),ROUND(E27*0.025,0),0),0) | M27: =IFERROR(IF(AND(FILLEULS!H27="Remboursé",FILLEULS!G27<>""),"🔻 À DÉDUIRE — Commission à reprendre"," ")," ")
A28: COM-022 | B28: =IFERROR(IF(FILLEULS!D28="","",FILLEULS!D28)," ") | C28: =IFERROR(IF(B28=" ","",VLOOKUP(B28,REGISTRE_PARRAINS!A7:B106,2,FALSE))," ") | D28: =IFERROR(IF(FILLEULS!B28="","",FILLEULS!B28)," ") | E28: =IFERROR(IF(FILLEULS!I28="","",FILLEULS!I28)," ") | F28: =IFERROR(IF(FILLEULS!E28="","",FILLEULS!E28)," ") | G28: =IFERROR(IF(AND(FILLEULS!G28="✅ ÉLIGIBLE",E28<>""),ROUND(E28*0.025,0),0),0) | M28: =IFERROR(IF(AND(FILLEULS!H28="Remboursé",FILLEULS!G28<>""),"🔻 À DÉDUIRE — Commission à reprendre"," ")," ")
A29: COM-023 | B29: =IFERROR(IF(FILLEULS!D29="","",FILLEULS!D29)," ") | C29: =IFERROR(IF(B29=" ","",VLOOKUP(B29,REGISTRE_PARRAINS!A7:B106,2,FALSE))," ") | D29: =IFERROR(IF(FILLEULS!B29="","",FILLEULS!B29)," ") | E29: =IFERROR(IF(FILLEULS!I29="","",FILLEULS!I29)," ") | F29: =IFERROR(IF(FILLEULS!E29="","",FILLEULS!E29)," ") | G29: =IFERROR(IF(AND(FILLEULS!G29="✅ ÉLIGIBLE",E29<>""),ROUND(E29*0.025,0),0),0) | M29: =IFERROR(IF(AND(FILLEULS!H29="Remboursé",FILLEULS!G29<>""),"🔻 À DÉDUIRE — Commission à reprendre"," ")," ")
A30: COM-024 | B30: =IFERROR(IF(FILLEULS!D30="","",FILLEULS!D30)," ") | C30: =IFERROR(IF(B30=" ","",VLOOKUP(B30,REGISTRE_PARRAINS!A7:B106,2,FALSE))," ") | D30: =IFERROR(IF(FILLEULS!B30="","",FILLEULS!B30)," ") | E30: =IFERROR(IF(FILLEULS!I30="","",FILLEULS!I30)," ") | F30: =IFERROR(IF(FILLEULS!E30="","",FILLEULS!E30)," ") | G30: =IFERROR(IF(AND(FILLEULS!G30="✅ ÉLIGIBLE",E30<>""),ROUND(E30*0.025,0),0),0) | M30: =IFERROR(IF(AND(FILLEULS!H30="Remboursé",FILLEULS!G30<>""),"🔻 À DÉDUIRE — Commission à reprendre"," ")," ")
A31: COM-025 | B31: =IFERROR(IF(FILLEULS!D31="","",FILLEULS!D31)," ") | C31: =IFERROR(IF(B31=" ","",VLOOKUP(B31,REGISTRE_PARRAINS!A7:B106,2,FALSE))," ") | D31: =IFERROR(IF(FILLEULS!B31="","",FILLEULS!B31)," ") | E31: =IFERROR(IF(FILLEULS!I31="","",FILLEULS!I31)," ") | F31: =IFERROR(IF(FILLEULS!E31="","",FILLEULS!E31)," ") | G31: =IFERROR(IF(AND(FILLEULS!G31="✅ ÉLIGIBLE",E31<>""),ROUND(E31*0.025,0),0),0) | M31: =IFERROR(IF(AND(FILLEULS!H31="Remboursé",FILLEULS!G31<>""),"🔻 À DÉDUIRE — Commission à reprendre"," ")," ")
A32: COM-026 | B32: =IFERROR(IF(FILLEULS!D32="","",FILLEULS!D32)," ") | C32: =IFERROR(IF(B32=" ","",VLOOKUP(B32,REGISTRE_PARRAINS!A7:B106,2,FALSE))," ") | D32: =IFERROR(IF(FILLEULS!B32="","",FILLEULS!B32)," ") | E32: =IFERROR(IF(FILLEULS!I32="","",FILLEULS!I32)," ") | F32: =IFERROR(IF(FILLEULS!E32="","",FILLEULS!E32)," ") | G32: =IFERROR(IF(AND(FILLEULS!G32="✅ ÉLIGIBLE",E32<>""),ROUND(E32*0.025,0),0),0) | M32: =IFERROR(IF(AND(FILLEULS!H32="Remboursé",FILLEULS!G32<>""),"🔻 À DÉDUIRE — Commission à reprendre"," ")," ")
A33: COM-027 | B33: =IFERROR(IF(FILLEULS!D33="","",FILLEULS!D33)," ") | C33: =IFERROR(IF(B33=" ","",VLOOKUP(B33,REGISTRE_PARRAINS!A7:B106,2,FALSE))," ") | D33: =IFERROR(IF(FILLEULS!B33="","",FILLEULS!B33)," ") | E33: =IFERROR(IF(FILLEULS!I33="","",FILLEULS!I33)," ") | F33: =IFERROR(IF(FILLEULS!E33="","",FILLEULS!E33)," ") | G33: =IFERROR(IF(AND(FILLEULS!G33="✅ ÉLIGIBLE",E33<>""),ROUND(E33*0.025,0),0),0) | M33: =IFERROR(IF(AND(FILLEULS!H33="Remboursé",FILLEULS!G33<>""),"🔻 À DÉDUIRE — Commission à reprendre"," ")," ")
A34: COM-028 | B34: =IFERROR(IF(FILLEULS!D34="","",FILLEULS!D34)," ") | C34: =IFERROR(IF(B34=" ","",VLOOKUP(B34,REGISTRE_PARRAINS!A7:B106,2,FALSE))," ") | D34: =IFERROR(IF(FILLEULS!B34="","",FILLEULS!B34)," ") | E34: =IFERROR(IF(FILLEULS!I34="","",FILLEULS!I34)," ") | F34: =IFERROR(IF(FILLEULS!E34="","",FILLEULS!E34)," ") | G34: =IFERROR(IF(AND(FILLEULS!G34="✅ ÉLIGIBLE",E34<>""),ROUND(E34*0.025,0),0),0) | M34: =IFERROR(IF(AND(FILLEULS!H34="Remboursé",FILLEULS!G34<>""),"🔻 À DÉDUIRE — Commission à reprendre"," ")," ")
A35: COM-029 | B35: =IFERROR(IF(FILLEULS!D35="","",FILLEULS!D35)," ") | C35: =IFERROR(IF(B35=" ","",VLOOKUP(B35,REGISTRE_PARRAINS!A7:B106,2,FALSE))," ") | D35: =IFERROR(IF(FILLEULS!B35="","",FILLEULS!B35)," ") | E35: =IFERROR(IF(FILLEULS!I35="","",FILLEULS!I35)," ") | F35: =IFERROR(IF(FILLEULS!E35="","",FILLEULS!E35)," ") | G35: =IFERROR(IF(AND(FILLEULS!G35="✅ ÉLIGIBLE",E35<>""),ROUND(E35*0.025,0),0),0) | M35: =IFERROR(IF(AND(FILLEULS!H35="Remboursé",FILLEULS!G35<>""),"🔻 À DÉDUIRE — Commission à reprendre"," ")," ")
A36: COM-030 | B36: =IFERROR(IF(FILLEULS!D36="","",FILLEULS!D36)," ") | C36: =IFERROR(IF(B36=" ","",VLOOKUP(B36,REGISTRE_PARRAINS!A7:B106,2,FALSE))," ") | D36: =IFERROR(IF(FILLEULS!B36="","",FILLEULS!B36)," ") | E36: =IFERROR(IF(FILLEULS!I36="","",FILLEULS!I36)," ") | F36: =IFERROR(IF(FILLEULS!E36="","",FILLEULS!E36)," ") | G36: =IFERROR(IF(AND(FILLEULS!G36="✅ ÉLIGIBLE",E36<>""),ROUND(E36*0.025,0),0),0) | M36: =IFERROR(IF(AND(FILLEULS!H36="Remboursé",FILLEULS!G36<>""),"🔻 À DÉDUIRE — Commission à reprendre"," ")," ")
A37: COM-031 | B37: =IFERROR(IF(FILLEULS!D37="","",FILLEULS!D37)," ") | C37: =IFERROR(IF(B37=" ","",VLOOKUP(B37,REGISTRE_PARRAINS!A7:B106,2,FALSE))," ") | D37: =IFERROR(IF(FILLEULS!B37="","",FILLEULS!B37)," ") | E37: =IFERROR(IF(FILLEULS!I37="","",FILLEULS!I37)," ") | F37: =IFERROR(IF(FILLEULS!E37="","",FILLEULS!E37)," ") | G37: =IFERROR(IF(AND(FILLEULS!G37="✅ ÉLIGIBLE",E37<>""),ROUND(E37*0.025,0),0),0) | M37: =IFERROR(IF(AND(FILLEULS!H37="Remboursé",FILLEULS!G37<>""),"🔻 À DÉDUIRE — Commission à reprendre"," ")," ")
A38: COM-032 | B38: =IFERROR(IF(FILLEULS!D38="","",FILLEULS!D38)," ") | C38: =IFERROR(IF(B38=" ","",VLOOKUP(B38,REGISTRE_PARRAINS!A7:B106,2,FALSE))," ") | D38: =IFERROR(IF(FILLEULS!B38="","",FILLEULS!B38)," ") | E38: =IFERROR(IF(FILLEULS!I38="","",FILLEULS!I38)," ") | F38: =IFERROR(IF(FILLEULS!E38="","",FILLEULS!E38)," ") | G38: =IFERROR(IF(AND(FILLEULS!G38="✅ ÉLIGIBLE",E38<>""),ROUND(E38*0.025,0),0),0) | M38: =IFERROR(IF(AND(FILLEULS!H38="Remboursé",FILLEULS!G38<>""),"🔻 À DÉDUIRE — Commission à reprendre"," ")," ")
A39: COM-033 | B39: =IFERROR(IF(FILLEULS!D39="","",FILLEULS!D39)," ") | C39: =IFERROR(IF(B39=" ","",VLOOKUP(B39,REGISTRE_PARRAINS!A7:B106,2,FALSE))," ") | D39: =IFERROR(IF(FILLEULS!B39="","",FILLEULS!B39)," ") | E39: =IFERROR(IF(FILLEULS!I39="","",FILLEULS!I39)," ") | F39: =IFERROR(IF(FILLEULS!E39="","",FILLEULS!E39)," ") | G39: =IFERROR(IF(AND(FILLEULS!G39="✅ ÉLIGIBLE",E39<>""),ROUND(E39*0.025,0),0),0) | M39: =IFERROR(IF(AND(FILLEULS!H39="Remboursé",FILLEULS!G39<>""),"🔻 À DÉDUIRE — Commission à reprendre"," ")," ")
A40: COM-034 | B40: =IFERROR(IF(FILLEULS!D40="","",FILLEULS!D40)," ") | C40: =IFERROR(IF(B40=" ","",VLOOKUP(B40,REGISTRE_PARRAINS!A7:B106,2,FALSE))," ") | D40: =IFERROR(IF(FILLEULS!B40="","",FILLEULS!B40)," ") | E40: =IFERROR(IF(FILLEULS!I40="","",FILLEULS!I40)," ") | F40: =IFERROR(IF(FILLEULS!E40="","",FILLEULS!E40)," ") | G40: =IFERROR(IF(AND(FILLEULS!G40="✅ ÉLIGIBLE",E40<>""),ROUND(E40*0.025,0),0),0) | M40: =IFERROR(IF(AND(FILLEULS!H40="Remboursé",FILLEULS!G40<>""),"🔻 À DÉDUIRE — Commission à reprendre"," ")," ")
A41: COM-035 | B41: =IFERROR(IF(FILLEULS!D41="","",FILLEULS!D41)," ") | C41: =IFERROR(IF(B41=" ","",VLOOKUP(B41,REGISTRE_PARRAINS!A7:B106,2,FALSE))," ") | D41: =IFERROR(IF(FILLEULS!B41="","",FILLEULS!B41)," ") | E41: =IFERROR(IF(FILLEULS!I41="","",FILLEULS!I41)," ") | F41: =IFERROR(IF(FILLEULS!E41="","",FILLEULS!E41)," ") | G41: =IFERROR(IF(AND(FILLEULS!G41="✅ ÉLIGIBLE",E41<>""),ROUND(E41*0.025,0),0),0) | M41: =IFERROR(IF(AND(FILLEULS!H41="Remboursé",FILLEULS!G41<>""),"🔻 À DÉDUIRE — Commission à reprendre"," ")," ")
...

Sheet ALERTES_FRAUDE
A1: 🚨 ALERTES FRAUDE — VERROUS 1 à 5 | LEMI SARL | BRASUS v3.2
A2: 🔒 Toutes les colonnes sont verrouillées sauf STATUT TRAITEMENT (réservé DG) | Calcul auto depuis verrous
A3: BLOQUANT = Opération refusée automatiquement | REVUE MANUELLE = Signal orange, flux non interrompu
A5: DATE DÉTECTION | B5: TYPE SIGNAL | C5: PARRAIN CONCERNÉ | D5: FILLEUL CONCERNÉ | E5: NIVEAU | F5: DÉTAIL | G5: STATUT TRAITEMENT

Sheet TACHES_PERIODIQUES
A1: 📋 TÂCHES PÉRIODIQUES — MODULE PARRAINAGE | LEMI SARL | BRASUS v3.2
A2: 🔒 Zone A — Planning opérationnel du programme de parrainage — Lecture seule
A4: FRÉQUENCE | B4: TÂCHE | C4: RESPONSABLE | D4: DÉLAI | E4: STATUT
A5: QUOTIDIEN | B5: Vérifier les nouveaux filleuls déclarés — contrôler éligibilité (Verrous 1-2) | C5: Resp. Commercial | D5: 10h00 | E5: 🟢
B6: Traiter les commissions au statut "À valider" — valider ou refuser | C6: DG | D6: 17h00 | E6: 🟢
B7: Vérifier les alertes fraude du jour — traiter les signaux bloquants | C7: DG | D7: 17h30 | E7: 🟢
A8: HEBDOMADAIRE | B8: Vérifier ALERTES_FRAUDE — traiter chaque signal orange (Verrou 5) | C8: DG | D8: Vendredi 16h | E8: 🟢
B9: Effectuer les virements Orange Money/Wave des commissions validées DG | C9: Resp. Financier | D9: Vendredi | E9: 🟢
B10: Mettre à jour le classement Top 5 parrains — communiquer au DG | C10: Resp. Commercial | D10: Vendredi | E10: 🟢
A11: MENSUEL | B11: Rapport parrainage mensuel — nb filleuls, montant versé, top parrains, ROI | C11: Resp. Commercial | D11: J+2 du mois | E11: 🟢
B12: Vérifier les clawbacks du mois — déductions correctement appliquées | C12: Resp. Financier | D12: J+3 du mois | E12: 🟢
B13: Intégrer les commissions versées dans 02_FINANCE charges mensuelles | C13: Resp. Financier | D13: J+5 du mois | E13: 🟢
A14: TRIMESTRIEL | B14: Bilan du programme — ROI parrainage vs coût acquisition Meta Ads | C14: DG + DMA | D14: Fin trimestre | E14: 🟢
B15: Évaluer le taux de commission (2,5%) — ajuster si nécessaire | C15: DG + DMA | D15: Fin trimestre | E15: 🟢
A16: ANNUEL | B16: Décision de reconduction / ajustement du taux de commission | C16: DG | D16: Avril 2027 | E16: 🟢
A18: CHECKLIST DE VALIDATION DU MODULE
A19: ✅ | B19: Code parrain généré automatiquement et unique (LEMI-PARR-XXX)
A20: ✅ | B20: Verrou 1 (unicité téléphone) : actif — NB.SI bloque les doublons
A21: ✅ | B21: Verrou 2 (déclaration 1er contact) : actif — comparaison dates
A22: ✅ | B22: Verrou 3 (clawback) : ligne de dette auto si remboursement < 30j
A23: ✅ | B23: Verrou 4 : aucune commission → Payé sans case DG cochée + ref. transaction
A24: ✅ | B24: Verrou 5 (signaux faibles) : alertes orange non bloquantes activées
A25: ✅ | B25: Commission = Acompte filleul × 2,5% — formule vérifiée
A26: ✅ | B26: Référence externe vers CRM fonctionnelle (pas de ressaisie)
A27: ✅ | B27: Commissions intégrées dans FINANCE charges mensuelles
A28: ✅ | B28: KPI parrainage visibles dans DASHBOARD
A29: ✅ | B29: Couleurs et verrouillage conformes au système BRASUS existant
