Workbook

Sheet 1 — MISSIONS DU JOUR
A1: LEMI SARL | RESPONSABLE FINANCE | MISSIONS DU JOUR — [DATE DU JOUR] | BRASUS v3.2
A2: ZONE A — GÉNÉRÉ PAR BRASUS 🔒 (Ne pas modifier) | F2: ZONE B — VOTRE SAISIE ✏️ (Remplissez ici)
A3: N° | B3: MISSION | C3: OBJECTIF LIÉ | D3: RÉSULTAT ATTENDU | E3: PRIORITÉ | F3: STATUT | G3: ACTIONS RÉALISÉES | H3: RÉSULTAT OBTENU | I3: DIFFICULTÉ | J3: ESCALADE
A4: 1 | B4: Enregistrer tous les encaissements et décaissements du jour (Wave, Orange Money, virement bancaire) | C4: Trésorerie à jour en temps réel | Solde journalier calculé et validé avant 18h | D4: Journal de caisse complet — Trésorerie disponible communiquée au DG via WhatsApp | E4: HAUTE
A5: 2 | B5: Vérifier les échéances Tontine Habitat du mois — identifier les retards de paiement clients | C5: 0 impayé > J+3 non détecté | Liste retards transmise au Commercial pour relance immédiate | D5: Liste impayés par client (montant, jours de retard, pénalités J+7 calculées) envoyée Commercial + DG | E5: HAUTE
A6: 3 | B6: Appliquer le protocole recouvrement LEMI SARL pour tous les clients en retard > J+7 | C6: 100% des retards > J+7 avec pénalité 1%/semaine calculée et relevé envoyé au client | D6: Pénalités calculées et communiquées aux clients — J+30 signalés pour suspension formelle des travaux | E6: HAUTE
A7: 4 | B7: Préparer les devis, factures et contrats Tontine demandés par le département Commercial | C7: Délai de traitement < 24h | Tous documents > 100 000 FCFA validés par DG avant envoi | D7: Documents traités, archivés dans Google Drive /Facturation/ — Numérotation séquentielle respectée | E7: MOYENNE
A8: 5 | B8: Calculer la marge brute des chantiers livrés cette semaine (matériaux + MO vs CA encaissé) | C8: Marge brute ≥ 22% minimum | Alerte si marge < 22% — analyse dérive coûts nécessaire | D8: Rapport de marge soumis au DG — Recommandations si marge < cible identifiées et documentées | E8: MOYENNE
A9: ⏰ Clôture automatique à 18h00 — Zone B verrouillée après clôture | F9: Horodatage clôture :

Sheet 2 — EXÉCUTION JOURNALIÈRE
A1: ZONE B — EXÉCUTION JOURNALIÈRE ✏️ | LEMI SARL | Toutes les colonnes sont à remplir
A2: HEURE | B2: ACTION RÉALISÉE | C2: RÉSULTAT OBTENU | D2: BILAN / COMMENTAIRE | E2: BESOIN / ESCALADE
A13: BRASUS analyse ces données chaque soir à 18h00 pour calculer votre taux de performance

Sheet 3 — MES PERFORMANCES
A1: ZONE A — MES PERFORMANCES — RESPONSABLE FINANCE | LEMI SARL | BRASUS v3.2
A2: 🔒 Calculé automatiquement par BRASUS à 18h00 chaque jour — Ne pas modifier
A3: INDICATEUR | B3: VALEUR | C3: BASE DE CALCUL | D3: COMMENTAIRE BRASUS
A4: TAUX D'EXÉCUTION JOURNALIER | B4: [ Calculé à 18h00 ] | C4: Statuts FAIT dans Onglet 1 Zone B
A5: TAUX D'EXÉCUTION HEBDOMADAIRE | B5: [ Moy. 5 jours ] | C5: Moyenne des taux journaliers
A6: TAUX D'EXÉCUTION MENSUEL | B6: [ Moy. mensuelle ] | C6: Moyenne des taux du mois en cours
A7: TAUX D'EXÉCUTION ANNUEL | B7: [ Moy. annuelle ] | C7: Moyenne depuis le 1er janvier
A9: NIVEAU DE PERFORMANCE | B9: [ Calculé ] | C9: Basé sur le taux journalier du jour
A10: MISSIONS RÉALISÉES / TOTAL | B10: [ Calculé ] | C10: Nombre de FAIT sur 5 missions
A11: DATE DE DERNIÈRE MISE À JOUR | B11: [ Horodatage ] | C11: Clôture automatique 18h00
A12: NIVEAUX DE PERFORMANCE BRASUS
A13: 90 – 100% | B13: 🟢 EXCELLENT | C13: Message de reconnaissance BRASUS
A14: 75 – 89% | B14: 🔵 BON | C14: Encouragement + 1 conseil
A15: 60 – 74% | B15: 🟡 MOYEN | C15: Plan d'amélioration — Onglet 5
A16: 40 – 59% | B16: 🟠 INSUFFISANT | C16: Alerte RH + plan de soutien
A17: < 40% | B17: 🔴 CRITIQUE | C17: Alerte Direction immédiate

Sheet 4 — MON HISTORIQUE
A1: ZONE A — MON HISTORIQUE — RESPONSABLE FINANCE | LEMI SARL | Archivage automatique BRASUS
A2: 🔒 Archives horodatées automatiquement à 18h00 par BRASUS — Ne pas modifier
A3: DATE | B3: MISSIONS RÉALISÉES | C3: TAUX (%) | D3: NIVEAU | E3: COMMENTAIRE BRASUS

Sheet 5 — MON PLAN D'AMÉLIORATION
A1: ZONE A — PLAN D'AMÉLIORATION HEBDOMADAIRE — RESPONSABLE FINANCE | LEMI SARL
A2: 🔒 Généré chaque vendredi soir par BRASUS selon vos performances de la semaine | Ne pas modifier
A3: Semaine du : [DATE DÉBUT] au [DATE FIN] | Taux hebdomadaire : [X]% | Niveau : [NIVEAU]
A4: # | B4: RECOMMANDATION BRASUS | C4: COMMENT FAIRE | D4: DÉLAI | E4: IMPACT
A5: 1 | B5: [ Recommandation BRASUS — Générée chaque vendredi selon vos performances ] | C5: Coller ici le résultat de Claude / BRASUS | D5: Semaine suivante | E5: Moyen
A6: 2 | B6: [ Recommandation BRASUS — Générée chaque vendredi selon vos performances ] | C6: Coller ici le résultat de Claude / BRASUS | D6: Semaine suivante | E6: Moyen
A7: 3 | B7: [ Recommandation BRASUS — Point fort à renforcer ] | C7: Basé sur votre meilleure journée de la semaine | D7: Continu | E7: Élevé
A8: 4 | B8: [ Point de vigilance BRASUS ] | C8: Basé sur votre journée la plus faible | D8: Immédiat | E8: Élevé
A9: 5 | B9: [ Alerte BRASUS si taux < 60% ] | C9: Plan de redressement personnalisé | D9: Immédiat | E9: Critique

Sheet TACHES_PERIODIQUES
A1: 📋 TÂCHES PÉRIODIQUES — FINANCE | LEMI SARL | BRASUS v3.2
A2: 🔒 Planning operationnel Finance — Inclut la gestion des commissions parrainage
A3: 🔒 ZONE A — Taches et delais (verrouille) | E3: ✏️ ZONE B — Suivi execution (deverrouille)
A4: FRÉQUENCE | B4: TÂCHE | C4: RESPONSABLE | D4: DÉLAI | E4: STATUT | F4: DATE EXÉCUTION | G4: COMMENTAIRES
A5: QUOTIDIEN | B5: Enregistrer tous les encaissements et decaissements du jour dans le journal de caisse | C5: Resp. Finance | D5: 17h30
B6: Communiquer la tresorerie disponible au DG via WhatsApp | C6: Resp. Finance | D6: 18h00
B7: Verifier les echeances Tontine Habitat — identifier retards > J+3 | C7: Resp. Finance | D7: 16h00
A8: HEBDOMADAIRE | B8: Executer les virements Orange Money/Wave des commissions parrainage 'Valide DG' | C8: Resp. Finance | D8: Vendredi
B9: Saisir chaque commission versee dans le journal (categorie 'Commission parrainage') | C9: Resp. Finance | D9: Vendredi
B10: Calculer la marge brute des chantiers livres de la semaine | C10: Resp. Finance | D10: Vendredi 16h
A11: MENSUEL | B11: Rapport tresorerie mensuel : encaissements, decaissements, solde | C11: Resp. Finance | D11: J+2 du mois
B12: Verifier le total mensuel des commissions versees vs charges mensuelles | C12: Resp. Finance | D12: J+3 du mois
B13: Appliquer les deductions clawback identifiees dans 08_PARRAINAGE.xlsx | C13: Resp. Finance | D13: J+3 du mois
B14: Bilan recouvrement : clients en retard, penalites, suspensions | C14: Resp. Finance | D14: J+5 du mois
A15: TRIMESTRIEL | B15: Analyse des marges par type de projet (Studio, T2, T3, PDL) | C15: Resp. Finance + DG | D15: Fin de trimestre
A16: ANNUEL | B16: Cloture comptable annuelle — preparation bilan | C16: Resp. Finance + DG | D16: Janvier 2027
A17: Nouvelles taches issues du module 08_PARRAINAGE.xlsx — Integrées par BRASUS v3.2

Sheet DASHBOARD TRESORERIE
A1: 📊 DASHBOARD TRÉSORERIE — LEMI SARL | BRASUS v3.2
A2: 🔒 Consolidation automatique depuis les onglets mensuels — Lecture seule
B4: KPI FLASH — TRÉSORERIE
B5: Total encaissé cumul 13 mois (FCFA) | C5: =IFERROR(SUM(C14:C26),0) -> 0
B6: Total décaissé cumul (FCFA) | C6: =IFERROR(SUM(D14:D26),0) -> 0
B7: Solde net trésorerie (FCFA) | C7: =IFERROR(C5-C6,0) -> 0
B8: Nb opérations décaissement | C8: =IFERROR(COUNTA(D14:D26)-COUNTBLANK(D14:D26),0) -> 0
B9: Postes en dépassement budget | C9: =0 -> 0
B12: RÉCAPITULATIF MENSUEL — ENCAISSEMENTS
B13: MOIS | C13: ENCAISSÉ (FCFA) | D13: DÉCAISSÉ (FCFA) | E13: SOLDE NET
B14: Juin 2026 | C14: 0 | D14: 0 | E14: =IFERROR(C14-D14,0) -> 0
B15: Juil 2026 | C15: 0 | D15: 0 | E15: =IFERROR(C15-D15,0) -> 0
B16: Août 2026 | C16: 0 | D16: 0 | E16: =IFERROR(C16-D16,0) -> 0
B17: Sep 2026 | C17: 0 | D17: 0 | E17: =IFERROR(C17-D17,0) -> 0
B18: Oct 2026 | C18: 0 | D18: 0 | E18: =IFERROR(C18-D18,0) -> 0
B19: Nov 2026 | C19: 0 | D19: 0 | E19: =IFERROR(C19-D19,0) -> 0
B20: Déc 2026 | C20: 0 | D20: 0 | E20: =IFERROR(C20-D20,0) -> 0
B21: Jan 2027 | C21: 0 | D21: 0 | E21: =IFERROR(C21-D21,0) -> 0
B22: Fév 2027 | C22: 0 | D22: 0 | E22: =IFERROR(C22-D22,0) -> 0
B23: Mar 2027 | C23: 0 | D23: 0 | E23: =IFERROR(C23-D23,0) -> 0
B24: Avr 2027 | C24: 0 | D24: 0 | E24: =IFERROR(C24-D24,0) -> 0
B25: Mai 2027 | C25: 0 | D25: 0 | E25: =IFERROR(C25-D25,0) -> 0
B26: Juin 2027 | C26: 0 | D26: 0 | E26: =IFERROR(C26-D26,0) -> 0
B27: TOTAL 13 MOIS | C27: =IFERROR(SUM(C14:C26),0) -> 0 | D27: =IFERROR(SUM(D14:D26),0) -> 0 | E27: =IFERROR(C27-D27,0) -> 0

Sheet SYNC_FINANCE
A3: ✏️ ZONE A — Identité Prospect (saisie CM) | J3: ✏️ ZONE B — Dates & Montants (saisie Resp. Financier) | M3: ⚙️ AUTO — Total | N3: ✏️ ZONE B — Date Levée Conditions | O3: ⚙️ AUTO — ALERTE JOURS
A4: N° | B4: N° IDENTIFIANT | C4: NOM & PRÉNOMS DU PROSPECT | D4: SOURCE DU PROSPECT | E4: DATE PREMIER CONTACT | F4: JOUR | G4: CONTACT TÉLÉPHONIQUE & WHATSAPP | H4: PROFESSION | I4: NUMÉRO DU CONTRAT | J4: DATE DE SIGNATURE DES CONTRATS | K4: APPORT INITIAL (30%) À LA SIGNATURE | L4: MONTANT PAIEMENT À LA SIGNATURE | M4: TOTAL PAIEMENT À LA SIGNATURE | N4: DATE D'ACHÈVEMENT PRÉVUE LEVÉE DE CONDITIONS | O4: NOMBRE DE JOURS RESTANTS LEVÉE DE CONDITIONS
A5: 1 | C5: TANOH KONAN GERVAIS ARMAND | D5: Prospection directe | E5: 15/03/2026 | F5: =IFERROR(IF(E5="","",TEXT(E5,"DDDD")),"" ) -> 15/03/2026 | K5: 0 | L5: 0 | M5: =IFERROR(IF(K5+L5=0,"—",K5+L5),"—") -> — | O5: =IFERROR(IF(N5="","—",MAX(0,INT(N5)-INT(TODAY()))),"—") -> —
A6: 2 | C6: N'DRI ép. NGBESSO AKISSI ELIANE | D6: Réseaux sociaux | E6: 24/09/2024 | F6: =IFERROR(IF(E6="","",TEXT(E6,"DDDD")),"" ) -> 24/09/2024 | G6: 0033 651 75 83 12 | K6: 0 | L6: 0 | M6: =IFERROR(IF(K6+L6=0,"—",K6+L6),"—") -> — | O6: =IFERROR(IF(N6="","—",MAX(0,INT(N6)-INT(TODAY()))),"—") -> —
A7: 3 | C7: N'GORAN KOFFI | D7: Parrainage | E7: 15/03/2026 | F7: =IFERROR(IF(E7="","",TEXT(E7,"DDDD")),"" ) -> 15/03/2026 | G7: 788738933 | K7: 0 | L7: 0 | M7: =IFERROR(IF(K7+L7=0,"—",K7+L7),"—") -> — | O7: =IFERROR(IF(N7="","—",MAX(0,INT(N7)-INT(TODAY()))),"—") -> —
A8: 4 | C8: KOUASSI VINCENT DE PAUL ASSOUMOU | D8: Prospection directe | E8: 04/11/2024 | F8: =IFERROR(IF(E8="","",TEXT(E8,"DDDD")),"" ) -> Thursday | G8: 708010188 | K8: 0 | L8: 0 | M8: =IFERROR(IF(K8+L8=0,"—",K8+L8),"—") -> — | O8: =IFERROR(IF(N8="","—",MAX(0,INT(N8)-INT(TODAY()))),"—") -> —
A9: 5 | C9: KOUASSI HONORE | D9: Prospection directe | E9: 07/08/2025 | F9: =IFERROR(IF(E9="","",TEXT(E9,"DDDD")),"" ) -> Tuesday | G9: 103319771 | K9: 0 | L9: 0 | M9: =IFERROR(IF(K9+L9=0,"—",K9+L9),"—") -> — | O9: =IFERROR(IF(N9="","—",MAX(0,INT(N9)-INT(TODAY()))),"—") -> —
A10: 6 | C10: AKISSI ELIANE KONAN | D10: Prospection directe | E10: 25/08/2025 | F10: =IFERROR(IF(E10="","",TEXT(E10,"DDDD")),"" ) -> 25/08/2025 | G10: 0102197828 | K10: 0 | L10: 0 | M10: =IFERROR(IF(K10+L10=0,"—",K10+L10),"—") -> — | O10: =IFERROR(IF(N10="","—",MAX(0,INT(N10)-INT(TODAY()))),"—") -> —
A11: 7 | C11: BROU LAMBERT KOUASSI | D11: Prospection directe | E11: 30/08/2025 | F11: =IFERROR(IF(E11="","",TEXT(E11,"DDDD")),"" ) -> 30/08/2025 | G11: 0708937533 | K11: 0 | L11: 0 | M11: =IFERROR(IF(K11+L11=0,"—",K11+L11),"—") -> — | O11: =IFERROR(IF(N11="","—",MAX(0,INT(N11)-INT(TODAY()))),"—") -> —
A12: 8 | C12: DJEDRI KOUAKOU JEAN PIERRE | D12: Prospection directe | E12: 10/10/2025 | F12: =IFERROR(IF(E12="","",TEXT(E12,"DDDD")),"" ) -> Friday | G12: 078866828 | K12: 0 | L12: 0 | M12: =IFERROR(IF(K12+L12=0,"—",K12+L12),"—") -> — | O12: =IFERROR(IF(N12="","—",MAX(0,INT(N12)-INT(TODAY()))),"—") -> —
A13: 9 | C13: DJAMAN KOUAKOU MATHIEU | D13: Prospection directe | E13: 17/11/2025 | F13: =IFERROR(IF(E13="","",TEXT(E13,"DDDD")),"" ) -> 17/11/2025 | G13: 0707382557 | K13: 0 | L13: 0 | M13: =IFERROR(IF(K13+L13=0,"—",K13+L13),"—") -> — | O13: =IFERROR(IF(N13="","—",MAX(0,INT(N13)-INT(TODAY()))),"—") -> —
A14: 10 | C14: N'GUESSAN KOUASSI | D14: Prospection directe | E14: 20/12/2025 | F14: =IFERROR(IF(E14="","",TEXT(E14,"DDDD")),"" ) -> 20/12/2025 | G14: 0789937292 | K14: 0 | L14: 0 | M14: =IFERROR(IF(K14+L14=0,"—",K14+L14),"—") -> — | O14: =IFERROR(IF(N14="","—",MAX(0,INT(N14)-INT(TODAY()))),"—") -> —
A15: 11 | C15: N'ZUE N'GUESSAN | D15: Prospection directe | E15: 14/01/2026 | F15: =IFERROR(IF(E15="","",TEXT(E15,"DDDD")),"" ) -> 14/01/2026 | G15: 0747571448 | K15: 0 | L15: 0 | M15: =IFERROR(IF(K15+L15=0,"—",K15+L15),"—") -> — | O15: =IFERROR(IF(N15="","—",MAX(0,INT(N15)-INT(TODAY()))),"—") -> —
A16: 12 | C16: CASIMIR | D16: Prospection directe | E16: 08/04/2026 | F16: =IFERROR(IF(E16="","",TEXT(E16,"DDDD")),"" ) -> Tuesday | G16: 0709411969 | K16: 0 | L16: 0 | M16: =IFERROR(IF(K16+L16=0,"—",K16+L16),"—") -> — | O16: =IFERROR(IF(N16="","—",MAX(0,INT(N16)-INT(TODAY()))),"—") -> —
A17: 13 | F17: =IFERROR(IF(E17="","",TEXT(E17,"DDDD")),"" ) | K17: 0 | L17: 0 | M17: =IFERROR(IF(K17+L17=0,"—",K17+L17),"—") -> — | O17: =IFERROR(IF(N17="","—",MAX(0,INT(N17)-INT(TODAY()))),"—") -> —
A18: 14 | F18: =IFERROR(IF(E18="","",TEXT(E18,"DDDD")),"" ) | K18: 0 | L18: 0 | M18: =IFERROR(IF(K18+L18=0,"—",K18+L18),"—") -> — | O18: =IFERROR(IF(N18="","—",MAX(0,INT(N18)-INT(TODAY()))),"—") -> —
A19: 15 | F19: =IFERROR(IF(E19="","",TEXT(E19,"DDDD")),"" ) | K19: 0 | L19: 0 | M19: =IFERROR(IF(K19+L19=0,"—",K19+L19),"—") -> — | O19: =IFERROR(IF(N19="","—",MAX(0,INT(N19)-INT(TODAY()))),"—") -> —
A20: 16 | F20: =IFERROR(IF(E20="","",TEXT(E20,"DDDD")),"" ) | K20: 0 | L20: 0 | M20: =IFERROR(IF(K20+L20=0,"—",K20+L20),"—") -> — | O20: =IFERROR(IF(N20="","—",MAX(0,INT(N20)-INT(TODAY()))),"—") -> —
A21: 17 | F21: =IFERROR(IF(E21="","",TEXT(E21,"DDDD")),"" ) | K21: 0 | L21: 0 | M21: =IFERROR(IF(K21+L21=0,"—",K21+L21),"—") -> — | O21: =IFERROR(IF(N21="","—",MAX(0,INT(N21)-INT(TODAY()))),"—") -> —
A22: 18 | F22: =IFERROR(IF(E22="","",TEXT(E22,"DDDD")),"" ) | K22: 0 | L22: 0 | M22: =IFERROR(IF(K22+L22=0,"—",K22+L22),"—") -> — | O22: =IFERROR(IF(N22="","—",MAX(0,INT(N22)-INT(TODAY()))),"—") -> —
A23: 19 | F23: =IFERROR(IF(E23="","",TEXT(E23,"DDDD")),"" ) | K23: 0 | L23: 0 | M23: =IFERROR(IF(K23+L23=0,"—",K23+L23),"—") -> — | O23: =IFERROR(IF(N23="","—",MAX(0,INT(N23)-INT(TODAY()))),"—") -> —
A24: 20 | F24: =IFERROR(IF(E24="","",TEXT(E24,"DDDD")),"" ) | K24: 0 | L24: 0 | M24: =IFERROR(IF(K24+L24=0,"—",K24+L24),"—") -> — | O24: =IFERROR(IF(N24="","—",MAX(0,INT(N24)-INT(TODAY()))),"—") -> —
A25: 21 | F25: =IFERROR(IF(E25="","",TEXT(E25,"DDDD")),"" ) | K25: 0 | L25: 0 | M25: =IFERROR(IF(K25+L25=0,"—",K25+L25),"—") -> — | O25: =IFERROR(IF(N25="","—",MAX(0,INT(N25)-INT(TODAY()))),"—") -> —
A26: 22 | F26: =IFERROR(IF(E26="","",TEXT(E26,"DDDD")),"" ) | K26: 0 | L26: 0 | M26: =IFERROR(IF(K26+L26=0,"—",K26+L26),"—") -> — | O26: =IFERROR(IF(N26="","—",MAX(0,INT(N26)-INT(TODAY()))),"—") -> —
A27: 23 | F27: =IFERROR(IF(E27="","",TEXT(E27,"DDDD")),"" ) | K27: 0 | L27: 0 | M27: =IFERROR(IF(K27+L27=0,"—",K27+L27),"—") -> — | O27: =IFERROR(IF(N27="","—",MAX(0,INT(N27)-INT(TODAY()))),"—") -> —
A28: 24 | F28: =IFERROR(IF(E28="","",TEXT(E28,"DDDD")),"" ) | K28: 0 | L28: 0 | M28: =IFERROR(IF(K28+L28=0,"—",K28+L28),"—") -> — | O28: =IFERROR(IF(N28="","—",MAX(0,INT(N28)-INT(TODAY()))),"—") -> —
... A1004: 1000 | F1004: =IFERROR(IF(E1004="","",TEXT(E1004,"DDDD")),"" ) | K1004: 0 | L1004: 0 | M1004: =IFERROR(IF(K1004+L1004=0,"—",K1004+L1004),"—") -> — | O1004: =IFERROR(IF(N1004="","—",MAX(0,INT(N1004)-INT(TODAY()))),"—") -> —
I1005: 🏁 TOTAUX GÉNÉRAUX — 1 000 CONTRATS | K1005: =IFERROR(SUM(K5:K1004),0) -> 0 | L1005: =IFERROR(SUM(L5:L1004),0) -> 0 | M1005: =IFERROR(SUM(K5:K1004)+SUM(L5:L1004),0) -> 0 | O1005: —
I1007: 🔗 FLUX 1 — FORMULES À COPIER DANS TABLEAU BRD DU SUIVI MAÎTRE (ligne 6 = Contrat 1 | ligne 7 = Contrat 2 | ligne N+5 = Contrat N) : X6 = ='[FINANCE_COMPLET_UPDATED.xlsx]SYNC_FINANCE'!$A$5 (N° CONTRAT) Y6 = ='[FINANCE_COMPLET_UPDATED.xlsx]SYNC_FINANCE'!$B$5 (DATE SIGNATURE) Z6 = ='[FINANCE_COMPLET_UPDATED.xlsx]SYNC_FINANCE'!$C$5 (APPORT 30%) AA6= ='[FINANCE_COMPLET_UPDATED.xlsx]SYNC_FINANCE'!$D$5 (MONTANT PAIEMENT) AB6= ='[FINANCE_COMPLET_UPDATED.xlsx]SYNC_FINANCE'!$E$5 (TOTAL PAIEMENT) AC6= ='[FINANCE_COMPLET_UPDATED.xlsx]SYNC_FINANCE'!$F$5 (DATE LEVÉE COND.) AD6= ='[FINANCE_COMPLET_UPDATED.xlsx]SYNC_FINANCE'!$G$5 (JOURS RESTANTS) → Contrat 2 : $5→$6 | Contrat N : $(N+4)
I1009: 🔗 FLUX 2 — PAIEMENTS [MOIS] → SUIVI [MOIS] (exemple Client 1 = ligne 6) : SUIVI JUIN B6 = ='[FINANCE_COMPLET_UPDATED.xlsx]PAIEMENTS JUIN 2026'!$B$6 SUIVI JUIN R6 = ='[FINANCE_COMPLET_UPDATED.xlsx]PAIEMENTS JUIN 2026'!$C$6 SUIVI JUIN K6 = ='[FINANCE_COMPLET_UPDATED.xlsx]PAIEMENTS JUIN 2026'!$D$6 SUIVI JUIN O6 = ='[FINANCE_COMPLET_UPDATED.xlsx]PAIEMENTS JUIN 2026'!$E$6 SUIVI JUIN T6 = ='[FINANCE_COMPLET_UPDATED.xlsx]PAIEMENTS JUIN 2026'!$F$6 SUIVI JUIN U6 = ='[FINANCE_COMPLET_UPDATED.xlsx]PAIEMENTS JUIN 2026'!$G$6 SUIVI JUIN V6 = ='[FINANCE_COMPLET_UPDATED.xlsx]PAIEMENTS JUIN 2026'!$H$6 SUIVI JUIN W6 = ='[FINANCE_COMPLET_UPDATED.xlsx]PAIEMENTS JUIN 2026'!$I$6 SUIVI JUIN X6 = ='[FINANCE_COMPLET_UPDATED.xlsx]PAIEMENTS JUIN 2026'!$J$6 SUIVI JUIN Y6 = ='[FINANCE_COMPLET_UPDATED.xlsx]PAIEMENTS JUIN 2026'!$K$6 SUIVI JUIN Z6 = ='[FINANCE_COMPLET_UPDATED.xlsx]PAIEMENTS JUIN 2026'!$L$6 SUIVI JUIN AA6= ='[FINANCE_COMPLET_UPDATED.xlsx]PAIEMENTS JUIN 2026'!$M$6 SUIVI JUIN AB6= ='[FINANCE_COMPLET_UPDATED.xlsx]PAIEMENTS JUIN 2026'!$N$6 SUIVI JUIN AC6= ='[FINANCE_COMPLET_UPDATED.xlsx]PAIEMENTS JUIN 2026'!$O$6 SUIVI JUIN AD6= ='[FINANCE_COMPLET_UPDATED.xlsx]PAIEMENTS JUIN 2026'!$P$6 → Même logique pour JUILLET 2026 … JUIN 2027 (remplacer nom onglet)

Sheet PAIEMENTS JUIN 2026
A1: 💰 PAIEMENTS JUIN 2026 — LEMI SARL | BRASUS v3.2
A2: ⚠️ Saisie des paiements reçus par semaine. Alimente automatiquement le SUIVI 13 MOIS.
A3: 🔒 Identité client (auto) | K3: 📋 Contrat | N3: ✏️ PAIEMENTS JUIN — 4 semaines × (Paiement + Droit + Apport) | Z3: ⚙️ CALCULS AUTO
N4: 01/06-07/06 | Q4: 08/06-15/06 | T4: 16/06-24/06 | W4: 25/06-30/06
A5: N° | B5: N° IDENTIFIANT | C5: NOM & PRÉNOMS DU CLIENT | D5: SOURCE DU PROSPECT | E5: DATE PREMIER CONTACT | F5: TÉLÉPHONE / WHATSAPP | G5: PROFESSION | H5: RÉGION D'HABITATION | I5: RÉGION DU PROJET | J5: LIEU DU PROJET | K5: N° CONTRAT | L5: MONTANT TTC (FCFA) | M5: MENSUALITÉ (FCFA) | N5: PAIEMENT | O5: DROIT ADHÉSION | P5: APPORT INITIAL | Q5: PAIEMENT | R5: DROIT ADHÉSION | S5: APPORT INITIAL | T5: PAIEMENT | U5: DROIT ADHÉSION | V5: APPORT INITIAL | W5: PAIEMENT | X5: DROIT ADHÉSION | Y5: APPORT INITIAL | Z5: TOTAL MOIS | AA5: MENSUALITÉ DUE | AB5: CUMUL PAIEMENTS | AC5: RESTANT DÛ
A6: 1 | B6: =IFERROR([1]SYNC_PROSPECTION_MKT!$B$5,"") -> 0 | C6: =IFERROR([1]SYNC_PROSPECTION_MKT!$C$5,"") -> TANOH KONAN GERVAIS ARMAND | D6: =IFERROR([1]SYNC_PROSPECTION_MKT!$D$5,"") -> 0 | E6: =IFERROR([1]SYNC_PROSPECTION_MKT!$E$5,"") -> 0 | F6: =IFERROR([1]SYNC_PROSPECTION_MKT!$G$5,"") -> 0 | G6: =IFERROR([1]SYNC_PROSPECTION_MKT!$H$5,"") -> 0 | H6: =IFERROR([1]SYNC_PROSPECTION_MKT!$J$5,"") -> 0 | I6: =IFERROR([1]SYNC_PROSPECTION_MKT!$I$5,"") -> 0 | J6: =IFERROR([1]SYNC_PROSPECTION_MKT!$K$5,"") -> 0 | K6: =IFERROR(SYNC_FINANCE!$I$5,"") -> 0 | L6: =IFERROR([2]SYNC_COMMERCIAL_VENTE!$S$5,"") -> 0 | M6: 0 | N6: 0 | O6: 0 | P6: 0 | Q6: 0 | R6: 0 | S6: 0 | T6: 0 | U6: 0 | V6: 0 | W6: 0 | X6: 0 | Y6: 0 | Z6: =IFERROR(SUM(N6:Y6),0) -> 0 | AA6: =IFERROR((N6+Q6+T6+W6)-M6,0) -> 0 | AB6: =IFERROR(Z6,0) -> 0 | AC6: =IFERROR(L6-AB6,0) -> 0
A7: 2 | B7: =IFERROR([1]SYNC_PROSPECTION_MKT!$B$6,"") -> 0 | C7: =IFERROR([1]SYNC_PROSPECTION_MKT!$C$6,"") -> N'DRI ép. NGBESSO AKISSI ELIANE | D7: =IFERROR([1]SYNC_PROSPECTION_MKT!$D$6,"") -> 0 | E7: =IFERROR([1]SYNC_PROSPECTION_MKT!$E$6,"") -> 0 | F7: =IFERROR([1]SYNC_PROSPECTION_MKT!$G$6,"") -> 0 | G7: =IFERROR([1]SYNC_PROSPECTION_MKT!$H$6,"") -> 0 | H7: =IFERROR([1]SYNC_PROSPECTION_MKT!$J$6,"") -> 0 | I7: =IFERROR([1]SYNC_PROSPECTION_MKT!$I$6,"") -> 0 | J7: =IFERROR([1]SYNC_PROSPECTION_MKT!$K$6,"") -> 0 | K7: =IFERROR(SYNC_FINANCE!$I$6,"") -> 0 | L7: =IFERROR([2]SYNC_COMMERCIAL_VENTE!$S$6,"") -> 0 | M7: 0 | N7: 0 | O7: 0 | P7: 0 | Q7: 0 | R7: 0 | S7: 0 | T7: 0 | U7: 0 | V7: 0 | W7: 0 | X7: 0 | Y7: 0 | Z7: =IFERROR(SUM(N7:Y7),0) -> 0 | AA7: =IFERROR((N7+Q7+T7+W7)-M7,0) -> 0 | AB7: =IFERROR(Z7,0) -> 0 | AC7: =IFERROR(L7-AB7,0) -> 0
A8: 3 | B8: =IFERROR([1]SYNC_PROSPECTION_MKT!$B$7,"") -> 0 | C8: =IFERROR([1]SYNC_PROSPECTION_MKT!$C$7,"") -> N'GORAN KOFFI | D8: =IFERROR([1]SYNC_PROSPECTION_MKT!$D$7,"") -> 0 | E8: =IFERROR([1]SYNC_PROSPECTION_MKT!$E$7,"") -> 0 | F8: =IFERROR([1]SYNC_PROSPECTION_MKT!$G$7,"") -> 0 | G8: =IFERROR([1]SYNC_PROSPECTION_MKT!$H$7,"") -> 0 | H8: =IFERROR([1]SYNC_PROSPECTION_MKT!$J$7,"") -> 0 | I8: =IFERROR([1]SYNC_PROSPECTION_MKT!$I$7,"") -> 0 | J8: =IFERROR([1]SYNC_PROSPECTION_MKT!$K$7,"") -> 0 | K8: =IFERROR(SYNC_FINANCE!$I$7,"") -> 0 | L8: =IFERROR([2]SYNC_COMMERCIAL_VENTE!$S$7,"") -> 0 | M8: 0 | N8: 0 | O8: 0 | P8: 0 | Q8: 0 | R8: 0 | S8: 0 | T8: 0 | U8: 0 | V8: 0 | W8: 0 | X8: 0 | Y8: 0 | Z8: =IFERROR(SUM(N8:Y8),0) -> 0 | AA8: =IFERROR((N8+Q8+T8+W8)-M8,0) -> 0 | AB8: =IFERROR(Z8,0) -> 0 | AC8: =IFERROR(L8-AB8,0) -> 0
A9: 4 | B9: =IFERROR([1]SYNC_PROSPECTION_MKT!$B$8,"") -> 0 | C9: =IFERROR([1]SYNC_PROSPECTION_MKT!$C$8,"") -> KOUASSI VINCENT DE PAUL ASSOUMOU | D9: =IFERROR([1]SYNC_PROSPECTION_MKT!$D$8,"") -> 0 | E9: =IFERROR([1]SYNC_PROSPECTION_MKT!$E$8,"") -> 0 | F9: =IFERROR([1]SYNC_PROSPECTION_MKT!$G$8,"") -> 0 | G9: =IFERROR([1]SYNC_PROSPECTION_MKT!$H$8,"") -> 0 | H9: =IFERROR([1]SYNC_PROSPECTION_MKT!$J$8,"") -> 0 | I9: =IFERROR([1]SYNC_PROSPECTION_MKT!$I$8,"") -> 0 | J9: =IFERROR([1]SYNC_PROSPECTION_MKT!$K$8,"") -> 0 | K9: =IFERROR(SYNC_FINANCE!$I$8,"") -> 0 | L9: =IFERROR([2]SYNC_COMMERCIAL_VENTE!$S$8,"") -> 0 | M9: 0 | N9: 0 | O9: 0 | P9: 0 | Q9: 0 | R9: 0 | S9: 0 | T9: 0 | U9: 0 | V9: 0 | W9: 0 | X9: 0 | Y9: 0 | Z9: =IFERROR(SUM(N9:Y9),0) -> 0 | AA9: =IFERROR((N9+Q9+T9+W9)-M9,0) -> 0 | AB9: =IFERROR(Z9,0) -> 0 | AC9: =IFERROR(L9-AB9,0) -> 0
A10: 5 | B10: =IFERROR([1]SYNC_PROSPECTION_MKT!$B$9,"") -> 0 | C10: =IFERROR([1]SYNC_PROSPECTION_MKT!$C$9,"") -> KOUASSI HONORE | D10: =IFERROR([1]SYNC_PROSPECTION_MKT!$D$9,"") -> 0 | E10: =IFERROR([1]SYNC_PROSPECTION_MKT!$E$9,"") -> 0 | F10: =IFERROR([1]SYNC_PROSPECTION_MKT!$G$9,"") -> 0 | G10: =IFERROR([1]SYNC_PROSPECTION_MKT!$H$9,"") -> 0 | H10: =IFERROR([1]SYNC_PROSPECTION_MKT!$J$9,"") -> 0 | I10: =IFERROR([1]SYNC_PROSPECTION_MKT!$I$9,"") -> 0 | J10: =IFERROR([1]SYNC_PROSPECTION_MKT!$K$9,"") -> 0 | K10: =IFERROR(SYNC_FINANCE!$I$9,"") -> 0 | L10: =IFERROR([2]SYNC_COMMERCIAL_VENTE!$S$9,"") -> 0 | M10: 0 | N10: 0 | O10: 0 | P10: 0 | Q10: 0 | R10: 0 | S10: 0 | T10: 0 | U10: 0 | V10: 0 | W10: 0 | X10: 0 | Y10: 0 | Z10: =IFERROR(SUM(N10:Y10),0) -> 0 | AA10: =IFERROR((N10+Q10+T10+W10)-M10,0) -> 0 | AB10: =IFERROR(Z10,0) -> 0 | AC10: =IFERROR(L10-AB10,0) -> 0
A11: 6 | B11: =IFERROR([1]SYNC_PROSPECTION_MKT!$B$10,"") -> 0 | C11: =IFERROR([1]SYNC_PROSPECTION_MKT!$C$10,"") -> AKISSI ELIANE KONAN | D11: =IFERROR([1]SYNC_PROSPECTION_MKT!$D$10,"") -> 0 | E11: =IFERROR([1]SYNC_PROSPECTION_MKT!$E$10,"") -> 0 | F11: =IFERROR([1]SYNC_PROSPECTION_MKT!$G$10,"") -> 0 | G11: =IFERROR([1]SYNC_PROSPECTION_MKT!$H$10,"") -> 0 | H11: =IFERROR([1]SYNC_PROSPECTION_MKT!$J$10,"") -> 0 | I11: =IFERROR([1]SYNC_PROSPECTION_MKT!$I$10,"") -> 0 | J11: =IFERROR([1]SYNC_PROSPECTION_MKT!$K$10,"") -> 0 | K11: =IFERROR(SYNC_FINANCE!$I$10,"") -> 0 | L11: =IFERROR([2]SYNC_COMMERCIAL_VENTE!$S$10,"") -> 0 | M11: 0 | N11: 0 | O11: 0 | P11: 0 | Q11: 0 | R11: 0 | S11: 0 | T11: 0 | U11: 0 | V11: 0 | W11: 0 | X11: 0 | Y11: 0 | Z11: =IFERROR(SUM(N11:Y11),0) -> 0 | AA11: =IFERROR((N11+Q11+T11+W11)-M11,0) -> 0 | AB11: =IFERROR(Z11,0) -> 0 | AC11: =IFERROR(L11-AB11,0) -> 0
A12: 7 | B12: =IFERROR([1]SYNC_PROSPECTION_MKT!$B$11,"") -> 0 | C12: =IFERROR([1]SYNC_PROSPECTION_MKT!$C$11,"") -> BROU LAMBERT KOUASSI | D12: =IFERROR([1]SYNC_PROSPECTION_MKT!$D$11,"") -> 0 | E12: =IFERROR([1]SYNC_PROSPECTION_MKT!$E$11,"") -> 0 | F12: =IFERROR([1]SYNC_PROSPECTION_MKT!$G$11,"") -> 0 | G12: =IFERROR([1]SYNC_PROSPECTION_MKT!$H$11,"") -> 0 | H12: =IFERROR([1]SYNC_PROSPECTION_MKT!$J$11,"") -> 0 | I12: =IFERROR([1]SYNC_PROSPECTION_MKT!$I$11,"") -> 0 | J12: =IFERROR([1]SYNC_PROSPECTION_MKT!$K$11,"") -> 0 | K12: =IFERROR(SYNC_FINANCE!$I$11,"") -> 0 | L12: =IFERROR([2]SYNC_COMMERCIAL_VENTE!$S$11,"") -> 0 | M12: 0 | N12: 0 | O12: 0 | P12: 0 | Q12: 0 | R12: 0 | S12: 0 | T12: 0 | U12: 0 | V12: 0 | W12: 0 | X12: 0 | Y12: 0 | Z12: =IFERROR(SUM(N12:Y12),0) -> 0 | AA12: =IFERROR((N12+Q12+T12+W12)-M12,0) -> 0 | AB12: =IFERROR(Z12,0) -> 0 | AC12: =IFERROR(L12-AB12,0) -> 0
A13: 8 | B13: =IFERROR([1]SYNC_PROSPECTION_MKT!$B$12,"") -> 0 | C13: =IFERROR([1]SYNC_PROSPECTION_MKT!$C$12,"") -> DJEDRI KOUAKOU JEAN PIERRE | D13: =IFERROR([1]SYNC_PROSPECTION_MKT!$D$12,"") -> 0 | E13: =IFERROR([1]SYNC_PROSPECTION_MKT!$E$12,"") -> 0 | F13: =IFERROR([1]SYNC_PROSPECTION_MKT!$G$12,"") -> 0 | G13: =IFERROR([1]SYNC_PROSPECTION_MKT!$H$12,"") -> 0 | H13: =IFERROR([1]SYNC_PROSPECTION_MKT!$J$12,"") -> 0 | I13: =IFERROR([1]SYNC_PROSPECTION_MKT!$I$12,"") -> 0 | J13: =IFERROR([1]SYNC_PROSPECTION_MKT!$K$12,"") -> 0 | K13: =IFERROR(SYNC_FINANCE!$I$12,"") -> 0 | L13: =IFERROR([2]SYNC_COMMERCIAL_VENTE!$S$12,"") -> 0 | M13: 0 | N13: 0 | O13: 0 | P13: 0 | Q13: 0 | R13: 0 | S13: 0 | T13: 0 | U13: 0 | V13: 0 | W13: 0 | X13: 0 | Y13: 0 | Z13: =IFERROR(SUM(N13:Y13),0) -> 0 | AA13: =IFERROR((N13+Q13+T13+W13)-M13,0) -> 0 | AB13: =IFERROR(Z13,0) -> 0 | AC13: =IFERROR(L13-AB13,0) -> 0
A14: 9 | B14: =IFERROR([1]SYNC_PROSPECTION_MKT!$B$13,"") -> 0 | C14: =IFERROR([1]SYNC_PROSPECTION_MKT!$C$13,"") -> DJAMAN KOUAKOU MATHIEU | D14: =IFERROR([1]SYNC_PROSPECTION_MKT!$D$13,"") -> 0 | E14: =IFERROR([1]SYNC_PROSPECTION_MKT!$E$13,"") -> 0 | F14: =IFERROR([1]SYNC_PROSPECTION_MKT!$G$13,"") -> 0 | G14: =IFERROR([1]SYNC_PROSPECTION_MKT!$H$13,"") -> 0 | H14: =IFERROR([1]SYNC_PROSPECTION_MKT!$J$13,"") -> 0 | I14: =IFERROR([1]SYNC_PROSPECTION_MKT!$I$13,"") -> 0 | J14: =IFERROR([1]SYNC_PROSPECTION_MKT!$K$13,"") -> 0 | K14: =IFERROR(SYNC_FINANCE!$I$13,"") -> 0 | L14: =IFERROR([2]SYNC_COMMERCIAL_VENTE!$S$13,"") -> 0 | M14: 0 | N14: 0 | O14: 0 | P14: 0 | Q14: 0 | R14: 0 | S14: 0 | T14: 0 | U14: 0 | V14: 0 | W14: 0 | X14: 0 | Y14: 0 | Z14: =IFERROR(SUM(N14:Y14),0) -> 0 | AA14: =IFERROR((N14+Q14+T14+W14)-M14,0) -> 0 | AB14: =IFERROR(Z14,0) -> 0 | AC14: =IFERROR(L14-AB14,0) -> 0
A15: 10 | B15: =IFERROR([1]SYNC_PROSPECTION_MKT!$B$14,"") -> 0 | C15: =IFERROR([1]SYNC_PROSPECTION_MKT!$C$14,"") -> N'GUESSAN KOUASSI | D15: =IFERROR([1]SYNC_PROSPECTION_MKT!$D$14,"") -> 0 | E15: =IFERROR([1]SYNC_PROSPECTION_MKT!$E$14,"") -> 0 | F15: =IFERROR([1]SYNC_PROSPECTION_MKT!$G$14,"") -> 0 | G15: =IFERROR([1]SYNC_PROSPECTION_MKT!$H$14,"") -> 0 | H15: =IFERROR([1]SYNC_PROSPECTION_MKT!$J$14,"") -> 0 | I15: =IFERROR([1]SYNC_PROSPECTION_MKT!$I$14,"") -> 0 | J15: =IFERROR([1]SYNC_PROSPECTION_MKT!$K$14,"") -> 0 | K15: =IFERROR(SYNC_FINANCE!$I$14,"") -> 0 | L15: =IFERROR([2]SYNC_COMMERCIAL_VENTE!$S$14,"") -> 0 | M15: 0 | N15: 0 | O15: 0 | P15: 0 | Q15: 0 | R15: 0 | S15: 0 | T15: 0 | U15: 0 | V15: 0 | W15: 0 | X15: 0 | Y15: 0 | Z15: =IFERROR(SUM(N15:Y15),0) -> 0 | AA15: =IFERROR((N15+Q15+T15+W15)-M15,0) -> 0 | AB15: =IFERROR(Z15,0) -> 0 | AC15: =IFERROR(L15-AB15,0) -> 0
A16: 11 | B16: =IFERROR([1]SYNC_PROSPECTION_MKT!$B$15,"") -> 0 | C16: =IFERROR([1]SYNC_PROSPECTION_MKT!$C$15,"") -> N'ZUE N'GUESSAN | D16: =IFERROR([1]SYNC_PROSPECTION_MKT!$D$15,"") -> 0 | E16: =IFERROR([1]SYNC_PROSPECTION_MKT!$E$15,"") -> 0 | F16: =IFERROR([1]SYNC_PROSPECTION_MKT!$G$15,"") -> 0 | G16: =IFERROR([1]SYNC_PROSPECTION_MKT!$H$15,"") -> 0 | H16: =IFERROR([1]SYNC_PROSPECTION_MKT!$J$15,"") -> 0 | I16: =IFERROR([1]SYNC_PROSPECTION_MKT!$I$15,"") -> 0 | J16: =IFERROR([1]SYNC_PROSPECTION_MKT!$K$15,"") -> 0 | K16: =IFERROR(SYNC_FINANCE!$I$15,"") -> 0 | L16: =IFERROR([2]SYNC_COMMERCIAL_VENTE!$S$15,"") -> 0 | M16: 0 | N16: 0 | O16: 0 | P16: 0 | Q16: 0 | R16: 0 | S16: 0 | T16: 0 | U16: 0 | V16: 0 | W16: 0 | X16: 0 | Y16: 0 | Z16: =IFERROR(SUM(N16:Y16),0) -> 0 | AA16: =IFERROR((N16+Q16+T16+W16)-M16,0) -> 0 | AB16: =IFERROR(Z16,0) -> 0 | AC16: =IFERROR(L16-AB16,0) -> 0
A17: 12 | B17: =IFERROR([1]SYNC_PROSPECTION_MKT!$B$16,"") -> 0 | C17: =IFERROR([1]SYNC_PROSPECTION_MKT!$C$16,"") -> CASIMIR | D17: =IFERROR([1]SYNC_PROSPECTION_MKT!$D$16,"") -> 0 | E17: =IFERROR([1]SYNC_PROSPECTION_MKT!$E$16,"") -> 0 | F17: =IFERROR([1]SYNC_PROSPECTION_MKT!$G$16,"") -> 0 | G17: =IFERROR([1]SYNC_PROSPECTION_MKT!$H$16,"") -> 0 | H17: =IFERROR([1]SYNC_PROSPECTION_MKT!$J$16,"") -> 0 | I17: =IFERROR([1]SYNC_PROSPECTION_MKT!$I$16,"") -> 0 | J17: =IFERROR([1]SYNC_PROSPECTION_MKT!$K$16,"") -> 0 | K17: =IFERROR(SYNC_FINANCE!$I$16,"") -> 0 | L17: =IFERROR([2]SYNC_COMMERCIAL_VENTE!$S$16,"") -> 0 | M17: 0 | N17: 0 | O17: 0 | P17: 0 | Q17: 0 | R17: 0 | S17: 0 | T17: 0 | U17: 0 | V17: 0 | W17: 0 | X17: 0 | Y17: 0 | Z17: =IFERROR(SUM(N17:Y17),0) -> 0 | AA17: =IFERROR((N17+Q17+T17+W17)-M17,0) -> 0 | AB17: =IFERROR(Z17,0) -> 0 | AC17: =IFERROR(L17-AB17,0) -> 0
A18: 13 | B18: =IFERROR([1]SYNC_PROSPECTION_MKT!$B$17,"") -> 0 | C18: =IFERROR([1]SYNC_PROSPECTION_MKT!$C$17,"") -> 0 | D18: =IFERROR([1]SYNC_PROSPECTION_MKT!$D$17,"") -> 0 | E18: =IFERROR([1]SYNC_PROSPECTION_MKT!$E$17,"") -> 0 | F18: =IFERROR([1]SYNC_PROSPECTION_MKT!$G$17,"") -> 0 | G18: =IFERROR([1]SYNC_PROSPECTION_MKT!$H$17,"") -> 0 | H18: =IFERROR([1]SYNC_PROSPECTION_MKT!$J$17,"") -> 0 | I18: =IFERROR([1]SYNC_PROSPECTION_MKT!$I$17,"") -> 0 | J18: =IFERROR([1]SYNC_PROSPECTION_MKT!$K$17,"") -> 0 | K18: =IFERROR(SYNC_FINANCE!$I$17,"") -> 0 | L18: =IFERROR([2]SYNC_COMMERCIAL_VENTE!$S$17,"") -> 0 | M18: 0 | N18: 0 | O18: 0 | P18: 0 | Q18: 0 | R18: 0 | S18: 0 | T18: 0 | U18: 0 | V18: 0 | W18: 0 | X18: 0 | Y18: 0 | Z18: =IFERROR(SUM(N18:Y18),0) -> 0 | AA18: =IFERROR((N18+Q18+T18+W18)-M18,0) -> 0 | AB18: =IFERROR(Z18,0) -> 0 | AC18: =IFERROR(L18-AB18,0) -> 0
A19: 14 | B19: =IFERROR([1]SYNC_PROSPECTION_MKT!$B$18,"") -> 0 | C19: =IFERROR([1]SYNC_PROSPECTION_MKT!$C$18,"") -> 0 | D19: =IFERROR([1]SYNC_PROSPECTION_MKT!$D$18,"") -> 0 | E19: =IFERROR([1]SYNC_PROSPECTION_MKT!$E$18,"") -> 0 | F19: =IFERROR([1]SYNC_PROSPECTION_MKT!$G$18,"") -> 0 | G19: =IFERROR([1]SYNC_PROSPECTION_MKT!$H$18,"") -> 0 | H19: =IFERROR([1]SYNC_PROSPECTION_MKT!$J$18,"") -> 0 | I19: =IFERROR([1]SYNC_PROSPECTION_MKT!$I$18,"") -> 0 | J19: =IFERROR([1]SYNC_PROSPECTION_MKT!$K$18,"") -> 0 | K19: =IFERROR(SYNC_FINANCE!$I$18,"") -> 0 | L19: =IFERROR([2]SYNC_COMMERCIAL_VENTE!$S$18,"") -> 0 | M19: 0 | N19: 0 | O19: 0 | P19: 0 | Q19: 0 | R19: 0 | S19: 0 | T19: 0 | U19: 0 | V19: 0 | W19: 0 | X19: 0 | Y19: 0 | Z19: =IFERROR(SUM(N19:Y19),0) -> 0 | AA19: =IFERROR((N19+Q19+T19+W19)-M19,0) -> 0 | AB19: =IFERROR(Z19,0) -> 0 | AC19: =IFERROR(L19-AB19,0) -> 0
A20: 15 | B20: =IFERROR([1]SYNC_PROSPECTION_MKT!$B$19,"") -> 0 | C20: =IFERROR([1]SYNC_PROSPECTION_MKT!$C$19,"") -> 0 | D20: =IFERROR([1]SYNC_PROSPECTION_MKT!$D$19,"") -> 0 | E20: =IFERROR([1]SYNC_PROSPECTION_MKT!$E$19,"") -> 0 | F20: =IFERROR([1]SYNC_PROSPECTION_MKT!$G$19,"") -> 0 | G20: =IFERROR([1]SYNC_PROSPECTION_MKT!$H$19,"") -> 0 | H20: =IFERROR([1]SYNC_PROSPECTION_MKT!$J$19,"") -> 0 | I20: =IFERROR([1]SYNC_PROSPECTION_MKT!$I$19,"") -> 0 | J20: =IFERROR([1]SYNC_PROSPECTION_MKT!$K$19,"") -> 0 | K20: =IFERROR(SYNC_FINANCE!$I$19,"") -> 0 | L20: =IFERROR([2]SYNC_COMMERCIAL_VENTE!$S$19,"") -> 0 | M20: 0 | N20: 0 | O20: 0 | P20: 0 | Q20: 0 | R20: 0 | S20: 0 | T20: 0 | U20: 0 | V20: 0 | W20: 0 | X20: 0 | Y20: 0 | Z20: =IFERROR(SUM(N20:Y20),0) -> 0 | AA20: =IFERROR((N20+Q20+T20+W20)-M20,0) -> 0 | AB20: =IFERROR(Z20,0) -> 0 | AC20: =IFERROR(L20-AB20,0) -> 0
A21: 16 | B21: =IFERROR([1]SYNC_PROSPECTION_MKT!$B$20,"") -> 0 | C21: =IFERROR([1]SYNC_PROSPECTION_MKT!$C$20,"") -> 0 | D21: =IFERROR([1]SYNC_PROSPECTION_MKT!$D$20,"") -> 0 | E21: =IFERROR([1]SYNC_PROSPECTION_MKT!$E$20,"") -> 0 | F21: =IFERROR([1]SYNC_PROSPECTION_MKT!$G$20,"") -> 0 | G21: =IFERROR([1]SYNC_PROSPECTION_MKT!$H$20,"") -> 0 | H21: =IFERROR([1]SYNC_PROSPECTION_MKT!$J$20,"") -> 0 | I21: =IFERROR([1]SYNC_PROSPECTION_MKT!$I$20,"") -> 0 | J21: =IFERROR([1]SYNC_PROSPECTION_MKT!$K$20,"") -> 0 | K21: =IFERROR(SYNC_FINANCE!$I$20,"") -> 0 | L21: =IFERROR([2]SYNC_COMMERCIAL_VENTE!$S$20,"") -> 0 | M21: 0 | N21: 0 | O21: 0 | P21: 0 | Q21: 0 | R21: 0 | S21: 0 | T21: 0 | U21: 0 | V21: 0 | W21: 0 | X21: 0 | Y21: 0 | Z21: =IFERROR(SUM(N21:Y21),0) -> 0 | AA21: =IFERROR((N21+Q21+T21+W21)-M21,0) -> 0 | AB21: =IFERROR(Z21,0) -> 0 | AC21: =IFERROR(L21-AB21,0) -> 0
A22: 17 | B22: =IFERROR([1]SYNC_PROSPECTION_MKT!$B$21,"") -> 0 | C22: =IFERROR([1]SYNC_PROSPECTION_MKT!$C$21,"") -> 0 | D22: =IFERROR([1]SYNC_PROSPECTION_MKT!$D$21,"") -> 0 | E22: =IFERROR([1]SYNC_PROSPECTION_MKT!$E$21,"") -> 0 | F22: =IFERROR([1]SYNC_PROSPECTION_MKT!$G$21,"") -> 0 | G22: =IFERROR([1]SYNC_PROSPECTION_MKT!$H$21,"") -> 0 | H22: =IFERROR([1]SYNC_PROSPECTION_MKT!$J$21,"") -> 0 | I22: =IFERROR([1]SYNC_PROSPECTION_MKT!$I$21,"") -> 0 | J22: =IFERROR([1]SYNC_PROSPECTION_MKT!$K$21,"") -> 0 | K22: =IFERROR(SYNC_FINANCE!$I$21,"") -> 0 | L22: =IFERROR([2]SYNC_COMMERCIAL_VENTE!$S$21,"") -> 0 | M22: 0 | N22: 0 | O22: 0 | P22: 0 | Q22: 0 | R22: 0 | S22: 0 | T22: 0 | U22: 0 | V22: 0 | W22: 0 | X22: 0 | Y22: 0 | Z22: =IFERROR(SUM(N22:Y22),0) -> 0 | AA22: =IFERROR((N22+Q22+T22+W22)-M22,0) -> 0 | AB22: =IFERROR(Z22,0) -> 0 | AC22: =IFERROR(L22-AB22,0) -> 0
A23: 18 | B23: =IFERROR([1]SYNC_PROSPECTION_MKT!$B$22,"") -> 0 | C23: =IFERROR([1]SYNC_PROSPECTION_MKT!$C$22,"") -> 0 | D23: =IFERROR([1]SYNC_PROSPECTION_MKT!$D$22,"") -> 0 | E23: =IFERROR([1]SYNC_PROSPECTION_MKT!$E$22,"") -> 0 | F23: =IFERROR([1]SYNC_PROSPECTION_MKT!$G$22,"") -> 0 | G23: =IFERROR([1]SYNC_PROSPECTION_MKT!$H$22,"") -> 0 | H23: =IFERROR([1]SYNC_PROSPECTION_MKT!$J$22,"") -> 0 | I23: =IFERROR([1]SYNC_PROSPECTION_MKT!$I$22,"") -> 0 | J23: =IFERROR([1]SYNC_PROSPECTION_MKT!$K$22,"") -> 0 | K23: =IFERROR(SYNC_FINANCE!$I$22,"") -> 0 | L23: =IFERROR([2]SYNC_COMMERCIAL_VENTE!$S$22,"") -> 0 | M23: 0 | N23: 0 | O23: 0 | P23: 0 | Q23: 0 | R23: 0 | S23: 0 | T23: 0 | U23: 0 | V23: 0 | W23: 0 | X23: 0 | Y23: 0 | Z23: =IFERROR(SUM(N23:Y23),0) -> 0 | AA23: =IFERROR((N23+Q23+T23+W23)-M23,0) -> 0 | AB23: =IFERROR(Z23,0) -> 0 | AC23: =IFERROR(L23-AB23,0) -> 0
A24: 19 | B24: =IFERROR([1]SYNC_PROSPECTION_MKT!$B$23,"") -> 0 | C24: =IFERROR([1]SYNC_PROSPECTION_MKT!$C$23,"") -> 0 | D24: =IFERROR([1]SYNC_PROSPECTION_MKT!$D$23,"") -> 0 | E24: =IFERROR([1]SYNC_PROSPECTION_MKT!$E$23,"") -> 0 | F24: =IFERROR([1]SYNC_PROSPECTION_MKT!$G$23,"") -> 0 | G24: =IFERROR([1]SYNC_PROSPECTION_MKT!$H$23,"") -> 0 | H24: =IFERROR([1]SYNC_PROSPECTION_MKT!$J$23,"") -> 0 | I24: =IFERROR([1]SYNC_PROSPECTION_MKT!$I$23,"") -> 0 | J24: =IFERROR([1]SYNC_PROSPECTION_MKT!$K$23,"") -> 0 | K24: =IFERROR(SYNC_FINANCE!$I$23,"") -> 0 | L24: =IFERROR([2]SYNC_COMMERCIAL_VENTE!$S$23,"") -> 0 | M24: 0 | N24: 0 | O24: 0 | P24: 0 | Q24: 0 | R24: 0 | S24: 0 | T24: 0 | U24: 0 | V24: 0 | W24: 0 | X24: 0 | Y24: 0 | Z24: =IFERROR(SUM(N24:Y24),0) -> 0 | AA24: =IFERROR((N24+Q24+T24+W24)-M24,0) -> 0 | AB24: =IFERROR(Z24,0) -> 0 | AC24: =IFERROR(L24-AB24,0) -> 0
A25: 20 | B25: =IFERROR([1]SYNC_PROSPECTION_MKT!$B$24,"") -> 0 | C25: =IFERROR([1]SYNC_PROSPECTION_MKT!$C$24,"") -> 0 | D25: =IFERROR([1]SYNC_PROSPECTION_MKT!$D$24,"") -> 0 | E25: =IFERROR([1]SYNC_PROSPECTION_MKT!$E$24,"") -> 0 | F25: =IFERROR([1]SYNC_PROSPECTION_MKT!$G$24,"") -> 0 | G25: =IFERROR([1]SYNC_PROSPECTION_MKT!$H$24,"") -> 0 | H25: =IFERROR([1]SYNC_PROSPECTION_MKT!$J$24,"") -> 0 | I25: =IFERROR([1]SYNC_PROSPECTION_MKT!$I$24,"") -> 0 | J25: =IFERROR([1]SYNC_PROSPECTION_MKT!$K$24,"") -> 0 | K25: =IFERROR(SYNC_FINANCE!$I$24,"") -> 0 | L25: =IFERROR([2]SYNC_COMMERCIAL_VENTE!$S$24,"") -> 0 | M25: 0 | N25: 0 | O25: 0 | P25: 0 | Q25: 0 | R25: 0 | S25: 0 | T25: 0 | U25: 0 | V25: 0 | W25: 0 | X25: 0 | Y25: 0 | Z25: =IFERROR(SUM(N25:Y25),0) -> 0 | AA25: =IFERROR((N25+Q25+T25+W25)-M25,0) -> 0 | AB25: =IFERROR(Z25,0) -> 0 | AC25: =IFERROR(L25-AB25,0) -> 0
A26: 21 | B26: =IFERROR([1]SYNC_PROSPECTION_MKT!$B$25,"") -> 0 | C26: =IFERROR([1]SYNC_PROSPECTION_MKT!$C$25,"") -> 0 | D26: =IFERROR([1]SYNC_PROSPECTION_MKT!$D$25,"") -> 0 | E26: =IFERROR([1]SYNC_PROSPECTION_MKT!$E$25,"") -> 0 | F26: =IFERROR([1]SYNC_PROSPECTION_MKT!$G$25,"") -> 0 | G26: =IFERROR([1]SYNC_PROSPECTION_MKT!$H$25,"") -> 0 | H26: =IFERROR([1]SYNC_PROSPECTION_MKT!$J$25,"") -> 0 | I26: =IFERROR([1]SYNC_PROSPECTION_MKT!$I$25,"") -> 0 | J26: =IFERROR([1]SYNC_PROSPECTION_MKT!$K$25,"") -> 0 | K26: =IFERROR(SYNC_FINANCE!$I$25,"") -> 0 | L26: =IFERROR([2]SYNC_COMMERCIAL_VENTE!$S$25,"") -> 0 | M26: 0 | N26: 0 | O26: 0 | P26: 0 | Q26: 0 | R26: 0 | S26: 0 | T26: 0 | U26: 0 | V26: 0 | W26: 0 | X26: 0 | Y26: 0 | Z26: =IFERROR(SUM(N26:Y26),0) -> 0 | AA26: =IFERROR((N26+Q26+T26+W26)-M26,0) -> 0 | AB26: =IFERROR(Z26,0) -> 0 | AC26: =IFERROR(L26-AB26,0) -> 0
A27: 22 | B27: =IFERROR([1]SYNC_PROSPECTION_MKT!$B$26,"") -> 0 | C27: =IFERROR([1]SYNC_PROSPECTION_MKT!$C$26,"") -> 0 | D27: =IFERROR([1]SYNC_PROSPECTION_MKT!$D$26,"") -> 0 | E27: =IFERROR([1]SYNC_PROSPECTION_MKT!$E$26,"") -> 0 | F27: =IFERROR([1]SYNC_PROSPECTION_MKT!$G$26,"") -> 0 | G27: =IFERROR([1]SYNC_PROSPECTION_MKT!$H$26,"") -> 0 | H27: =IFERROR([1]SYNC_PROSPECTION_MKT!$J$26,"") -> 0 | I27: =IFERROR([1]SYNC_PROSPECTION_MKT!$I$26,"") -> 0 | J27: =IFERROR([1]SYNC_PROSPECTION_MKT!$K$26,"") -> 0 | K27: =IFERROR(SYNC_FINANCE!$I$26,"") -> 0 | L27: =IFERROR([2]SYNC_COMMERCIAL_VENTE!$S$26,"") -> 0 | M27: 0 | N27: 0 | O27: 0 | P27: 0 | Q27: 0 | R27: 0 | S27: 0 | T27: 0 | U27: 0 | V27: 0 | W27: 0 | X27: 0 | Y27: 0 | Z27: =IFERROR(SUM(N27:Y27),0) -> 0 | AA27: =IFERROR((N27+Q27+T27+W27)-M27,0) -> 0 | AB27: =IFERROR(Z27,0) -> 0 | AC27: =IFERROR(L27-AB27,0) -> 0
A28: 23 | B28: =IFERROR([1]SYNC_PROSPECTION_MKT!$B$27,"") -> 0 | C28: =IFERROR([1]SYNC_PROSPECTION_MKT!$C$27,"") -> 0 | D28: =IFERROR([1]SYNC_PROSPECTION_MKT!$D$27,"") -> 0 | E28: =IFERROR([1]SYNC_PROSPECTION_MKT!$E$27,"") -> 0 | F28: =IFERROR([1]SYNC_PROSPECTION_MKT!$G$27,"") -> 0 | G28: =IFERROR([1]SYNC_PROSPECTION_MKT!$H$27,"") -> 0 | H28: =IFERROR([1]SYNC_PROSPECTION_MKT!$J$27,"") -> 0 | I28: =IFERROR([1]SYNC_PROSPECTION_MKT!$I$27,"") -> 0 | J28: =IFERROR([1]SYNC_PROSPECTION_MKT!$K$27,"") -> 0 | K28: =IFERROR(SYNC_FINANCE!$I$27,"") -> 0 | L28: =IFERROR([2]SYNC_COMMERCIAL_VENTE!$S$27,"") -> 0 | M28: 0 | N28: 0 | O28: 0 | P28: 0 | Q28: 0 | R28: 0 | S28: 0 | T28: 0 | U28: 0 | V28: 0 | W28: 0 | X28: 0 | Y28: 0 | Z28: =IFERROR(SUM(N28:Y28),0) -> 0 | AA28: =IFERROR((N28+Q28+T28+W28)-M28,0) -> 0 | AB28: =IFERROR(Z28,0) -> 0 | AC28: =IFERROR(L28-AB28,0) -> 0
A29: 24 | B29: =IFERROR([1]SYNC_PROSPECTION_MKT!$B$28,"") -> 0 | C29: =IFERROR([1]SYNC_PROSPECTION_MKT!$C$28,"") -> 0 | D29: =IFERROR([1]SYNC_PROSPECTION_MKT!$D$28,"") -> 0 | E29: =IFERROR([1]SYNC_PROSPECTION_MKT!$E$28,"") -> 0 | F29: =IFERROR([1]SYNC_PROSPECTION_MKT!$G$28,"") -> 0 | G29: =IFERROR([1]SYNC_PROSPECTION_MKT!$H$28,"") -> 0 | H29: =IFERROR([1]SYNC_PROSPECTION_MKT!$J$28,"") -> 0 | I29: =IFERROR([1]SYNC_PROSPECTION_MKT!$I$28,"") -> 0 | J29: =IFERROR([1]SYNC_PROSPECTION_MKT!$K$28,"") -> 0 | K29: =IFERROR(SYNC_FINANCE!$I$28,"") -> 0 | L29: =IFERROR([2]SYNC_COMMERCIAL_VENTE!$S$28,"") -> 0 | M29: 0 | N29: 0 | O29: 0 | P29: 0 | Q29: 0 | R29: 0 | S29: 0 | T29: 0 | U29: 0 | V29: 0 | W29: 0 | X29: 0 | Y29: 0 | Z29: =IFERROR(SUM(N29:Y29),0) -> 0 | AA29: =IFERROR((N29+Q29+T29+W29)-M29,0) -> 0 | AB29: =IFERROR(Z29,0) -> 0 | AC29: =IFERROR(L29-AB29,0) -> 0
A30: 25 | B30: =IFERROR([1]SYNC_PROSPECTION_MKT!$B$29,"") -> 0 | C30: =IFERROR([1]SYNC_PROSPECTION_MKT!$C$29,"") -> 0 | D30: =IFERROR([1]SYNC_PROSPECTION_MKT!$D$29,"") -> 0 | E30: =IFERROR([1]SYNC_PROSPECTION_MKT!$E$29,"") -> 0 | F30: =IFERROR([1]SYNC_PROSPECTION_MKT!$G$29,"") -> 0 | G30: =IFERROR([1]SYNC_PROSPECTION_MKT!$H$29,"") -> 0 | H30: =IFERROR([1]SYNC_PROSPECTION_MKT!$J$29,"") -> 0 | I30: =IFERROR([1]SYNC_PROSPECTION_MKT!$I$29,"") -> 0 | J30: =IFERROR([1]SYNC_PROSPECTION_MKT!$K$29,"") -> 0 | K30: =IFERROR(SYNC_FINANCE!$I$29,"") -> 0 | L30: =IFERROR([2]SYNC_COMMERCIAL_VENTE!$S$29,"") -> 0 | M30: 0 | N30: 0 | O30: 0 | P30: 0 | Q30: 0 | R30: 0 | S30: 0 | T30: 0 | U30: 0 | V30: 0 | W30: 0 | X30: 0 | Y30: 0 | Z30: =IFERROR(SUM(N30:Y30),0) -> 0 | AA30: =IFERROR((N30+Q30+T30+W30)-M30,0) -> 0 | AB30: =IFERROR(Z30,0) -> 0 | AC30: =IFERROR(L30-AB30,0) -> 0
A31: 26 | B31: =IFERROR([1]SYNC_PROSPECTION_MKT!$B$30,"") -> 0 | C31: =IFERROR([1]SYNC_PROSPECTION_MKT!$C$30,"") -> 0 | D31: =IFERROR([1]SYNC_PROSPECTION_MKT!$D$30,"") -> 0 | E31: =IFERROR([1]SYNC_PROSPECTION_MKT!$E$30,"") -> 0 | F31: =IFERROR([1]SYNC_PROSPECTION_MKT!$G$30,"") -> 0 | G31: =IFERROR([1]SYNC_PROSPECTION_MKT!$H$30,"") -> 0 | H31: =IFERROR([1]SYNC_PROSPECTION_MKT!$J$30,"") -> 0 | I31: =IFERROR([1]SYNC_PROSPECTION_MKT!$I$30,"") -> 0 | J31: =IFERROR([1]SYNC_PROSPECTION_MKT!$K$30,"") -> 0 | K31: =IFERROR(SYNC_FINANCE!$I$30,"") -> 0 | L31: =IFERROR([2]SYNC_COMMERCIAL_VENTE!$S$30,"") -> 0 | M31: 0 | N31: 0 | O31: 0 | P31: 0 | Q31: 0 | R31: 0 | S31: 0 | T31: 0 | U31: 0 | V31: 0 | W31: 0 | X31: 0 | Y31: 0 | Z31: =IFERROR(SUM(N31:Y31),0) -> 0 | AA31: =IFERROR((N31+Q31+T31+W31)-M31,0) -> 0 | AB31: =IFERROR(Z31,0) -> 0 | AC31: =IFERROR(L31-AB31,0) -> 0
A32: 27 | B32: =IFERROR([1]SYNC_PROSPECTION_MKT!$B$31,"") -> 0 | C32: =IFERROR([1]SYNC_PROSPECTION_MKT!$C$31,"") -> 0 | D32: =IFERROR([1]SYNC_PROSPECTION_MKT!$D$31,"") -> 0 | E32: =IFERROR([1]SYNC_PROSPECTION_MKT!$E$31,"") -> 0 | F32: =IFERROR([1]SYNC_PROSPECTION_MKT!$G$31,"") -> 0 | G32: =IFERROR([1]SYNC_PROSPECTION_MKT!$H$31,"") -> 0 | H32: =IFERROR([1]SYNC_PROSPECTION_MKT!$J$31,"") -> 0 | I32: =IFERROR([1]SYNC_PROSPECTION_MKT!$I$31,"") -> 0 | J32: =IFERROR([1]SYNC_PROSPECTION_MKT!$K$31,"") -> 0 | K32: =IFERROR(SYNC_FINANCE!$I$31,"") -> 0 | L32: =IFERROR([2]SYNC_COMMERCIAL_VENTE!$S$31,"") -> 0 | M32: 0 | N32: 0 | O32: 0 | P32: 0 | Q32: 0 | R32: 0 | S32: 0 | T32: 0 | U32: 0 | V32: 0 | W32: 0 | X32: 0 | Y32: 0 | Z32: =IFERROR(SUM(N32:Y32),0) -> 0 | AA32: =IFERROR((N32+Q32+T32+W32)-M32,0) -> 0 | AB32: =IFERROR(Z32,0) -> 0 | AC32: =IFERROR(L32-AB32,0) -> 0
A33: 28 | B33: =IFERROR([1]SYNC_PROSPECTION_MKT!$B$32,"") -> 0 | C33: =IFERROR([1]SYNC_PROSPECTION_MKT!$C$32,"") -> 0 | D33: =IFERROR([1]SYNC_PROSPECTION_MKT!$D$32,"") -> 0 | E33: =IFERROR([1]SYNC_PROSPECTION_MKT!$E$32,"") -> 0 | F33: =IFERROR([1]SYNC_PROSPECTION_MKT!$G$32,"") -> 0 | G33: =IFERROR([1]SYNC_PROSPECTION_MKT!$H$32,"") -> 0 | H33: =IFERROR([1]SYNC_PROSPECTION_MKT!$J$32,"") -> 0 | I33: =IFERROR([1]SYNC_PROSPECTION_MKT!$I$32,"") -> 0 | J33: =IFERROR([1]SYNC_PROSPECTION_MKT!$K$32,"") -> 0 | K33: =IFERROR(SYNC_FINANCE!$I$32,"") -> 0 | L33: =IFERROR([2]SYNC_COMMERCIAL_VENTE!$S$32,"") -> 0 | M33: 0 | N33: 0 | O33: 0 | P33: 0 | Q33: 0 | R33: 0 | S33: 0 | T33: 0 | U33: 0 | V33: 0 | W33: 0 | X33: 0 | Y33: 0 | Z33: =IFERROR(SUM(N33:Y33),0) -> 0 | AA33: =IFERROR((N33+Q33+T33+W33)-M33,0) -> 0 | AB33: =IFERROR(Z33,0) -> 0 | AC33: =IFERROR(L33-AB33,0) -> 0
A34: 29 | B34: =IFERROR([1]SYNC_PROSPECTION_MKT!$B$33,"") -> 0 | C34: =IFERROR([1]SYNC_PROSPECTION_MKT!$C$33,"") -> 0 | D34: =IFERROR([1]SYNC_PROSPECTION_MKT!$D$33,"") -> 0 | E34: =IFERROR([1]SYNC_PROSPECTION_MKT!$E$33,"") -> 0 | F34: =IFERROR([1]SYNC_PROSPECTION_MKT!$G$33,"") -> 0 | G34: =IFERROR([1]SYNC_PROSPECTION_MKT!$H$33,"") -> 0 | H34: =IFERROR([1]SYNC_PROSPECTION_MKT!$J$33,"") -> 0 | I34: =IFERROR([1]SYNC_PROSPECTION_MKT!$I$33,"") -> 0 | J34: =IFERROR([1]SYNC_PROSPECTION_MKT!$K$33,"") -> 0 | K34: =IFERROR(SYNC_FINANCE!$I$33,"") -> 0 | L34: =IFERROR([2]SYNC_COMMERCIAL_VENTE!$S$33,"") -> 0 | M34: 0 | N34: 0 | O34: 0 | P34: 0 | Q34: 0 | R34: 0 | S34: 0 | T34: 0 | U34: 0 | V34: 0 | W34: 0 | X34: 0 | Y34: 0 | Z34: =IFERROR(SUM(N34:Y34),0) -> 0 | AA34: =IFERROR((N34+Q34+T34+W34)-M34,0) -> 0 | AB34: =IFERROR(Z34,0) -> 0 | AC34: =IFERROR(L34-AB34,0) -> 0
A35: 30 | B35: =IFERROR([1]SYNC_PROSPECTION_MKT!$B$34,"") -> 0 | C35: =IFERROR([1]SYNC_PROSPECTION_MKT!$C$34,"") -> 0 | D35: =IFERROR([1]SYNC_PROSPECTION_MKT!$D$34,"") -> 0 | E35: =IFERROR([1]SYNC_PROSPECTION_MKT!$E$34,"") -> 0 | F35: =IFERROR([1]SYNC_PROSPECTION_MKT!$G$34,"") -> 0 | G35: =IFERROR([1]SYNC_PROSPECTION_MKT!$H$34,"") -> 0 | H35: =IFERROR([1]SYNC_PROSPECTION_MKT!$J$34,"") -> 0 | I35: =IFERROR([1]SYNC_PROSPECTION_MKT!$I$34,"") -> 0 | J35: =IFERROR([1]SYNC_PROSPECTION_MKT!$K$34,"") -> 0 | K35: =IFERROR(SYNC_FINANCE!$I$34,"") -> 0 | L35: =IFERROR([2]SYNC_COMMERCIAL_VENTE!$S$34,"") -> 0 | M35: 0 | N35: 0 | O35: 0 | P35: 0 | Q35: 0 | R35: 0 | S35: 0 | T35: 0 | U35: 0 | V35: 0 | W35: 0 | X35: 0 | Y35: 0 | Z35: =IFERROR(SUM(N35:Y35),0) -> 0 | AA35: =IFERROR((N35+Q35+T35+W35)-M35,0) -> 0 | AB35: =IFERROR(Z35,0) -> 0 | AC35: =IFERROR(L35-AB35,0) -> 0
A36: 31 | B36: =IFERROR([1]SYNC_PROSPECTION_MKT!$B$35,"") -> 0 | C36: =IFERROR([1]SYNC_PROSPECTION_MKT!$C$35,"") -> 0 | D36: =IFERROR([1]SYNC_PROSPECTION_MKT!$D$35,"") -> 0 | E36: =IFERROR([1]SYNC_PROSPECTION_MKT!$E$35,"") -> 0 | F36: =IFERROR([1]SYNC_PROSPECTION_MKT!$G$35,"") -> 0 | G36: =IFERROR([1]SYNC_PROSPECTION_MKT!$H$35,"") -> 0 | H36: =IFERROR([1]SYNC_PROSPECTION_MKT!$J$35,"") -> 0 | I36: =IFERROR([1]SYNC_PROSPECTION_MKT!$I$35,"") -> 0 | J36: =IFERROR([1]SYNC_PROSPECTION_MKT!$K$35,"") -> 0 | K36: =IFERROR(SYNC_FINANCE!$I$35,"") -> 0 | L36: =IFERROR([2]SYNC_COMMERCIAL_VENTE!$S$35,"") -> 0 | M36: 0 | N36: 0 | O36: 0 | P36: 0 | Q36: 0 | R36: 0 | S36: 0 | T36: 0 | U36: 0 | V36: 0 | W36: 0 | X36: 0 | Y36: 0 | Z36: =IFERROR(SUM(N36:Y36),0) -> 0 | AA36: =IFERROR((N36+Q36+T36+W36)-M36,0) -> 0 | AB36: =IFERROR(Z36,0) -> 0 | AC36: =IFERROR(L36-AB36,0) -> 0
A37: 32 | B37: =IFERROR([1]SYNC_PROSPECTION_MKT!$B$36,"") -> 0 | C37: =IFERROR([1]SYNC_PROSPECTION_MKT!$C$36,"") -> 0 | D37: =IFERROR([1]SYNC_PROSPECTION_MKT!$D$36,"") -> 0 | E37: =IFERROR([1]SYNC_PROSPECTION_MKT!$E$36,"") -> 0 | F37: =IFERROR([1]SYNC_PROSPECTION_MKT!$G$36,"") -> 0 | G37: =IFERROR([1]SYNC_PROSPECTION_MKT!$H$36,"") -> 0 | H37: =IFERROR([1]SYNC_PROSPECTION_MKT!$J$36,"") -> 0 | I37: =IFERROR([1]SYNC_PROSPECTION_MKT!$I$36,"") -> 0 | J37: =IFERROR([1]SYNC_PROSPECTION_MKT!$K$36,"") -> 0 | K37: =IFERROR(SYNC_FINANCE!$I$36,"") -> 0 | L37: =IFERROR([2]SYNC_COMMERCIAL_VENTE!$S$36,"") -> 0 | M37: 0 | N37: 0 | O37: 0 | P37: 0 | Q37: 0 | R37: 0 | S37: 0 | T37: 0 | U37: 0 | V37: 0 | W37: 0 | X37: 0 | Y37: 0 | Z37: =IFERROR(SUM(N37:Y37),0) -> 0 | AA37: =IFERROR((N37+Q37+T37+W37)-M37,0) -> 0 | AB37: =IFERROR(Z37,0) -> 0 | AC37: =IFERROR(L37-AB37,0) -> 0
A38: 33 | B38: =IFERROR([1]SYNC_PROSPECTION_MKT!$B$37,"") -> 0 | C38: =IFERROR([1]SYNC_PROSPECTION_MKT!$C$37,"") -> 0 | D38: =IFERROR([1]SYNC_PROSPECTION_MKT!$D$37,"") -> 0 | E38: =IFERROR([1]SYNC_PROSPECTION_MKT!$E$37,"") -> 0 | F38: =IFERROR([1]SYNC_PROSPECTION_MKT!$G$37,"") -> 0 | G38: =IFERROR([1]SYNC_PROSPECTION_MKT!$H$37,"") -> 0 | H38: =IFERROR([1]SYNC_PROSPECTION_MKT!$J$37,"") -> 0 | I38: =IFERROR([1]SYNC_PROSPECTION_MKT!$I$37,"") -> 0 | J38: =IFERROR([1]SYNC_PROSPECTION_MKT!$K$37,"") -> 0 | K38: =IFERROR(SYNC_FINANCE!$I$37,"") -> 0 | L38: =IFERROR([2]SYNC_COMMERCIAL_VENTE!$S$37,"") -> 0 | M38: 0 | N38: 0 | O38: 0 | P38: 0 | Q38: 0 | R38: 0 | S38: 0 | T38: 0 | U38: 0 | V38: 0 | W38: 0 | X38: 0 | Y38: 0 | Z38: =IFERROR(SUM(N38:Y38),0) -> 0 | AA38: =IFERROR((N38+Q38+T38+W38)-M38,0) -> 0 | AB38: =IFERROR(Z38,0) -> 0 | AC38: =IFERROR(L38-AB38,0) -> 0
A39: 34 | B39: =IFERROR([1]SYNC_PROSPECTION_MKT!$B$38,"") -> 0 | C39: =IFERROR([1]SYNC_PROSPECTION_MKT!$C$38,"") -> 0 | D39: =IFERROR([1]SYNC_PROSPECTION_MKT!$D$38,"") -> 0 | E39: =IFERROR([1]SYNC_PROSPECTION_MKT!$E$38,"") -> 0 | F39: =IFERROR([1]SYNC_PROSPECTION_MKT!$G$38,"") -> 0 | G39: =IFERROR([1]SYNC_PROSPECTION_MKT!$H$38,"") -> 0 | H39: =IFERROR([1]SYNC_PROSPECTION_MKT!$J$38,"") -> 0 | I39: =IFERROR([1]SYNC_PROSPECTION_MKT!$I$38,"") -> 0 | J39: =IFERROR([1]SYNC_PROSPECTION_MKT!$K$38,"") -> 0 | K39: =IFERROR(SYNC_FINANCE!$I$38,"") -> 0 | L39: =IFERROR([2]SYNC_COMMERCIAL_VENTE!$S$38,"") -> 0 | M39: 0 | N39: 0 | O39: 0 | P39: 0 | Q39: 0 | R39: 0 | S39: 0 | T39: 0 | U39: 0 | V39: 0 | W39: 0 | X39: 0 | Y39: 0 | Z39: =IFERROR(SUM(N39:Y39),0) -> 0 | AA39: =IFERROR((N39+Q39+T39+W39)-M39,0) -> 0 | AB39: =IFERROR(Z39,0) -> 0 | AC39: =IFERROR(L39-AB39,0) -> 0
A40: 35 | B40: =IFERROR([1]SYNC_PROSPECTION_MKT!$B$39,"") -> 0 | C40: =IFERROR([1]SYNC_PROSPECTION_MKT!$C$39,"") -> 0 | D40: =IFERROR([1]SYNC_PROSPECTION_MKT!$D$39,"") -> 0 | E40: =IFERROR([1]SYNC_PROSPECTION_MKT!$E$39,"") -> 0 | F40: =IFERROR([1]SYNC_PROSPECTION_MKT!$G$39,"") -> 0 | G40: =IFERROR([1]SYNC_PROSPECTION_MKT!$H$39,"") -> 0 | H40: =IFERROR([1]SYNC_PROSPECTION_MKT!$J$39,"") -> 0 | I40: =IFERROR([1]SYNC_PROSPECTION_MKT!$I$39,"") -> 0 | J40: =IFERROR([1]SYNC_PROSPECTION_MKT!$K$39,"") -> 0 | K40: =IFERROR(SYNC_FINANCE!$I$39,"") -> 0 | L40: =IFERROR([2]SYNC_COMMERCIAL_VENTE!$S$39,"") -> 0 | M40: 0 | N40: 0 | O40: 0 | P40: 0 | Q40: 0 | R40: 0 | S40: 0 | T40: 0 | U40: 0 | V40: 0 | W40: 0 | X40: 0 | Y40: 0 | Z40: =IFERROR(SUM(N40:Y40),0) -> 0 | AA40: =IFERROR((N40+Q40+T40+W40)-M40,0) -> 0 | AB40: =IFERROR(Z40,0) -> 0 | AC40: =IFERROR(L40-AB40,0) -> 0
...

Sheet PAIEMENTS JUILLET 2026
A1: 💰 PAIEMENTS JUILLET 2026 — LEMI SARL | BRASUS v3.2
A2: ⚠️ Saisie des paiements reçus par semaine. Alimente automatiquement le SUIVI 13 MOIS.
A3: 🔒 Identité client (auto) | K3: 📋 Contrat | N3: ✏️ PAIEMENTS JUILLET — 4 semaines × (Paiement + Droit + Apport) | Z3: ⚙️ CALCULS AUTO
N4: 01/07-07/07 | Q4: 08/07-15/07 | T4: 16/07-24/07 | W4: 25/07-31/07
A5: N° | B5: N° IDENTIFIANT | C5: NOM & PRÉNOMS DU CLIENT | D5: SOURCE DU PROSPECT | E5: DATE PREMIER CONTACT | F5: TÉLÉPHONE / WHATSAPP | G5: PROFESSION | H5: RÉGION D'HABITATION | I5: RÉGION DU PROJET | J5: LIEU DU PROJET | K5: N° CONTRAT | L5: MONTANT TTC (FCFA) | M5: MENSUALITÉ (FCFA) | N5: PAIEMENT | O5: DROIT ADHÉSION | P5: APPORT INITIAL | Q5: PAIEMENT | R5: DROIT ADHÉSION | S5: APPORT INITIAL | T5: PAIEMENT | U5: DROIT ADHÉSION | V5: APPORT INITIAL | W5: PAIEMENT | X5: DROIT ADHÉSION | Y5: APPORT INITIAL | Z5: TOTAL MOIS | AA5: MENSUALITÉ DUE | AB5: CUMUL PAIEMENTS | AC5: RESTANT DÛ
A6: 1 | B6: =IFERROR([1]SYNC_PROSPECTION_MKT!$B$5,"") -> 0 | C6: =IFERROR([1]SYNC_PROSPECTION_MKT!$C$5,"") -> TANOH KONAN GERVAIS ARMAND | D6: =IFERROR([1]SYNC_PROSPECTION_MKT!$D$5,"") -> 0 | E6: =IFERROR([1]SYNC_PROSPECTION_MKT!$E$5,"") -> 0 | F6: =IFERROR([1]SYNC_PROSPECTION_MKT!$G$5,"") -> 0 | G6: =IFERROR([1]SYNC_PROSPECTION_MKT!$H$5,"") -> 0 | H6: =IFERROR([1]SYNC_PROSPECTION_MKT!$J$5,"") -> 0 | I6: =IFERROR([1]SYNC_PROSPECTION_MKT!$I$5,"") -> 0 | J6: =IFERROR([1]SYNC_PROSPECTION_MKT!$K$5,"") -> 0 | K6: =IFERROR(SYNC_FINANCE!$I$5,"") -> 0 | L6: =IFERROR([2]SYNC_COMMERCIAL_VENTE!$S$5,"") -> 0 | M6: 138889 | N6: 138889 | O6: 250000 | P6: 3000000 | Q6: 0 | R6: 0 | S6: 0 | T6: 0 | U6: 0 | V6: 0 | W6: 0 | X6: 0 | Y6: 0 | Z6: =IFERROR(SUM(N6:Y6),0) -> 3388889 | AA6: =IFERROR((N6+Q6+T6+W6)-M6,0) -> 0 | AB6: =IFERROR(Z6,0) -> 3388889 | AC6: =IFERROR(L6-AB6,0) -> -3388889
A7: 2 | B7: =IFERROR([1]SYNC_PROSPECTION_MKT!$B$6,"") -> 0 | C7: =IFERROR([1]SYNC_PROSPECTION_MKT!$C$6,"") -> N'DRI ép. NGBESSO AKISSI ELIANE | D7: =IFERROR([1]SYNC_PROSPECTION_MKT!$D$6,"") -> 0 | E7: =IFERROR([1]SYNC_PROSPECTION_MKT!$E$6,"") -> 0 | F7: =IFERROR([1]SYNC_PROSPECTION_MKT!$G$6,"") -> 0 | G7: =IFERROR([1]SYNC_PROSPECTION_MKT!$H$6,"") -> 0 | H7: =IFERROR([1]SYNC_PROSPECTION_MKT!$J$6,"") -> 0 | I7: =IFERROR([1]SYNC_PROSPECTION_MKT!$I$6,"") -> 0 | J7: =IFERROR([1]SYNC_PROSPECTION_MKT!$K$6,"") -> 0 | K7: =IFERROR(SYNC_FINANCE!$I$6,"") -> 0 | L7: =IFERROR([2]SYNC_COMMERCIAL_VENTE!$S$6,"") -> 0 | M7: 0 | N7: 0 | O7: 0 | P7: 0 | Q7: 0 | R7: 0 | S7: 0 | T7: 0 | U7: 0 | V7: 0 | W7: 0 | X7: 0 | Y7: 0 | Z7: =IFERROR(SUM(N7:Y7),0) -> 0 | AA7: =IFERROR((N7+Q7+T7+W7)-M7,0) -> 0 | AB7: =IFERROR(Z7,0) -> 0 | AC7: =IFERROR(L7-AB7,0) -> 0
A8: 3 | B8: =IFERROR([1]SYNC_PROSPECTION_MKT!$B$7,"") -> 0 | C8: =IFERROR([1]SYNC_PROSPECTION_MKT!$C$7,"") -> N'GORAN KOFFI | D8: =IFERROR([1]SYNC_PROSPECTION_MKT!$D$7,"") -> 0 | E8: =IFERROR([1]SYNC_PROSPECTION_MKT!$E$7,"") -> 0 | F8: =IFERROR([1]SYNC_PROSPECTION_MKT!$G$7,"") -> 0 | G8: =IFERROR([1]SYNC_PROSPECTION_MKT!$H$7,"") -> 0 | H8: =IFERROR([1]SYNC_PROSPECTION_MKT!$J$7,"") -> 0 | I8: =IFERROR([1]SYNC_PROSPECTION_MKT!$I$7,"") -> 0 | J8: =IFERROR([1]SYNC_PROSPECTION_MKT!$K$7,"") -> 0 | K8: =IFERROR(SYNC_FINANCE!$I$7,"") -> 0 | L8: =IFERROR([2]SYNC_COMMERCIAL_VENTE!$S$7,"") -> 0 | M8: 0 | N8: 0 | O8: 0 | P8: 0 | Q8: 0 | R8: 0 | S8: 0 | T8: 0 | U8: 0 | V8: 0 | W8: 0 | X8: 0 | Y8: 0 | Z8: =IFERROR(SUM(N8:Y8),0) -> 0 | AA8: =IFERROR((N8+Q8+T8+W8)-M8,0) -> 0 | AB8: =IFERROR(Z8,0) -> 0 | AC8: =IFERROR(L8-AB8,0) -> 0
A9: 4 | B9: =IFERROR([1]SYNC_PROSPECTION_MKT!$B$8,"") -> 0 | C9: =IFERROR([1]SYNC_PROSPECTION_MKT!$C$8,"") -> KOUASSI VINCENT DE PAUL ASSOUMOU | D9: =IFERROR([1]SYNC_PROSPECTION_MKT!$D$8,"") -> 0 | E9: =IFERROR([1]SYNC_PROSPECTION_MKT!$E$8,"") -> 0 | F9: =IFERROR([1]SYNC_PROSPECTION_MKT!$G$8,"") -> 0 | G9: =IFERROR([1]SYNC_PROSPECTION_MKT!$H$8,"") -> 0 | H9: =IFERROR([1]SYNC_PROSPECTION_MKT!$J$8,"") -> 0 | I9: =IFERROR([1]SYNC_PROSPECTION_MKT!$I$8,"") -> 0 | J9: =IFERROR([1]SYNC_PROSPECTION_MKT!$K$8,"") -> 0 | K9: =IFERROR(SYNC_FINANCE!$I$8,"") -> 0 | L9: =IFERROR([2]SYNC_COMMERCIAL_VENTE!$S$8,"") -> 0 | M9: 0 | N9: 0 | O9: 0 | P9: 0 | Q9: 0 | R9: 0 | S9: 0 | T9: 0 | U9: 0 | V9: 0 | W9: 0 | X9: 0 | Y9: 0 | Z9: =IFERROR(SUM(N9:Y9),0) -> 0 | AA9: =IFERROR((N9+Q9+T9+W9)-M9,0) -> 0 | AB9: =IFERROR(Z9,0) -> 0 | AC9: =IFERROR(L9-AB9,0) -> 0
A10: 5 | B10: =IFERROR([1]SYNC_PROSPECTION_MKT!$B$9,"") -> 0 | C10: =IFERROR([1]SYNC_PROSPECTION_MKT!$C$9,"") -> KOUASSI HONORE | D10: =IFERROR([1]SYNC_PROSPECTION_MKT!$D$9,"") -> 0 | E10: =IFERROR([1]SYNC_PROSPECTION_MKT!$E$9,"") -> 0 | F10: =IFERROR([1]SYNC_PROSPECTION_MKT!$G$9,"") -> 0 | G10: =IFERROR([1]SYNC_PROSPECTION_MKT!$H$9,"") -> 0 | H10: =IFERROR([1]SYNC_PROSPECTION_MKT!$J$9,"") -> 0 | I10: =IFERROR([1]SYNC_PROSPECTION_MKT!$I$9,"") -> 0 | J10: =IFERROR([1]SYNC_PROSPECTION_MKT!$K$9,"") -> 0 | K10: =IFERROR(SYNC_FINANCE!$I$9,"") -> 0 | L10: =IFERROR([2]SYNC_COMMERCIAL_VENTE!$S$9,"") -> 0 | M10: 0 | N10: 0 | O10: 0 | P10: 0 | Q10: 0 | R10: 0 | S10: 0 | T10: 0 | U10: 0 | V10: 0 | W10: 0 | X10: 0 | Y10: 0 | Z10: =IFERROR(SUM(N10:Y10),0) -> 0 | AA10: =IFERROR((N10+Q10+T10+W10)-M10,0) -> 0 | AB10: =IFERROR(Z10,0) -> 0 | AC10: =IFERROR(L10-AB10,0) -> 0
A11: 6 | B11: =IFERROR([1]SYNC_PROSPECTION_MKT!$B$10,"") -> 0 | C11: =IFERROR([1]SYNC_PROSPECTION_MKT!$C$10,"") -> AKISSI ELIANE KONAN | D11: =IFERROR([1]SYNC_PROSPECTION_MKT!$D$10,"") -> 0 | E11: =IFERROR([1]SYNC_PROSPECTION_MKT!$E$10,"") -> 0 | F11: =IFERROR([1]SYNC_PROSPECTION_MKT!$G$10,"") -> 0 | G11: =IFERROR([1]SYNC_PROSPECTION_MKT!$H$10,"") -> 0 | H11: =IFERROR([1]SYNC_PROSPECTION_MKT!$J$10,"") -> 0 | I11: =IFERROR([1]SYNC_PROSPECTION_MKT!$I$10,"") -> 0 | J11: =IFERROR([1]SYNC_PROSPECTION_MKT!$K$10,"") -> 0 | K11: =IFERROR(SYNC_FINANCE!$I$10,"") -> 0 | L11: =IFERROR([2]SYNC_COMMERCIAL_VENTE!$S$10,"") -> 0 | M11: 0 | N11: 0 | O11: 0 | P11: 0 | Q11: 0 | R11: 0 | S11: 0 | T11: 0 | U11: 0 | V11: 0 | W11: 0 | X11: 0 | Y11: 0 | Z11: =IFERROR(SUM(N11:Y11),0) -> 0 | AA11: =IFERROR((N11+Q11+T11+W11)-M11,0) -> 0 | AB11: =IFERROR(Z11,0) -> 0 | AC11: =IFERROR(L11-AB11,0) -> 0
A12: 7 | B12: =IFERROR([1]SYNC_PROSPECTION_MKT!$B$11,"") -> 0 | C12: =IFERROR([1]SYNC_PROSPECTION_MKT!$C$11,"") -> BROU LAMBERT KOUASSI | D12: =IFERROR([1]SYNC_PROSPECTION_MKT!$D$11,"") -> 0 | E12: =IFERROR([1]SYNC_PROSPECTION_MKT!$E$11,"") -> 0 | F12: =IFERROR([1]SYNC_PROSPECTION_MKT!$G$11,"") -> 0 | G12: =IFERROR([1]SYNC_PROSPECTION_MKT!$H$11,"") -> 0 | H12: =IFERROR([1]SYNC_PROSPECTION_MKT!$J$11,"") -> 0 | I12: =IFERROR([1]SYNC_PROSPECTION_MKT!$I$11,"") -> 0 | J12: =IFERROR([1]SYNC_PROSPECTION_MKT!$K$11,"") -> 0 | K12: =IFERROR(SYNC_FINANCE!$I$11,"") -> 0 | L12: =IFERROR([2]SYNC_COMMERCIAL_VENTE!$S$11,"") -> 0 | M12: 0 | N12: 0 | O12: 0 | P12: 0 | Q12: 0 | R12: 0 | S12: 0 | T12: 0 | U12: 0 | V12: 0 | W12: 0 | X12: 0 | Y12: 0 | Z12: =IFERROR(SUM(N12:Y12),0) -> 0 | AA12: =IFERROR((N12+Q12+T12+W12)-M12,0) -> 0 | AB12: =IFERROR(Z12,0) -> 0 | AC12: =IFERROR(L12-AB12,0) -> 0
A13: 8 | B13: =IFERROR([1]SYNC_PROSPECTION_MKT!$B$12,"") -> 0 | C13: =IFERROR([1]SYNC_PROSPECTION_MKT!$C$12,"") -> DJEDRI KOUAKOU JEAN PIERRE | D13: =IFERROR([1]SYNC_PROSPECTION_MKT!$D$12,"") -> 0 | E13: =IFERROR([1]SYNC_PROSPECTION_MKT!$E$12,"") -> 0 | F13: =IFERROR([1]SYNC_PROSPECTION_MKT!$G$12,"") -> 0 | G13: =IFERROR([1]SYNC_PROSPECTION_MKT!$H$12,"") -> 0 | H13: =IFERROR([1]SYNC_PROSPECTION_MKT!$J$12,"") -> 0 | I13: =IFERROR([1]SYNC_PROSPECTION_MKT!$I$12,"") -> 0 | J13: =IFERROR([1]SYNC_PROSPECTION_MKT!$K$12,"") -> 0 | K13: =IFERROR(SYNC_FINANCE!$I$12,"") -> 0 | L13: =IFERROR([2]SYNC_COMMERCIAL_VENTE!$S$12,"") -> 0 | M13: 0 | N13: 0 | O13: 0 | P13: 0 | Q13: 0 | R13: 0 | S13: 0 | T13: 0 | U13: 0 | V13: 0 | W13: 0 | X13: 0 | Y13: 0 | Z13: =IFERROR(SUM(N13:Y13),0) -> 0 | AA13: =IFERROR((N13+Q13+T13+W13)-M13,0) -> 0 | AB13: =IFERROR(Z13,0) -> 0 | AC13: =IFERROR(L13-AB13,0) -> 0
A14: 9 | B14: =IFERROR([1]SYNC_PROSPECTION_MKT!$B$13,"") -> 0 | C14: =IFERROR([1]SYNC_PROSPECTION_MKT!$C$13,"") -> DJAMAN KOUAKOU MATHIEU | D14: =IFERROR([1]SYNC_PROSPECTION_MKT!$D$13,"") -> 0 | E14: =IFERROR([1]SYNC_PROSPECTION_MKT!$E$13,"") -> 0 | F14: =IFERROR([1]SYNC_PROSPECTION_MKT!$G$13,"") -> 0 | G14: =IFERROR([1]SYNC_PROSPECTION_MKT!$H$13,"") -> 0 | H14: =IFERROR([1]SYNC_PROSPECTION_MKT!$J$13,"") -> 0 | I14: =IFERROR([1]SYNC_PROSPECTION_MKT!$I$13,"") -> 0 | J14: =IFERROR([1]SYNC_PROSPECTION_MKT!$K$13,"") -> 0 | K14: =IFERROR(SYNC_FINANCE!$I$13,"") -> 0 | L14: =IFERROR([2]SYNC_COMMERCIAL_VENTE!$S$13,"") -> 0 | M14: 0 | N14: 0 | O14: 0 | P14: 0 | Q14: 0 | R14: 0 | S14: 0 | T14: 0 | U14: 0 | V14: 0 | W14: 0 | X14: 0 | Y14: 0 | Z14: =IFERROR(SUM(N14:Y14),0) -> 0 | AA14: =IFERROR((N14+Q14+T14+W14)-M14,0) -> 0 | AB14: =IFERROR(Z14,0) -> 0 | AC14: =IFERROR(L14-AB14,0) -> 0
A15: 10 | B15: =IFERROR([1]SYNC_PROSPECTION_MKT!$B$14,"") -> 0 | C15: =IFERROR([1]SYNC_PROSPECTION_MKT!$C$14,"") -> N'GUESSAN KOUASSI | D15: =IFERROR([1]SYNC_PROSPECTION_MKT!$D$14,"") -> 0 | E15: =IFERROR([1]SYNC_PROSPECTION_MKT!$E$14,"") -> 0 | F15: =IFERROR([1]SYNC_PROSPECTION_MKT!$G$14,"") -> 0 | G15: =IFERROR([1]SYNC_PROSPECTION_MKT!$H$14,"") -> 0 | H15: =IFERROR([1]SYNC_PROSPECTION_MKT!$J$14,"") -> 0 | I15: =IFERROR([1]SYNC_PROSPECTION_MKT!$I$14,"") -> 0 | J15: =IFERROR([1]SYNC_PROSPECTION_MKT!$K$14,"") -> 0 | K15: =IFERROR(SYNC_FINANCE!$I$14,"") -> 0 | L15: =IFERROR([2]SYNC_COMMERCIAL_VENTE!$S$14,"") -> 0 | M15: 0 | N15: 0 | O15: 0 | P15: 0 | Q15: 0 | R15: 0 | S15: 0 | T15: 0 | U15: 0 | V15: 0 | W15: 0 | X15: 0 | Y15: 0 | Z15: =IFERROR(SUM(N15:Y15),0) -> 0 | AA15: =IFERROR((N15+Q15+T15+W15)-M15,0) -> 0 | AB15: =IFERROR(Z15,0) -> 0 | AC15: =IFERROR(L15-AB15,0) -> 0
A16: 11 | B16: =IFERROR([1]SYNC_PROSPECTION_MKT!$B$15,"") -> 0 | C16: =IFERROR([1]SYNC_PROSPECTION_MKT!$C$15,"") -> N'ZUE N'GUESSAN | D16: =IFERROR([1]SYNC_PROSPECTION_MKT!$D$15,"") -> 0 | E16: =IFERROR([1]SYNC_PROSPECTION_MKT!$E$15,"") -> 0 | F16: =IFERROR([1]SYNC_PROSPECTION_MKT!$G$15,"") -> 0 | G16: =IFERROR([1]SYNC_PROSPECTION_MKT!$H$15,"") -> 0 | H16: =IFERROR([1]SYNC_PROSPECTION_MKT!$J$15,"") -> 0 | I16: =IFERROR([1]SYNC_PROSPECTION_MKT!$I$15,"") -> 0 | J16: =IFERROR([1]SYNC_PROSPECTION_MKT!$K$15,"") -> 0 | K16: =IFERROR(SYNC_FINANCE!$I$15,"") -> 0 | L16: =IFERROR([2]SYNC_COMMERCIAL_VENTE!$S$15,"") -> 0 | M16: 0 | N16: 0 | O16: 0 | P16: 0 | Q16: 0 | R16: 0 | S16: 0 | T16: 0 | U16: 0 | V16: 0 | W16: 0 | X16: 0 | Y16: 0 | Z16: =IFERROR(SUM(N16:Y16),0) -> 0 | AA16: =IFERROR((N16+Q16+T16+W16)-M16,0) -> 0 | AB16: =IFERROR(Z16,0) -> 0 | AC16: =IFERROR(L16-AB16,0) -> 0
